[2022-07-08 13:15:00,146: INFO/MainProcess] Connected to redis://172.16.55.20:6379/0
[2022-07-08 13:15:00,162: INFO/MainProcess] mingle: searching for neighbors
[2022-07-08 13:15:01,221: INFO/MainProcess] mingle: all alone
[2022-07-08 13:15:01,252: WARNING/MainProcess] C:\inetpub\sites\edu-dev.coko38.ru\venv\lib\site-packages\celery\fixups\django.py:202: UserWarning: Using settings.DEBUG leads to a memory leak, never use this setting in production environments!
  warnings.warn('Using settings.DEBUG leads to a memory leak, never '
[2022-07-08 13:15:01,252: INFO/MainProcess] celery@srv-dev ready.
[2022-07-08 13:15:01,252: INFO/MainProcess] pidbox: Connected to redis://172.16.55.20:6379/0.
[2022-07-08 13:16:18,996: INFO/MainProcess] Received task: centre.tasks.EmailOfferPay[7b003007-b212-44ba-838c-f9b9340e15ba]  
[2022-07-08 13:16:22,796: INFO/MainProcess] Task centre.tasks.EmailOfferPay[7b003007-b212-44ba-838c-f9b9340e15ba] succeeded in 3.780999999999949s: None
[2022-07-08 13:20:09,745: INFO/MainProcess] Received task: centre.tasks.CheckRegistrationEnd[7c37ab41-7722-4048-8459-5df67e87258c]  
[2022-07-08 13:20:09,902: WARNING/MainProcess] --- Logging error ---
[2022-07-08 13:20:09,949: WARNING/MainProcess] Traceback (most recent call last):
[2022-07-08 13:20:09,949: WARNING/MainProcess] File "C:\inetpub\sites\edu-dev.coko38.ru\venv\lib\site-packages\celery\app\trace.py", line 385, in trace_task
    R = retval = fun(*args, **kwargs)
[2022-07-08 13:20:09,949: WARNING/MainProcess] File "C:\inetpub\sites\edu-dev.coko38.ru\venv\lib\site-packages\celery\app\trace.py", line 648, in __protected_call__
    return self.run(*args, **kwargs)
[2022-07-08 13:20:10,028: WARNING/MainProcess] File "C:\inetpub\sites\edu-dev.coko38.ru\venv\lib\site-packages\django\db\models\manager.py", line 85, in manager_method
    return getattr(self.get_queryset(), name)(*args, **kwargs)
[2022-07-08 13:20:10,028: WARNING/MainProcess] File "C:\inetpub\sites\edu-dev.coko38.ru\venv\lib\site-packages\django\db\models\query.py", line 492, in get
    num = len(clone)
[2022-07-08 13:20:10,028: WARNING/MainProcess] File "C:\inetpub\sites\edu-dev.coko38.ru\venv\lib\site-packages\django\db\models\query.py", line 302, in __len__
    self._fetch_all()
[2022-07-08 13:20:10,028: WARNING/MainProcess] File "C:\inetpub\sites\edu-dev.coko38.ru\venv\lib\site-packages\django\db\models\query.py", line 1507, in _fetch_all
    self._result_cache = list(self._iterable_class(self))
[2022-07-08 13:20:10,028: WARNING/MainProcess] File "C:\inetpub\sites\edu-dev.coko38.ru\venv\lib\site-packages\django\db\models\query.py", line 57, in __iter__
    results = compiler.execute_sql(
[2022-07-08 13:20:10,028: WARNING/MainProcess] File "C:\inetpub\sites\edu-dev.coko38.ru\venv\lib\site-packages\django\db\models\sql\compiler.py", line 1359, in execute_sql
    cursor = self.connection.cursor()
[2022-07-08 13:20:10,028: WARNING/MainProcess] File "C:\inetpub\sites\edu-dev.coko38.ru\venv\lib\site-packages\django\utils\asyncio.py", line 26, in inner
    return func(*args, **kwargs)
[2022-07-08 13:20:10,028: WARNING/MainProcess] File "C:\inetpub\sites\edu-dev.coko38.ru\venv\lib\site-packages\django\db\backends\base\base.py", line 284, in cursor
    return self._cursor()
[2022-07-08 13:20:10,028: WARNING/MainProcess] File "C:\inetpub\sites\edu-dev.coko38.ru\venv\lib\site-packages\mssql\base.py", line 230, in _cursor
    conn = super()._cursor()
[2022-07-08 13:20:10,028: WARNING/MainProcess] File "C:\inetpub\sites\edu-dev.coko38.ru\venv\lib\site-packages\django\db\backends\base\base.py", line 260, in _cursor
    self.ensure_connection()
[2022-07-08 13:20:10,028: WARNING/MainProcess] File "C:\inetpub\sites\edu-dev.coko38.ru\venv\lib\site-packages\django\utils\asyncio.py", line 26, in inner
    return func(*args, **kwargs)
[2022-07-08 13:20:10,028: WARNING/MainProcess] File "C:\inetpub\sites\edu-dev.coko38.ru\venv\lib\site-packages\django\db\backends\base\base.py", line 244, in ensure_connection
    self.connect()
[2022-07-08 13:20:10,028: WARNING/MainProcess] File "C:\inetpub\sites\edu-dev.coko38.ru\venv\lib\site-packages\django\utils\asyncio.py", line 26, in inner
    return func(*args, **kwargs)
[2022-07-08 13:20:10,028: WARNING/MainProcess] File "C:\inetpub\sites\edu-dev.coko38.ru\venv\lib\site-packages\django\db\backends\base\base.py", line 227, in connect
    self.init_connection_state()
[2022-07-08 13:20:10,028: WARNING/MainProcess] File "C:\inetpub\sites\edu-dev.coko38.ru\venv\lib\site-packages\mssql\base.py", line 391, in init_connection_state
    val = self.get_system_datetime()
[2022-07-08 13:20:10,028: WARNING/MainProcess] File "C:\inetpub\sites\edu-dev.coko38.ru\venv\lib\site-packages\mssql\base.py", line 406, in get_system_datetime
    with self.temporary_connection() as cursor:
[2022-07-08 13:20:10,028: WARNING/MainProcess] File "C:\Python39\lib\contextlib.py", line 119, in __enter__
    return next(self.gen)
[2022-07-08 13:20:10,028: WARNING/MainProcess] File "C:\inetpub\sites\edu-dev.coko38.ru\venv\lib\site-packages\django\db\backends\base\base.py", line 639, in temporary_connection
    with self.cursor() as cursor:
[2022-07-08 13:20:10,028: WARNING/MainProcess] File "C:\inetpub\sites\edu-dev.coko38.ru\venv\lib\site-packages\django\utils\asyncio.py", line 26, in inner
    return func(*args, **kwargs)
[2022-07-08 13:20:10,028: WARNING/MainProcess] File "C:\inetpub\sites\edu-dev.coko38.ru\venv\lib\site-packages\django\db\backends\base\base.py", line 284, in cursor
    return self._cursor()
[2022-07-08 13:20:10,028: WARNING/MainProcess] File "C:\inetpub\sites\edu-dev.coko38.ru\venv\lib\site-packages\mssql\base.py", line 230, in _cursor
    conn = super()._cursor()
[2022-07-08 13:20:10,028: WARNING/MainProcess] File "C:\inetpub\sites\edu-dev.coko38.ru\venv\lib\site-packages\django\db\backends\base\base.py", line 262, in _cursor
    return self._prepare_cursor(self.create_cursor(name))
[2022-07-08 13:20:10,028: WARNING/MainProcess] File "C:\inetpub\sites\edu-dev.coko38.ru\venv\lib\site-packages\django\db\backends\base\base.py", line 252, in _prepare_cursor
    self.validate_thread_sharing()
[2022-07-08 13:20:10,028: WARNING/MainProcess] File "C:\inetpub\sites\edu-dev.coko38.ru\venv\lib\site-packages\django\db\backends\base\base.py", line 589, in validate_thread_sharing
    raise DatabaseError(
[2022-07-08 13:20:10,028: WARNING/MainProcess] django.db.utils.DatabaseError: DatabaseWrapper objects created in a thread can only be used in that same thread. The object with alias 'default' was created in thread id 2495561913264 and this is thread id 2495781067760.
[2022-07-08 13:20:10,028: WARNING/MainProcess] During handling of the above exception, another exception occurred:
[2022-07-08 13:20:10,043: WARNING/MainProcess] Traceback (most recent call last):
[2022-07-08 13:20:10,043: WARNING/MainProcess] File "C:\Python39\lib\logging\__init__.py", line 1086, in emit
    stream.write(msg + self.terminator)
[2022-07-08 13:20:10,043: WARNING/MainProcess] File "C:\Python39\lib\encodings\cp1252.py", line 19, in encode
    return codecs.charmap_encode(input,self.errors,encoding_table)[0]
[2022-07-08 13:20:10,043: WARNING/MainProcess] UnicodeEncodeError: 'charmap' codec can't encode characters in position 881-884: character maps to <undefined>
[2022-07-08 13:20:10,043: WARNING/MainProcess] Call stack:
[2022-07-08 13:20:10,043: WARNING/MainProcess] File "C:\inetpub\sites\edu-dev.coko38.ru\venv\lib\site-packages\eventlet\greenpool.py", line 88, in _spawn_n_impl
    func(*args, **kwargs)
[2022-07-08 13:20:10,043: WARNING/MainProcess] File "C:\inetpub\sites\edu-dev.coko38.ru\venv\lib\site-packages\celery\concurrency\eventlet.py", line 33, in apply_target
    return base.apply_target(target, args, kwargs, callback, accept_callback,
[2022-07-08 13:20:10,043: WARNING/MainProcess] File "C:\inetpub\sites\edu-dev.coko38.ru\venv\lib\site-packages\celery\concurrency\base.py", line 31, in apply_target
    ret = target(*args, **kwargs)
[2022-07-08 13:20:10,043: WARNING/MainProcess] File "C:\inetpub\sites\edu-dev.coko38.ru\venv\lib\site-packages\celery\app\trace.py", line 555, in _fast_trace_task
    R, I, T, Rstr = tasks[task].__trace__(
[2022-07-08 13:20:10,043: WARNING/MainProcess] File "C:\inetpub\sites\edu-dev.coko38.ru\venv\lib\site-packages\celery\app\trace.py", line 399, in trace_task
    I, R, state, retval = on_error(task_request, exc, uuid)
[2022-07-08 13:20:10,043: WARNING/MainProcess] File "C:\inetpub\sites\edu-dev.coko38.ru\venv\lib\site-packages\celery\app\trace.py", line 338, in on_error
    R = I.handle_error_state(
[2022-07-08 13:20:10,043: WARNING/MainProcess] File "C:\inetpub\sites\edu-dev.coko38.ru\venv\lib\site-packages\celery\app\trace.py", line 167, in handle_error_state
    return {
[2022-07-08 13:20:10,043: WARNING/MainProcess] File "C:\inetpub\sites\edu-dev.coko38.ru\venv\lib\site-packages\celery\app\trace.py", line 226, in handle_failure
    self._log_error(task, req, einfo)
[2022-07-08 13:20:10,043: WARNING/MainProcess] File "C:\inetpub\sites\edu-dev.coko38.ru\venv\lib\site-packages\celery\app\trace.py", line 254, in _log_error
    logger.log(policy.severity, policy.format.strip(), context,
[2022-07-08 13:20:10,043: ERROR/MainProcess] Signal handler <bound method DjangoWorkerFixup.on_task_postrun of <celery.fixups.django.DjangoWorkerFixup object at 0x000002450BA98100>> raised: DatabaseError("DatabaseWrapper objects created in a thread can only be used in that same thread. The object with alias 'default' was created in thread id 2495561913264 and this is thread id 2495781067760.")
Traceback (most recent call last):
  File "C:\inetpub\sites\edu-dev.coko38.ru\venv\lib\site-packages\celery\utils\dispatch\signal.py", line 288, in send
    response = receiver(signal=self, sender=sender, **named)
  File "C:\inetpub\sites\edu-dev.coko38.ru\venv\lib\site-packages\celery\fixups\django.py", line 172, in on_task_postrun
    self.close_database()
  File "C:\inetpub\sites\edu-dev.coko38.ru\venv\lib\site-packages\celery\fixups\django.py", line 177, in close_database
    return self._close_database()
  File "C:\inetpub\sites\edu-dev.coko38.ru\venv\lib\site-packages\celery\fixups\django.py", line 186, in _close_database
    conn.close_if_unusable_or_obsolete()
  File "C:\inetpub\sites\edu-dev.coko38.ru\venv\lib\site-packages\django\db\backends\base\base.py", line 559, in close_if_unusable_or_obsolete
    self.close()
  File "C:\inetpub\sites\edu-dev.coko38.ru\venv\lib\site-packages\django\utils\asyncio.py", line 26, in inner
    return func(*args, **kwargs)
  File "C:\inetpub\sites\edu-dev.coko38.ru\venv\lib\site-packages\django\db\backends\base\base.py", line 310, in close
    self.validate_thread_sharing()
  File "C:\inetpub\sites\edu-dev.coko38.ru\venv\lib\site-packages\django\db\backends\base\base.py", line 589, in validate_thread_sharing
    raise DatabaseError(
django.db.utils.DatabaseError: DatabaseWrapper objects created in a thread can only be used in that same thread. The object with alias 'default' was created in thread id 2495561913264 and this is thread id 2495781067760.
[2022-07-08 13:20:10,059: INFO/MainProcess] Received task: centre.tasks.ShowSurveyUrl[f6af2091-d07e-4f7a-9e48-ab90a3d0a5cc]  
[2022-07-08 13:20:10,075: ERROR/MainProcess] Signal handler <bound method DjangoWorkerFixup.on_task_prerun of <celery.fixups.django.DjangoWorkerFixup object at 0x000002450BA98100>> raised: DatabaseError("DatabaseWrapper objects created in a thread can only be used in that same thread. The object with alias 'default' was created in thread id 2495561913264 and this is thread id 2495776458528.")
Traceback (most recent call last):
  File "C:\inetpub\sites\edu-dev.coko38.ru\venv\lib\site-packages\celery\utils\dispatch\signal.py", line 288, in send
    response = receiver(signal=self, sender=sender, **named)
  File "C:\inetpub\sites\edu-dev.coko38.ru\venv\lib\site-packages\celery\fixups\django.py", line 166, in on_task_prerun
    self.close_database()
  File "C:\inetpub\sites\edu-dev.coko38.ru\venv\lib\site-packages\celery\fixups\django.py", line 177, in close_database
    return self._close_database()
  File "C:\inetpub\sites\edu-dev.coko38.ru\venv\lib\site-packages\celery\fixups\django.py", line 186, in _close_database
    conn.close_if_unusable_or_obsolete()
  File "C:\inetpub\sites\edu-dev.coko38.ru\venv\lib\site-packages\django\db\backends\base\base.py", line 559, in close_if_unusable_or_obsolete
    self.close()
  File "C:\inetpub\sites\edu-dev.coko38.ru\venv\lib\site-packages\django\utils\asyncio.py", line 26, in inner
    return func(*args, **kwargs)
  File "C:\inetpub\sites\edu-dev.coko38.ru\venv\lib\site-packages\django\db\backends\base\base.py", line 310, in close
    self.validate_thread_sharing()
  File "C:\inetpub\sites\edu-dev.coko38.ru\venv\lib\site-packages\django\db\backends\base\base.py", line 589, in validate_thread_sharing
    raise DatabaseError(
django.db.utils.DatabaseError: DatabaseWrapper objects created in a thread can only be used in that same thread. The object with alias 'default' was created in thread id 2495561913264 and this is thread id 2495776458528.
[2022-07-08 13:20:10,075: WARNING/MainProcess] --- Logging error ---
[2022-07-08 13:20:10,093: WARNING/MainProcess] Traceback (most recent call last):
[2022-07-08 13:20:10,093: WARNING/MainProcess] File "C:\inetpub\sites\edu-dev.coko38.ru\venv\lib\site-packages\celery\app\trace.py", line 385, in trace_task
    R = retval = fun(*args, **kwargs)
[2022-07-08 13:20:10,093: WARNING/MainProcess] File "C:\inetpub\sites\edu-dev.coko38.ru\venv\lib\site-packages\celery\app\trace.py", line 648, in __protected_call__
    return self.run(*args, **kwargs)
[2022-07-08 13:20:10,093: WARNING/MainProcess] File "C:\inetpub\sites\edu-dev.coko38.ru\venv\lib\site-packages\django\db\models\manager.py", line 85, in manager_method
    return getattr(self.get_queryset(), name)(*args, **kwargs)
[2022-07-08 13:20:10,093: WARNING/MainProcess] File "C:\inetpub\sites\edu-dev.coko38.ru\venv\lib\site-packages\django\db\models\query.py", line 492, in get
    num = len(clone)
[2022-07-08 13:20:10,093: WARNING/MainProcess] File "C:\inetpub\sites\edu-dev.coko38.ru\venv\lib\site-packages\django\db\models\query.py", line 302, in __len__
    self._fetch_all()
[2022-07-08 13:20:10,093: WARNING/MainProcess] File "C:\inetpub\sites\edu-dev.coko38.ru\venv\lib\site-packages\django\db\models\query.py", line 1507, in _fetch_all
    self._result_cache = list(self._iterable_class(self))
[2022-07-08 13:20:10,093: WARNING/MainProcess] File "C:\inetpub\sites\edu-dev.coko38.ru\venv\lib\site-packages\django\db\models\query.py", line 57, in __iter__
    results = compiler.execute_sql(
[2022-07-08 13:20:10,093: WARNING/MainProcess] File "C:\inetpub\sites\edu-dev.coko38.ru\venv\lib\site-packages\django\db\models\sql\compiler.py", line 1359, in execute_sql
    cursor = self.connection.cursor()
[2022-07-08 13:20:10,093: WARNING/MainProcess] File "C:\inetpub\sites\edu-dev.coko38.ru\venv\lib\site-packages\django\utils\asyncio.py", line 26, in inner
    return func(*args, **kwargs)
[2022-07-08 13:20:10,093: WARNING/MainProcess] File "C:\inetpub\sites\edu-dev.coko38.ru\venv\lib\site-packages\django\db\backends\base\base.py", line 284, in cursor
    return self._cursor()
[2022-07-08 13:20:10,093: WARNING/MainProcess] File "C:\inetpub\sites\edu-dev.coko38.ru\venv\lib\site-packages\mssql\base.py", line 230, in _cursor
    conn = super()._cursor()
[2022-07-08 13:20:10,093: WARNING/MainProcess] File "C:\inetpub\sites\edu-dev.coko38.ru\venv\lib\site-packages\django\db\backends\base\base.py", line 262, in _cursor
    return self._prepare_cursor(self.create_cursor(name))
[2022-07-08 13:20:10,093: WARNING/MainProcess] File "C:\inetpub\sites\edu-dev.coko38.ru\venv\lib\site-packages\django\db\backends\base\base.py", line 252, in _prepare_cursor
    self.validate_thread_sharing()
[2022-07-08 13:20:10,093: WARNING/MainProcess] File "C:\inetpub\sites\edu-dev.coko38.ru\venv\lib\site-packages\django\db\backends\base\base.py", line 589, in validate_thread_sharing
    raise DatabaseError(
[2022-07-08 13:20:10,093: WARNING/MainProcess] django.db.utils.DatabaseError: DatabaseWrapper objects created in a thread can only be used in that same thread. The object with alias 'default' was created in thread id 2495561913264 and this is thread id 2495776458528.
[2022-07-08 13:20:10,093: WARNING/MainProcess] During handling of the above exception, another exception occurred:
[2022-07-08 13:20:10,093: WARNING/MainProcess] Traceback (most recent call last):
[2022-07-08 13:20:10,093: WARNING/MainProcess] File "C:\Python39\lib\logging\__init__.py", line 1086, in emit
    stream.write(msg + self.terminator)
[2022-07-08 13:20:10,093: WARNING/MainProcess] File "C:\Python39\lib\encodings\cp1252.py", line 19, in encode
    return codecs.charmap_encode(input,self.errors,encoding_table)[0]
[2022-07-08 13:20:10,093: WARNING/MainProcess] UnicodeEncodeError: 'charmap' codec can't encode characters in position 867-870: character maps to <undefined>
[2022-07-08 13:20:10,106: WARNING/MainProcess] Call stack:
[2022-07-08 13:20:10,106: WARNING/MainProcess] File "C:\inetpub\sites\edu-dev.coko38.ru\venv\lib\site-packages\eventlet\greenpool.py", line 88, in _spawn_n_impl
    func(*args, **kwargs)
[2022-07-08 13:20:10,106: WARNING/MainProcess] File "C:\inetpub\sites\edu-dev.coko38.ru\venv\lib\site-packages\celery\concurrency\eventlet.py", line 33, in apply_target
    return base.apply_target(target, args, kwargs, callback, accept_callback,
[2022-07-08 13:20:10,106: WARNING/MainProcess] File "C:\inetpub\sites\edu-dev.coko38.ru\venv\lib\site-packages\celery\concurrency\base.py", line 31, in apply_target
    ret = target(*args, **kwargs)
[2022-07-08 13:20:10,106: WARNING/MainProcess] File "C:\inetpub\sites\edu-dev.coko38.ru\venv\lib\site-packages\celery\app\trace.py", line 555, in _fast_trace_task
    R, I, T, Rstr = tasks[task].__trace__(
[2022-07-08 13:20:10,106: WARNING/MainProcess] File "C:\inetpub\sites\edu-dev.coko38.ru\venv\lib\site-packages\celery\app\trace.py", line 399, in trace_task
    I, R, state, retval = on_error(task_request, exc, uuid)
[2022-07-08 13:20:10,106: WARNING/MainProcess] File "C:\inetpub\sites\edu-dev.coko38.ru\venv\lib\site-packages\celery\app\trace.py", line 338, in on_error
    R = I.handle_error_state(
[2022-07-08 13:20:10,106: WARNING/MainProcess] File "C:\inetpub\sites\edu-dev.coko38.ru\venv\lib\site-packages\celery\app\trace.py", line 167, in handle_error_state
    return {
[2022-07-08 13:20:10,106: WARNING/MainProcess] File "C:\inetpub\sites\edu-dev.coko38.ru\venv\lib\site-packages\celery\app\trace.py", line 226, in handle_failure
    self._log_error(task, req, einfo)
[2022-07-08 13:20:10,106: WARNING/MainProcess] File "C:\inetpub\sites\edu-dev.coko38.ru\venv\lib\site-packages\celery\app\trace.py", line 254, in _log_error
    logger.log(policy.severity, policy.format.strip(), context,
[2022-07-08 13:20:10,106: ERROR/MainProcess] Signal handler <bound method DjangoWorkerFixup.on_task_postrun of <celery.fixups.django.DjangoWorkerFixup object at 0x000002450BA98100>> raised: DatabaseError("DatabaseWrapper objects created in a thread can only be used in that same thread. The object with alias 'default' was created in thread id 2495561913264 and this is thread id 2495776458528.")
Traceback (most recent call last):
  File "C:\inetpub\sites\edu-dev.coko38.ru\venv\lib\site-packages\celery\utils\dispatch\signal.py", line 288, in send
    response = receiver(signal=self, sender=sender, **named)
  File "C:\inetpub\sites\edu-dev.coko38.ru\venv\lib\site-packages\celery\fixups\django.py", line 172, in on_task_postrun
    self.close_database()
  File "C:\inetpub\sites\edu-dev.coko38.ru\venv\lib\site-packages\celery\fixups\django.py", line 177, in close_database
    return self._close_database()
  File "C:\inetpub\sites\edu-dev.coko38.ru\venv\lib\site-packages\celery\fixups\django.py", line 186, in _close_database
    conn.close_if_unusable_or_obsolete()
  File "C:\inetpub\sites\edu-dev.coko38.ru\venv\lib\site-packages\django\db\backends\base\base.py", line 559, in close_if_unusable_or_obsolete
    self.close()
  File "C:\inetpub\sites\edu-dev.coko38.ru\venv\lib\site-packages\django\utils\asyncio.py", line 26, in inner
    return func(*args, **kwargs)
  File "C:\inetpub\sites\edu-dev.coko38.ru\venv\lib\site-packages\django\db\backends\base\base.py", line 310, in close
    self.validate_thread_sharing()
  File "C:\inetpub\sites\edu-dev.coko38.ru\venv\lib\site-packages\django\db\backends\base\base.py", line 589, in validate_thread_sharing
    raise DatabaseError(
django.db.utils.DatabaseError: DatabaseWrapper objects created in a thread can only be used in that same thread. The object with alias 'default' was created in thread id 2495561913264 and this is thread id 2495776458528.
[2022-07-08 13:23:18,120: INFO/MainProcess] Connected to redis://172.16.55.20:6379/0
[2022-07-08 13:23:18,152: INFO/MainProcess] mingle: searching for neighbors
[2022-07-08 13:23:19,171: INFO/MainProcess] mingle: all alone
[2022-07-08 13:23:19,187: INFO/MainProcess] pidbox: Connected to redis://172.16.55.20:6379/0.
[2022-07-08 13:23:19,203: WARNING/MainProcess] C:\inetpub\sites\edu-dev.coko38.ru\venv\lib\site-packages\celery\fixups\django.py:202: UserWarning: Using settings.DEBUG leads to a memory leak, never use this setting in production environments!
  warnings.warn('Using settings.DEBUG leads to a memory leak, never '
[2022-07-08 13:23:19,203: INFO/MainProcess] celery@srv-dev ready.
[2022-07-08 13:26:06,344: INFO/MainProcess] Connected to redis://172.16.55.20:6379/0
[2022-07-08 13:26:06,344: INFO/MainProcess] mingle: searching for neighbors
[2022-07-08 13:26:07,412: INFO/MainProcess] mingle: all alone
[2022-07-08 13:26:07,443: INFO/MainProcess] pidbox: Connected to redis://172.16.55.20:6379/0.
[2022-07-08 13:26:07,443: WARNING/MainProcess] C:\inetpub\sites\edu-dev.coko38.ru\venv\lib\site-packages\celery\fixups\django.py:202: UserWarning: Using settings.DEBUG leads to a memory leak, never use this setting in production environments!
  warnings.warn('Using settings.DEBUG leads to a memory leak, never '
[2022-07-08 13:26:07,443: INFO/MainProcess] celery@srv-dev ready.
[2022-07-08 13:27:42,677: INFO/MainProcess] Connected to redis://172.16.55.20:6379/0
[2022-07-08 13:27:42,692: INFO/MainProcess] mingle: searching for neighbors
[2022-07-08 13:27:43,757: INFO/MainProcess] mingle: all alone
[2022-07-08 13:27:43,789: INFO/MainProcess] pidbox: Connected to redis://172.16.55.20:6379/0.
[2022-07-08 13:27:43,789: WARNING/MainProcess] C:\inetpub\sites\edu-dev.coko38.ru\venv\lib\site-packages\celery\fixups\django.py:202: UserWarning: Using settings.DEBUG leads to a memory leak, never use this setting in production environments!
  warnings.warn('Using settings.DEBUG leads to a memory leak, never '
[2022-07-08 13:27:43,789: INFO/MainProcess] celery@srv-dev ready.
[2022-07-08 13:41:27,001: INFO/MainProcess] Connected to redis://172.16.55.20:6379/0
[2022-07-08 13:41:27,016: INFO/MainProcess] mingle: searching for neighbors
[2022-07-08 13:41:28,049: INFO/MainProcess] mingle: all alone
[2022-07-08 13:41:28,065: INFO/MainProcess] pidbox: Connected to redis://172.16.55.20:6379/0.
[2022-07-08 13:41:28,096: WARNING/MainProcess] C:\inetpub\sites\edu-dev.coko38.ru\venv\lib\site-packages\celery\fixups\django.py:202: UserWarning: Using settings.DEBUG leads to a memory leak, never use this setting in production environments!
  warnings.warn('Using settings.DEBUG leads to a memory leak, never '
[2022-07-08 13:41:28,096: INFO/MainProcess] celery@srv-dev ready.
[2022-07-08 13:49:02,985: INFO/MainProcess] Connected to redis://172.16.55.20:6379/0
[2022-07-08 13:49:03,016: INFO/MainProcess] mingle: searching for neighbors
[2022-07-08 13:49:04,071: INFO/MainProcess] mingle: all alone
[2022-07-08 13:49:04,102: WARNING/MainProcess] C:\inetpub\sites\edu-dev.coko38.ru\venv\lib\site-packages\celery\fixups\django.py:202: UserWarning: Using settings.DEBUG leads to a memory leak, never use this setting in production environments!
  warnings.warn('Using settings.DEBUG leads to a memory leak, never '
[2022-07-08 13:49:04,102: INFO/MainProcess] celery@srv-dev ready.
[2022-07-08 13:49:04,117: INFO/MainProcess] pidbox: Connected to redis://172.16.55.20:6379/0.
[2022-07-08 13:57:16,596: INFO/MainProcess] Connected to redis://172.16.55.20:6379/0
[2022-07-08 13:57:16,611: INFO/MainProcess] mingle: searching for neighbors
[2022-07-08 13:57:17,661: INFO/MainProcess] mingle: all alone
[2022-07-08 13:57:17,707: WARNING/MainProcess] C:\inetpub\sites\edu-dev.coko38.ru\venv\lib\site-packages\celery\fixups\django.py:202: UserWarning: Using settings.DEBUG leads to a memory leak, never use this setting in production environments!
  warnings.warn('Using settings.DEBUG leads to a memory leak, never '
[2022-07-08 13:57:17,707: INFO/MainProcess] celery@srv-dev ready.
[2022-07-08 13:57:17,739: INFO/MainProcess] pidbox: Connected to redis://172.16.55.20:6379/0.
[2022-07-09 08:00:00,106: INFO/MainProcess] Received task: centre.tasks.ShowSurveyUrl[3f5a38d3-ce17-4926-84cd-542fdf212f99]  
[2022-07-09 08:00:01,126: INFO/MainProcess] Received task: centre.tasks.CheckRegistrationEnd[40ca3f01-a19a-42b8-baf0-6a82471ed4fa]  
[2022-07-09 08:00:01,126: ERROR/MainProcess] Signal handler <bound method DjangoWorkerFixup.on_task_prerun of <celery.fixups.django.DjangoWorkerFixup object at 0x000001D8A3688100>> raised: DatabaseError("DatabaseWrapper objects created in a thread can only be used in that same thread. The object with alias 'default' was created in thread id 2029956420528 and this is thread id 2030177084688.")
Traceback (most recent call last):
  File "C:\inetpub\sites\edu-dev.coko38.ru\venv\lib\site-packages\celery\utils\dispatch\signal.py", line 288, in send
    response = receiver(signal=self, sender=sender, **named)
  File "C:\inetpub\sites\edu-dev.coko38.ru\venv\lib\site-packages\celery\fixups\django.py", line 166, in on_task_prerun
    self.close_database()
  File "C:\inetpub\sites\edu-dev.coko38.ru\venv\lib\site-packages\celery\fixups\django.py", line 177, in close_database
    return self._close_database()
  File "C:\inetpub\sites\edu-dev.coko38.ru\venv\lib\site-packages\celery\fixups\django.py", line 186, in _close_database
    conn.close_if_unusable_or_obsolete()
  File "C:\inetpub\sites\edu-dev.coko38.ru\venv\lib\site-packages\django\db\backends\base\base.py", line 559, in close_if_unusable_or_obsolete
    self.close()
  File "C:\inetpub\sites\edu-dev.coko38.ru\venv\lib\site-packages\django\utils\asyncio.py", line 26, in inner
    return func(*args, **kwargs)
  File "C:\inetpub\sites\edu-dev.coko38.ru\venv\lib\site-packages\django\db\backends\base\base.py", line 310, in close
    self.validate_thread_sharing()
  File "C:\inetpub\sites\edu-dev.coko38.ru\venv\lib\site-packages\django\db\backends\base\base.py", line 589, in validate_thread_sharing
    raise DatabaseError(
django.db.utils.DatabaseError: DatabaseWrapper objects created in a thread can only be used in that same thread. The object with alias 'default' was created in thread id 2029956420528 and this is thread id 2030177084688.
[2022-07-09 08:00:01,157: WARNING/MainProcess] --- Logging error ---
[2022-07-09 08:00:01,235: WARNING/MainProcess] Traceback (most recent call last):
[2022-07-09 08:00:01,235: WARNING/MainProcess] File "C:\inetpub\sites\edu-dev.coko38.ru\venv\lib\site-packages\celery\app\trace.py", line 385, in trace_task
    R = retval = fun(*args, **kwargs)
[2022-07-09 08:00:01,235: WARNING/MainProcess] File "C:\inetpub\sites\edu-dev.coko38.ru\venv\lib\site-packages\celery\app\trace.py", line 648, in __protected_call__
    return self.run(*args, **kwargs)
[2022-07-09 08:00:01,313: WARNING/MainProcess] File "C:\inetpub\sites\edu-dev.coko38.ru\venv\lib\site-packages\django\db\models\manager.py", line 85, in manager_method
    return getattr(self.get_queryset(), name)(*args, **kwargs)
[2022-07-09 08:00:01,313: WARNING/MainProcess] File "C:\inetpub\sites\edu-dev.coko38.ru\venv\lib\site-packages\django\db\models\query.py", line 492, in get
    num = len(clone)
[2022-07-09 08:00:01,313: WARNING/MainProcess] File "C:\inetpub\sites\edu-dev.coko38.ru\venv\lib\site-packages\django\db\models\query.py", line 302, in __len__
    self._fetch_all()
[2022-07-09 08:00:01,313: WARNING/MainProcess] File "C:\inetpub\sites\edu-dev.coko38.ru\venv\lib\site-packages\django\db\models\query.py", line 1507, in _fetch_all
    self._result_cache = list(self._iterable_class(self))
[2022-07-09 08:00:01,313: WARNING/MainProcess] File "C:\inetpub\sites\edu-dev.coko38.ru\venv\lib\site-packages\django\db\models\query.py", line 57, in __iter__
    results = compiler.execute_sql(
[2022-07-09 08:00:01,313: WARNING/MainProcess] File "C:\inetpub\sites\edu-dev.coko38.ru\venv\lib\site-packages\django\db\models\sql\compiler.py", line 1359, in execute_sql
    cursor = self.connection.cursor()
[2022-07-09 08:00:01,313: WARNING/MainProcess] File "C:\inetpub\sites\edu-dev.coko38.ru\venv\lib\site-packages\django\utils\asyncio.py", line 26, in inner
    return func(*args, **kwargs)
[2022-07-09 08:00:01,313: WARNING/MainProcess] File "C:\inetpub\sites\edu-dev.coko38.ru\venv\lib\site-packages\django\db\backends\base\base.py", line 284, in cursor
    return self._cursor()
[2022-07-09 08:00:01,313: WARNING/MainProcess] File "C:\inetpub\sites\edu-dev.coko38.ru\venv\lib\site-packages\mssql\base.py", line 230, in _cursor
    conn = super()._cursor()
[2022-07-09 08:00:01,313: WARNING/MainProcess] File "C:\inetpub\sites\edu-dev.coko38.ru\venv\lib\site-packages\django\db\backends\base\base.py", line 260, in _cursor
    self.ensure_connection()
[2022-07-09 08:00:01,313: WARNING/MainProcess] File "C:\inetpub\sites\edu-dev.coko38.ru\venv\lib\site-packages\django\utils\asyncio.py", line 26, in inner
    return func(*args, **kwargs)
[2022-07-09 08:00:01,313: WARNING/MainProcess] File "C:\inetpub\sites\edu-dev.coko38.ru\venv\lib\site-packages\django\db\backends\base\base.py", line 244, in ensure_connection
    self.connect()
[2022-07-09 08:00:01,313: WARNING/MainProcess] File "C:\inetpub\sites\edu-dev.coko38.ru\venv\lib\site-packages\django\utils\asyncio.py", line 26, in inner
    return func(*args, **kwargs)
[2022-07-09 08:00:01,313: WARNING/MainProcess] File "C:\inetpub\sites\edu-dev.coko38.ru\venv\lib\site-packages\django\db\backends\base\base.py", line 227, in connect
    self.init_connection_state()
[2022-07-09 08:00:01,313: WARNING/MainProcess] File "C:\inetpub\sites\edu-dev.coko38.ru\venv\lib\site-packages\mssql\base.py", line 391, in init_connection_state
    val = self.get_system_datetime()
[2022-07-09 08:00:01,313: WARNING/MainProcess] File "C:\inetpub\sites\edu-dev.coko38.ru\venv\lib\site-packages\mssql\base.py", line 406, in get_system_datetime
    with self.temporary_connection() as cursor:
[2022-07-09 08:00:01,329: WARNING/MainProcess] File "C:\Python39\lib\contextlib.py", line 119, in __enter__
    return next(self.gen)
[2022-07-09 08:00:01,329: WARNING/MainProcess] File "C:\inetpub\sites\edu-dev.coko38.ru\venv\lib\site-packages\django\db\backends\base\base.py", line 639, in temporary_connection
    with self.cursor() as cursor:
[2022-07-09 08:00:01,329: WARNING/MainProcess] File "C:\inetpub\sites\edu-dev.coko38.ru\venv\lib\site-packages\django\utils\asyncio.py", line 26, in inner
    return func(*args, **kwargs)
[2022-07-09 08:00:01,329: WARNING/MainProcess] File "C:\inetpub\sites\edu-dev.coko38.ru\venv\lib\site-packages\django\db\backends\base\base.py", line 284, in cursor
    return self._cursor()
[2022-07-09 08:00:01,329: WARNING/MainProcess] File "C:\inetpub\sites\edu-dev.coko38.ru\venv\lib\site-packages\mssql\base.py", line 230, in _cursor
    conn = super()._cursor()
[2022-07-09 08:00:01,329: WARNING/MainProcess] File "C:\inetpub\sites\edu-dev.coko38.ru\venv\lib\site-packages\django\db\backends\base\base.py", line 262, in _cursor
    return self._prepare_cursor(self.create_cursor(name))
[2022-07-09 08:00:01,329: WARNING/MainProcess] File "C:\inetpub\sites\edu-dev.coko38.ru\venv\lib\site-packages\django\db\backends\base\base.py", line 252, in _prepare_cursor
    self.validate_thread_sharing()
[2022-07-09 08:00:01,329: WARNING/MainProcess] File "C:\inetpub\sites\edu-dev.coko38.ru\venv\lib\site-packages\django\db\backends\base\base.py", line 589, in validate_thread_sharing
    raise DatabaseError(
[2022-07-09 08:00:01,329: WARNING/MainProcess] django.db.utils.DatabaseError: DatabaseWrapper objects created in a thread can only be used in that same thread. The object with alias 'default' was created in thread id 2029956420528 and this is thread id 2030175467648.
[2022-07-09 08:00:01,329: WARNING/MainProcess] During handling of the above exception, another exception occurred:
[2022-07-09 08:00:01,329: WARNING/MainProcess] Traceback (most recent call last):
[2022-07-09 08:00:01,329: WARNING/MainProcess] File "C:\Python39\lib\logging\__init__.py", line 1086, in emit
    stream.write(msg + self.terminator)
[2022-07-09 08:00:01,329: WARNING/MainProcess] File "C:\Python39\lib\encodings\cp1252.py", line 19, in encode
    return codecs.charmap_encode(input,self.errors,encoding_table)[0]
[2022-07-09 08:00:01,329: WARNING/MainProcess] UnicodeEncodeError: 'charmap' codec can't encode characters in position 867-870: character maps to <undefined>
[2022-07-09 08:00:01,329: WARNING/MainProcess] Call stack:
[2022-07-09 08:00:01,329: WARNING/MainProcess] File "C:\inetpub\sites\edu-dev.coko38.ru\venv\lib\site-packages\eventlet\greenpool.py", line 88, in _spawn_n_impl
    func(*args, **kwargs)
[2022-07-09 08:00:01,329: WARNING/MainProcess] File "C:\inetpub\sites\edu-dev.coko38.ru\venv\lib\site-packages\celery\concurrency\eventlet.py", line 33, in apply_target
    return base.apply_target(target, args, kwargs, callback, accept_callback,
[2022-07-09 08:00:01,329: WARNING/MainProcess] File "C:\inetpub\sites\edu-dev.coko38.ru\venv\lib\site-packages\celery\concurrency\base.py", line 31, in apply_target
    ret = target(*args, **kwargs)
[2022-07-09 08:00:01,329: WARNING/MainProcess] File "C:\inetpub\sites\edu-dev.coko38.ru\venv\lib\site-packages\celery\app\trace.py", line 555, in _fast_trace_task
    R, I, T, Rstr = tasks[task].__trace__(
[2022-07-09 08:00:01,329: WARNING/MainProcess] File "C:\inetpub\sites\edu-dev.coko38.ru\venv\lib\site-packages\celery\app\trace.py", line 399, in trace_task
    I, R, state, retval = on_error(task_request, exc, uuid)
[2022-07-09 08:00:01,329: WARNING/MainProcess] File "C:\inetpub\sites\edu-dev.coko38.ru\venv\lib\site-packages\celery\app\trace.py", line 338, in on_error
    R = I.handle_error_state(
[2022-07-09 08:00:01,329: WARNING/MainProcess] File "C:\inetpub\sites\edu-dev.coko38.ru\venv\lib\site-packages\celery\app\trace.py", line 167, in handle_error_state
    return {
[2022-07-09 08:00:01,329: WARNING/MainProcess] File "C:\inetpub\sites\edu-dev.coko38.ru\venv\lib\site-packages\celery\app\trace.py", line 226, in handle_failure
    self._log_error(task, req, einfo)
[2022-07-09 08:00:01,329: WARNING/MainProcess] File "C:\inetpub\sites\edu-dev.coko38.ru\venv\lib\site-packages\celery\app\trace.py", line 254, in _log_error
    logger.log(policy.severity, policy.format.strip(), context,
[2022-07-09 08:00:01,344: ERROR/MainProcess] Signal handler <bound method DjangoWorkerFixup.on_task_postrun of <celery.fixups.django.DjangoWorkerFixup object at 0x000001D8A3688100>> raised: DatabaseError("DatabaseWrapper objects created in a thread can only be used in that same thread. The object with alias 'default' was created in thread id 2029956420528 and this is thread id 2030175467648.")
Traceback (most recent call last):
  File "C:\inetpub\sites\edu-dev.coko38.ru\venv\lib\site-packages\celery\utils\dispatch\signal.py", line 288, in send
    response = receiver(signal=self, sender=sender, **named)
  File "C:\inetpub\sites\edu-dev.coko38.ru\venv\lib\site-packages\celery\fixups\django.py", line 172, in on_task_postrun
    self.close_database()
  File "C:\inetpub\sites\edu-dev.coko38.ru\venv\lib\site-packages\celery\fixups\django.py", line 177, in close_database
    return self._close_database()
  File "C:\inetpub\sites\edu-dev.coko38.ru\venv\lib\site-packages\celery\fixups\django.py", line 186, in _close_database
    conn.close_if_unusable_or_obsolete()
  File "C:\inetpub\sites\edu-dev.coko38.ru\venv\lib\site-packages\django\db\backends\base\base.py", line 559, in close_if_unusable_or_obsolete
    self.close()
  File "C:\inetpub\sites\edu-dev.coko38.ru\venv\lib\site-packages\django\utils\asyncio.py", line 26, in inner
    return func(*args, **kwargs)
  File "C:\inetpub\sites\edu-dev.coko38.ru\venv\lib\site-packages\django\db\backends\base\base.py", line 310, in close
    self.validate_thread_sharing()
  File "C:\inetpub\sites\edu-dev.coko38.ru\venv\lib\site-packages\django\db\backends\base\base.py", line 589, in validate_thread_sharing
    raise DatabaseError(
django.db.utils.DatabaseError: DatabaseWrapper objects created in a thread can only be used in that same thread. The object with alias 'default' was created in thread id 2029956420528 and this is thread id 2030175467648.
[2022-07-09 08:00:01,344: WARNING/MainProcess] --- Logging error ---
[2022-07-09 08:00:01,344: WARNING/MainProcess] Traceback (most recent call last):
[2022-07-09 08:00:01,344: WARNING/MainProcess] File "C:\inetpub\sites\edu-dev.coko38.ru\venv\lib\site-packages\celery\app\trace.py", line 385, in trace_task
    R = retval = fun(*args, **kwargs)
[2022-07-09 08:00:01,344: WARNING/MainProcess] File "C:\inetpub\sites\edu-dev.coko38.ru\venv\lib\site-packages\celery\app\trace.py", line 648, in __protected_call__
    return self.run(*args, **kwargs)
[2022-07-09 08:00:01,344: WARNING/MainProcess] File "C:\inetpub\sites\edu-dev.coko38.ru\venv\lib\site-packages\django\db\models\manager.py", line 85, in manager_method
    return getattr(self.get_queryset(), name)(*args, **kwargs)
[2022-07-09 08:00:01,344: WARNING/MainProcess] File "C:\inetpub\sites\edu-dev.coko38.ru\venv\lib\site-packages\django\db\models\query.py", line 492, in get
    num = len(clone)
[2022-07-09 08:00:01,344: WARNING/MainProcess] File "C:\inetpub\sites\edu-dev.coko38.ru\venv\lib\site-packages\django\db\models\query.py", line 302, in __len__
    self._fetch_all()
[2022-07-09 08:00:01,344: WARNING/MainProcess] File "C:\inetpub\sites\edu-dev.coko38.ru\venv\lib\site-packages\django\db\models\query.py", line 1507, in _fetch_all
    self._result_cache = list(self._iterable_class(self))
[2022-07-09 08:00:01,344: WARNING/MainProcess] File "C:\inetpub\sites\edu-dev.coko38.ru\venv\lib\site-packages\django\db\models\query.py", line 57, in __iter__
    results = compiler.execute_sql(
[2022-07-09 08:00:01,344: WARNING/MainProcess] File "C:\inetpub\sites\edu-dev.coko38.ru\venv\lib\site-packages\django\db\models\sql\compiler.py", line 1359, in execute_sql
    cursor = self.connection.cursor()
[2022-07-09 08:00:01,344: WARNING/MainProcess] File "C:\inetpub\sites\edu-dev.coko38.ru\venv\lib\site-packages\django\utils\asyncio.py", line 26, in inner
    return func(*args, **kwargs)
[2022-07-09 08:00:01,344: WARNING/MainProcess] File "C:\inetpub\sites\edu-dev.coko38.ru\venv\lib\site-packages\django\db\backends\base\base.py", line 284, in cursor
    return self._cursor()
[2022-07-09 08:00:01,344: WARNING/MainProcess] File "C:\inetpub\sites\edu-dev.coko38.ru\venv\lib\site-packages\mssql\base.py", line 230, in _cursor
    conn = super()._cursor()
[2022-07-09 08:00:01,344: WARNING/MainProcess] File "C:\inetpub\sites\edu-dev.coko38.ru\venv\lib\site-packages\django\db\backends\base\base.py", line 262, in _cursor
    return self._prepare_cursor(self.create_cursor(name))
[2022-07-09 08:00:01,344: WARNING/MainProcess] File "C:\inetpub\sites\edu-dev.coko38.ru\venv\lib\site-packages\django\db\backends\base\base.py", line 252, in _prepare_cursor
    self.validate_thread_sharing()
[2022-07-09 08:00:01,344: WARNING/MainProcess] File "C:\inetpub\sites\edu-dev.coko38.ru\venv\lib\site-packages\django\db\backends\base\base.py", line 589, in validate_thread_sharing
    raise DatabaseError(
[2022-07-09 08:00:01,344: WARNING/MainProcess] django.db.utils.DatabaseError: DatabaseWrapper objects created in a thread can only be used in that same thread. The object with alias 'default' was created in thread id 2029956420528 and this is thread id 2030177084688.
[2022-07-09 08:00:01,344: WARNING/MainProcess] During handling of the above exception, another exception occurred:
[2022-07-09 08:00:01,344: WARNING/MainProcess] Traceback (most recent call last):
[2022-07-09 08:00:01,344: WARNING/MainProcess] File "C:\Python39\lib\logging\__init__.py", line 1086, in emit
    stream.write(msg + self.terminator)
[2022-07-09 08:00:01,344: WARNING/MainProcess] File "C:\Python39\lib\encodings\cp1252.py", line 19, in encode
    return codecs.charmap_encode(input,self.errors,encoding_table)[0]
[2022-07-09 08:00:01,344: WARNING/MainProcess] UnicodeEncodeError: 'charmap' codec can't encode characters in position 881-884: character maps to <undefined>
[2022-07-09 08:00:01,344: WARNING/MainProcess] Call stack:
[2022-07-09 08:00:01,360: WARNING/MainProcess] File "C:\inetpub\sites\edu-dev.coko38.ru\venv\lib\site-packages\eventlet\greenpool.py", line 88, in _spawn_n_impl
    func(*args, **kwargs)
[2022-07-09 08:00:01,360: WARNING/MainProcess] File "C:\inetpub\sites\edu-dev.coko38.ru\venv\lib\site-packages\celery\concurrency\eventlet.py", line 33, in apply_target
    return base.apply_target(target, args, kwargs, callback, accept_callback,
[2022-07-09 08:00:01,360: WARNING/MainProcess] File "C:\inetpub\sites\edu-dev.coko38.ru\venv\lib\site-packages\celery\concurrency\base.py", line 31, in apply_target
    ret = target(*args, **kwargs)
[2022-07-09 08:00:01,360: WARNING/MainProcess] File "C:\inetpub\sites\edu-dev.coko38.ru\venv\lib\site-packages\celery\app\trace.py", line 555, in _fast_trace_task
    R, I, T, Rstr = tasks[task].__trace__(
[2022-07-09 08:00:01,360: WARNING/MainProcess] File "C:\inetpub\sites\edu-dev.coko38.ru\venv\lib\site-packages\celery\app\trace.py", line 399, in trace_task
    I, R, state, retval = on_error(task_request, exc, uuid)
[2022-07-09 08:00:01,360: WARNING/MainProcess] File "C:\inetpub\sites\edu-dev.coko38.ru\venv\lib\site-packages\celery\app\trace.py", line 338, in on_error
    R = I.handle_error_state(
[2022-07-09 08:00:01,360: WARNING/MainProcess] File "C:\inetpub\sites\edu-dev.coko38.ru\venv\lib\site-packages\celery\app\trace.py", line 167, in handle_error_state
    return {
[2022-07-09 08:00:01,360: WARNING/MainProcess] File "C:\inetpub\sites\edu-dev.coko38.ru\venv\lib\site-packages\celery\app\trace.py", line 226, in handle_failure
    self._log_error(task, req, einfo)
[2022-07-09 08:00:01,360: WARNING/MainProcess] File "C:\inetpub\sites\edu-dev.coko38.ru\venv\lib\site-packages\celery\app\trace.py", line 254, in _log_error
    logger.log(policy.severity, policy.format.strip(), context,
[2022-07-09 08:00:01,360: ERROR/MainProcess] Signal handler <bound method DjangoWorkerFixup.on_task_postrun of <celery.fixups.django.DjangoWorkerFixup object at 0x000001D8A3688100>> raised: DatabaseError("DatabaseWrapper objects created in a thread can only be used in that same thread. The object with alias 'default' was created in thread id 2029956420528 and this is thread id 2030177084688.")
Traceback (most recent call last):
  File "C:\inetpub\sites\edu-dev.coko38.ru\venv\lib\site-packages\celery\utils\dispatch\signal.py", line 288, in send
    response = receiver(signal=self, sender=sender, **named)
  File "C:\inetpub\sites\edu-dev.coko38.ru\venv\lib\site-packages\celery\fixups\django.py", line 172, in on_task_postrun
    self.close_database()
  File "C:\inetpub\sites\edu-dev.coko38.ru\venv\lib\site-packages\celery\fixups\django.py", line 177, in close_database
    return self._close_database()
  File "C:\inetpub\sites\edu-dev.coko38.ru\venv\lib\site-packages\celery\fixups\django.py", line 186, in _close_database
    conn.close_if_unusable_or_obsolete()
  File "C:\inetpub\sites\edu-dev.coko38.ru\venv\lib\site-packages\django\db\backends\base\base.py", line 559, in close_if_unusable_or_obsolete
    self.close()
  File "C:\inetpub\sites\edu-dev.coko38.ru\venv\lib\site-packages\django\utils\asyncio.py", line 26, in inner
    return func(*args, **kwargs)
  File "C:\inetpub\sites\edu-dev.coko38.ru\venv\lib\site-packages\django\db\backends\base\base.py", line 310, in close
    self.validate_thread_sharing()
  File "C:\inetpub\sites\edu-dev.coko38.ru\venv\lib\site-packages\django\db\backends\base\base.py", line 589, in validate_thread_sharing
    raise DatabaseError(
django.db.utils.DatabaseError: DatabaseWrapper objects created in a thread can only be used in that same thread. The object with alias 'default' was created in thread id 2029956420528 and this is thread id 2030177084688.
[2022-07-10 08:00:00,029: INFO/MainProcess] Received task: centre.tasks.CheckRegistrationEnd[916842af-9cc3-4d04-815e-b9a42873685b]  
[2022-07-10 08:00:00,029: ERROR/MainProcess] Signal handler <bound method DjangoWorkerFixup.on_task_prerun of <celery.fixups.django.DjangoWorkerFixup object at 0x000001D8A3688100>> raised: DatabaseError("DatabaseWrapper objects created in a thread can only be used in that same thread. The object with alias 'default' was created in thread id 2029956420528 and this is thread id 2030175468000.")
Traceback (most recent call last):
  File "C:\inetpub\sites\edu-dev.coko38.ru\venv\lib\site-packages\celery\utils\dispatch\signal.py", line 288, in send
    response = receiver(signal=self, sender=sender, **named)
  File "C:\inetpub\sites\edu-dev.coko38.ru\venv\lib\site-packages\celery\fixups\django.py", line 166, in on_task_prerun
    self.close_database()
  File "C:\inetpub\sites\edu-dev.coko38.ru\venv\lib\site-packages\celery\fixups\django.py", line 177, in close_database
    return self._close_database()
  File "C:\inetpub\sites\edu-dev.coko38.ru\venv\lib\site-packages\celery\fixups\django.py", line 186, in _close_database
    conn.close_if_unusable_or_obsolete()
  File "C:\inetpub\sites\edu-dev.coko38.ru\venv\lib\site-packages\django\db\backends\base\base.py", line 559, in close_if_unusable_or_obsolete
    self.close()
  File "C:\inetpub\sites\edu-dev.coko38.ru\venv\lib\site-packages\django\utils\asyncio.py", line 26, in inner
    return func(*args, **kwargs)
  File "C:\inetpub\sites\edu-dev.coko38.ru\venv\lib\site-packages\django\db\backends\base\base.py", line 310, in close
    self.validate_thread_sharing()
  File "C:\inetpub\sites\edu-dev.coko38.ru\venv\lib\site-packages\django\db\backends\base\base.py", line 589, in validate_thread_sharing
    raise DatabaseError(
django.db.utils.DatabaseError: DatabaseWrapper objects created in a thread can only be used in that same thread. The object with alias 'default' was created in thread id 2029956420528 and this is thread id 2030175468000.
[2022-07-10 08:00:00,060: INFO/MainProcess] Received task: centre.tasks.ShowSurveyUrl[da04ecbf-5f90-41ff-9960-06afa8a986a5]  
[2022-07-10 08:00:00,060: ERROR/MainProcess] Signal handler <bound method DjangoWorkerFixup.on_task_prerun of <celery.fixups.django.DjangoWorkerFixup object at 0x000001D8A3688100>> raised: DatabaseError("DatabaseWrapper objects created in a thread can only be used in that same thread. The object with alias 'default' was created in thread id 2029956420528 and this is thread id 2030169376544.")
Traceback (most recent call last):
  File "C:\inetpub\sites\edu-dev.coko38.ru\venv\lib\site-packages\celery\utils\dispatch\signal.py", line 288, in send
    response = receiver(signal=self, sender=sender, **named)
  File "C:\inetpub\sites\edu-dev.coko38.ru\venv\lib\site-packages\celery\fixups\django.py", line 166, in on_task_prerun
    self.close_database()
  File "C:\inetpub\sites\edu-dev.coko38.ru\venv\lib\site-packages\celery\fixups\django.py", line 177, in close_database
    return self._close_database()
  File "C:\inetpub\sites\edu-dev.coko38.ru\venv\lib\site-packages\celery\fixups\django.py", line 186, in _close_database
    conn.close_if_unusable_or_obsolete()
  File "C:\inetpub\sites\edu-dev.coko38.ru\venv\lib\site-packages\django\db\backends\base\base.py", line 559, in close_if_unusable_or_obsolete
    self.close()
  File "C:\inetpub\sites\edu-dev.coko38.ru\venv\lib\site-packages\django\utils\asyncio.py", line 26, in inner
    return func(*args, **kwargs)
  File "C:\inetpub\sites\edu-dev.coko38.ru\venv\lib\site-packages\django\db\backends\base\base.py", line 310, in close
    self.validate_thread_sharing()
  File "C:\inetpub\sites\edu-dev.coko38.ru\venv\lib\site-packages\django\db\backends\base\base.py", line 589, in validate_thread_sharing
    raise DatabaseError(
django.db.utils.DatabaseError: DatabaseWrapper objects created in a thread can only be used in that same thread. The object with alias 'default' was created in thread id 2029956420528 and this is thread id 2030169376544.
[2022-07-10 08:00:00,060: WARNING/MainProcess] --- Logging error ---
[2022-07-10 08:00:00,076: WARNING/MainProcess] Traceback (most recent call last):
[2022-07-10 08:00:00,076: WARNING/MainProcess] File "C:\inetpub\sites\edu-dev.coko38.ru\venv\lib\site-packages\celery\app\trace.py", line 385, in trace_task
    R = retval = fun(*args, **kwargs)
[2022-07-10 08:00:00,076: WARNING/MainProcess] File "C:\inetpub\sites\edu-dev.coko38.ru\venv\lib\site-packages\celery\app\trace.py", line 648, in __protected_call__
    return self.run(*args, **kwargs)
[2022-07-10 08:00:00,076: WARNING/MainProcess] File "C:\inetpub\sites\edu-dev.coko38.ru\venv\lib\site-packages\django\db\models\manager.py", line 85, in manager_method
    return getattr(self.get_queryset(), name)(*args, **kwargs)
[2022-07-10 08:00:00,076: WARNING/MainProcess] File "C:\inetpub\sites\edu-dev.coko38.ru\venv\lib\site-packages\django\db\models\query.py", line 492, in get
    num = len(clone)
[2022-07-10 08:00:00,076: WARNING/MainProcess] File "C:\inetpub\sites\edu-dev.coko38.ru\venv\lib\site-packages\django\db\models\query.py", line 302, in __len__
    self._fetch_all()
[2022-07-10 08:00:00,076: WARNING/MainProcess] File "C:\inetpub\sites\edu-dev.coko38.ru\venv\lib\site-packages\django\db\models\query.py", line 1507, in _fetch_all
    self._result_cache = list(self._iterable_class(self))
[2022-07-10 08:00:00,076: WARNING/MainProcess] File "C:\inetpub\sites\edu-dev.coko38.ru\venv\lib\site-packages\django\db\models\query.py", line 57, in __iter__
    results = compiler.execute_sql(
[2022-07-10 08:00:00,076: WARNING/MainProcess] File "C:\inetpub\sites\edu-dev.coko38.ru\venv\lib\site-packages\django\db\models\sql\compiler.py", line 1359, in execute_sql
    cursor = self.connection.cursor()
[2022-07-10 08:00:00,076: WARNING/MainProcess] File "C:\inetpub\sites\edu-dev.coko38.ru\venv\lib\site-packages\django\utils\asyncio.py", line 26, in inner
    return func(*args, **kwargs)
[2022-07-10 08:00:00,076: WARNING/MainProcess] File "C:\inetpub\sites\edu-dev.coko38.ru\venv\lib\site-packages\django\db\backends\base\base.py", line 284, in cursor
    return self._cursor()
[2022-07-10 08:00:00,076: WARNING/MainProcess] File "C:\inetpub\sites\edu-dev.coko38.ru\venv\lib\site-packages\mssql\base.py", line 230, in _cursor
    conn = super()._cursor()
[2022-07-10 08:00:00,076: WARNING/MainProcess] File "C:\inetpub\sites\edu-dev.coko38.ru\venv\lib\site-packages\django\db\backends\base\base.py", line 262, in _cursor
    return self._prepare_cursor(self.create_cursor(name))
[2022-07-10 08:00:00,076: WARNING/MainProcess] File "C:\inetpub\sites\edu-dev.coko38.ru\venv\lib\site-packages\django\db\backends\base\base.py", line 252, in _prepare_cursor
    self.validate_thread_sharing()
[2022-07-10 08:00:00,076: WARNING/MainProcess] File "C:\inetpub\sites\edu-dev.coko38.ru\venv\lib\site-packages\django\db\backends\base\base.py", line 589, in validate_thread_sharing
    raise DatabaseError(
[2022-07-10 08:00:00,076: WARNING/MainProcess] django.db.utils.DatabaseError: DatabaseWrapper objects created in a thread can only be used in that same thread. The object with alias 'default' was created in thread id 2029956420528 and this is thread id 2030175468000.
[2022-07-10 08:00:00,076: WARNING/MainProcess] During handling of the above exception, another exception occurred:
[2022-07-10 08:00:00,076: WARNING/MainProcess] Traceback (most recent call last):
[2022-07-10 08:00:00,076: WARNING/MainProcess] File "C:\Python39\lib\logging\__init__.py", line 1086, in emit
    stream.write(msg + self.terminator)
[2022-07-10 08:00:00,076: WARNING/MainProcess] File "C:\Python39\lib\encodings\cp1252.py", line 19, in encode
    return codecs.charmap_encode(input,self.errors,encoding_table)[0]
[2022-07-10 08:00:00,092: WARNING/MainProcess] UnicodeEncodeError: 'charmap' codec can't encode characters in position 881-884: character maps to <undefined>
[2022-07-10 08:00:00,092: WARNING/MainProcess] Call stack:
[2022-07-10 08:00:00,092: WARNING/MainProcess] File "C:\inetpub\sites\edu-dev.coko38.ru\venv\lib\site-packages\eventlet\greenpool.py", line 88, in _spawn_n_impl
    func(*args, **kwargs)
[2022-07-10 08:00:00,092: WARNING/MainProcess] File "C:\inetpub\sites\edu-dev.coko38.ru\venv\lib\site-packages\celery\concurrency\eventlet.py", line 33, in apply_target
    return base.apply_target(target, args, kwargs, callback, accept_callback,
[2022-07-10 08:00:00,092: WARNING/MainProcess] File "C:\inetpub\sites\edu-dev.coko38.ru\venv\lib\site-packages\celery\concurrency\base.py", line 31, in apply_target
    ret = target(*args, **kwargs)
[2022-07-10 08:00:00,092: WARNING/MainProcess] File "C:\inetpub\sites\edu-dev.coko38.ru\venv\lib\site-packages\celery\app\trace.py", line 555, in _fast_trace_task
    R, I, T, Rstr = tasks[task].__trace__(
[2022-07-10 08:00:00,092: WARNING/MainProcess] File "C:\inetpub\sites\edu-dev.coko38.ru\venv\lib\site-packages\celery\app\trace.py", line 399, in trace_task
    I, R, state, retval = on_error(task_request, exc, uuid)
[2022-07-10 08:00:00,092: WARNING/MainProcess] File "C:\inetpub\sites\edu-dev.coko38.ru\venv\lib\site-packages\celery\app\trace.py", line 338, in on_error
    R = I.handle_error_state(
[2022-07-10 08:00:00,092: WARNING/MainProcess] File "C:\inetpub\sites\edu-dev.coko38.ru\venv\lib\site-packages\celery\app\trace.py", line 167, in handle_error_state
    return {
[2022-07-10 08:00:00,092: WARNING/MainProcess] File "C:\inetpub\sites\edu-dev.coko38.ru\venv\lib\site-packages\celery\app\trace.py", line 226, in handle_failure
    self._log_error(task, req, einfo)
[2022-07-10 08:00:00,092: WARNING/MainProcess] File "C:\inetpub\sites\edu-dev.coko38.ru\venv\lib\site-packages\celery\app\trace.py", line 254, in _log_error
    logger.log(policy.severity, policy.format.strip(), context,
[2022-07-10 08:00:00,092: ERROR/MainProcess] Signal handler <bound method DjangoWorkerFixup.on_task_postrun of <celery.fixups.django.DjangoWorkerFixup object at 0x000001D8A3688100>> raised: DatabaseError("DatabaseWrapper objects created in a thread can only be used in that same thread. The object with alias 'default' was created in thread id 2029956420528 and this is thread id 2030175468000.")
Traceback (most recent call last):
  File "C:\inetpub\sites\edu-dev.coko38.ru\venv\lib\site-packages\celery\utils\dispatch\signal.py", line 288, in send
    response = receiver(signal=self, sender=sender, **named)
  File "C:\inetpub\sites\edu-dev.coko38.ru\venv\lib\site-packages\celery\fixups\django.py", line 172, in on_task_postrun
    self.close_database()
  File "C:\inetpub\sites\edu-dev.coko38.ru\venv\lib\site-packages\celery\fixups\django.py", line 177, in close_database
    return self._close_database()
  File "C:\inetpub\sites\edu-dev.coko38.ru\venv\lib\site-packages\celery\fixups\django.py", line 186, in _close_database
    conn.close_if_unusable_or_obsolete()
  File "C:\inetpub\sites\edu-dev.coko38.ru\venv\lib\site-packages\django\db\backends\base\base.py", line 559, in close_if_unusable_or_obsolete
    self.close()
  File "C:\inetpub\sites\edu-dev.coko38.ru\venv\lib\site-packages\django\utils\asyncio.py", line 26, in inner
    return func(*args, **kwargs)
  File "C:\inetpub\sites\edu-dev.coko38.ru\venv\lib\site-packages\django\db\backends\base\base.py", line 310, in close
    self.validate_thread_sharing()
  File "C:\inetpub\sites\edu-dev.coko38.ru\venv\lib\site-packages\django\db\backends\base\base.py", line 589, in validate_thread_sharing
    raise DatabaseError(
django.db.utils.DatabaseError: DatabaseWrapper objects created in a thread can only be used in that same thread. The object with alias 'default' was created in thread id 2029956420528 and this is thread id 2030175468000.
[2022-07-10 08:00:00,092: WARNING/MainProcess] --- Logging error ---
[2022-07-10 08:00:00,092: WARNING/MainProcess] Traceback (most recent call last):
[2022-07-10 08:00:00,092: WARNING/MainProcess] File "C:\inetpub\sites\edu-dev.coko38.ru\venv\lib\site-packages\celery\app\trace.py", line 385, in trace_task
    R = retval = fun(*args, **kwargs)
[2022-07-10 08:00:00,092: WARNING/MainProcess] File "C:\inetpub\sites\edu-dev.coko38.ru\venv\lib\site-packages\celery\app\trace.py", line 648, in __protected_call__
    return self.run(*args, **kwargs)
[2022-07-10 08:00:00,092: WARNING/MainProcess] File "C:\inetpub\sites\edu-dev.coko38.ru\venv\lib\site-packages\django\db\models\manager.py", line 85, in manager_method
    return getattr(self.get_queryset(), name)(*args, **kwargs)
[2022-07-10 08:00:00,092: WARNING/MainProcess] File "C:\inetpub\sites\edu-dev.coko38.ru\venv\lib\site-packages\django\db\models\query.py", line 492, in get
    num = len(clone)
[2022-07-10 08:00:00,092: WARNING/MainProcess] File "C:\inetpub\sites\edu-dev.coko38.ru\venv\lib\site-packages\django\db\models\query.py", line 302, in __len__
    self._fetch_all()
[2022-07-10 08:00:00,092: WARNING/MainProcess] File "C:\inetpub\sites\edu-dev.coko38.ru\venv\lib\site-packages\django\db\models\query.py", line 1507, in _fetch_all
    self._result_cache = list(self._iterable_class(self))
[2022-07-10 08:00:00,092: WARNING/MainProcess] File "C:\inetpub\sites\edu-dev.coko38.ru\venv\lib\site-packages\django\db\models\query.py", line 57, in __iter__
    results = compiler.execute_sql(
[2022-07-10 08:00:00,092: WARNING/MainProcess] File "C:\inetpub\sites\edu-dev.coko38.ru\venv\lib\site-packages\django\db\models\sql\compiler.py", line 1359, in execute_sql
    cursor = self.connection.cursor()
[2022-07-10 08:00:00,092: WARNING/MainProcess] File "C:\inetpub\sites\edu-dev.coko38.ru\venv\lib\site-packages\django\utils\asyncio.py", line 26, in inner
    return func(*args, **kwargs)
[2022-07-10 08:00:00,092: WARNING/MainProcess] File "C:\inetpub\sites\edu-dev.coko38.ru\venv\lib\site-packages\django\db\backends\base\base.py", line 284, in cursor
    return self._cursor()
[2022-07-10 08:00:00,092: WARNING/MainProcess] File "C:\inetpub\sites\edu-dev.coko38.ru\venv\lib\site-packages\mssql\base.py", line 230, in _cursor
    conn = super()._cursor()
[2022-07-10 08:00:00,092: WARNING/MainProcess] File "C:\inetpub\sites\edu-dev.coko38.ru\venv\lib\site-packages\django\db\backends\base\base.py", line 262, in _cursor
    return self._prepare_cursor(self.create_cursor(name))
[2022-07-10 08:00:00,092: WARNING/MainProcess] File "C:\inetpub\sites\edu-dev.coko38.ru\venv\lib\site-packages\django\db\backends\base\base.py", line 252, in _prepare_cursor
    self.validate_thread_sharing()
[2022-07-10 08:00:00,092: WARNING/MainProcess] File "C:\inetpub\sites\edu-dev.coko38.ru\venv\lib\site-packages\django\db\backends\base\base.py", line 589, in validate_thread_sharing
    raise DatabaseError(
[2022-07-10 08:00:00,107: WARNING/MainProcess] django.db.utils.DatabaseError: DatabaseWrapper objects created in a thread can only be used in that same thread. The object with alias 'default' was created in thread id 2029956420528 and this is thread id 2030169376544.
[2022-07-10 08:00:00,107: WARNING/MainProcess] During handling of the above exception, another exception occurred:
[2022-07-10 08:00:00,107: WARNING/MainProcess] Traceback (most recent call last):
[2022-07-10 08:00:00,107: WARNING/MainProcess] File "C:\Python39\lib\logging\__init__.py", line 1086, in emit
    stream.write(msg + self.terminator)
[2022-07-10 08:00:00,107: WARNING/MainProcess] File "C:\Python39\lib\encodings\cp1252.py", line 19, in encode
    return codecs.charmap_encode(input,self.errors,encoding_table)[0]
[2022-07-10 08:00:00,107: WARNING/MainProcess] UnicodeEncodeError: 'charmap' codec can't encode characters in position 867-870: character maps to <undefined>
[2022-07-10 08:00:00,107: WARNING/MainProcess] Call stack:
[2022-07-10 08:00:00,107: WARNING/MainProcess] File "C:\inetpub\sites\edu-dev.coko38.ru\venv\lib\site-packages\eventlet\greenpool.py", line 88, in _spawn_n_impl
    func(*args, **kwargs)
[2022-07-10 08:00:00,107: WARNING/MainProcess] File "C:\inetpub\sites\edu-dev.coko38.ru\venv\lib\site-packages\celery\concurrency\eventlet.py", line 33, in apply_target
    return base.apply_target(target, args, kwargs, callback, accept_callback,
[2022-07-10 08:00:00,107: WARNING/MainProcess] File "C:\inetpub\sites\edu-dev.coko38.ru\venv\lib\site-packages\celery\concurrency\base.py", line 31, in apply_target
    ret = target(*args, **kwargs)
[2022-07-10 08:00:00,107: WARNING/MainProcess] File "C:\inetpub\sites\edu-dev.coko38.ru\venv\lib\site-packages\celery\app\trace.py", line 555, in _fast_trace_task
    R, I, T, Rstr = tasks[task].__trace__(
[2022-07-10 08:00:00,107: WARNING/MainProcess] File "C:\inetpub\sites\edu-dev.coko38.ru\venv\lib\site-packages\celery\app\trace.py", line 399, in trace_task
    I, R, state, retval = on_error(task_request, exc, uuid)
[2022-07-10 08:00:00,107: WARNING/MainProcess] File "C:\inetpub\sites\edu-dev.coko38.ru\venv\lib\site-packages\celery\app\trace.py", line 338, in on_error
    R = I.handle_error_state(
[2022-07-10 08:00:00,107: WARNING/MainProcess] File "C:\inetpub\sites\edu-dev.coko38.ru\venv\lib\site-packages\celery\app\trace.py", line 167, in handle_error_state
    return {
[2022-07-10 08:00:00,107: WARNING/MainProcess] File "C:\inetpub\sites\edu-dev.coko38.ru\venv\lib\site-packages\celery\app\trace.py", line 226, in handle_failure
    self._log_error(task, req, einfo)
[2022-07-10 08:00:00,107: WARNING/MainProcess] File "C:\inetpub\sites\edu-dev.coko38.ru\venv\lib\site-packages\celery\app\trace.py", line 254, in _log_error
    logger.log(policy.severity, policy.format.strip(), context,
[2022-07-10 08:00:00,107: ERROR/MainProcess] Signal handler <bound method DjangoWorkerFixup.on_task_postrun of <celery.fixups.django.DjangoWorkerFixup object at 0x000001D8A3688100>> raised: DatabaseError("DatabaseWrapper objects created in a thread can only be used in that same thread. The object with alias 'default' was created in thread id 2029956420528 and this is thread id 2030169376544.")
Traceback (most recent call last):
  File "C:\inetpub\sites\edu-dev.coko38.ru\venv\lib\site-packages\celery\utils\dispatch\signal.py", line 288, in send
    response = receiver(signal=self, sender=sender, **named)
  File "C:\inetpub\sites\edu-dev.coko38.ru\venv\lib\site-packages\celery\fixups\django.py", line 172, in on_task_postrun
    self.close_database()
  File "C:\inetpub\sites\edu-dev.coko38.ru\venv\lib\site-packages\celery\fixups\django.py", line 177, in close_database
    return self._close_database()
  File "C:\inetpub\sites\edu-dev.coko38.ru\venv\lib\site-packages\celery\fixups\django.py", line 186, in _close_database
    conn.close_if_unusable_or_obsolete()
  File "C:\inetpub\sites\edu-dev.coko38.ru\venv\lib\site-packages\django\db\backends\base\base.py", line 559, in close_if_unusable_or_obsolete
    self.close()
  File "C:\inetpub\sites\edu-dev.coko38.ru\venv\lib\site-packages\django\utils\asyncio.py", line 26, in inner
    return func(*args, **kwargs)
  File "C:\inetpub\sites\edu-dev.coko38.ru\venv\lib\site-packages\django\db\backends\base\base.py", line 310, in close
    self.validate_thread_sharing()
  File "C:\inetpub\sites\edu-dev.coko38.ru\venv\lib\site-packages\django\db\backends\base\base.py", line 589, in validate_thread_sharing
    raise DatabaseError(
django.db.utils.DatabaseError: DatabaseWrapper objects created in a thread can only be used in that same thread. The object with alias 'default' was created in thread id 2029956420528 and this is thread id 2030169376544.
[2022-07-11 08:00:00,011: INFO/MainProcess] Received task: centre.tasks.CheckRegistrationEnd[ba8647d1-7f0e-4356-b73e-3600e71cdba1]  
[2022-07-11 08:00:00,011: ERROR/MainProcess] Signal handler <bound method DjangoWorkerFixup.on_task_prerun of <celery.fixups.django.DjangoWorkerFixup object at 0x000001D8A3688100>> raised: DatabaseError("DatabaseWrapper objects created in a thread can only be used in that same thread. The object with alias 'default' was created in thread id 2029956420528 and this is thread id 2030169302640.")
Traceback (most recent call last):
  File "C:\inetpub\sites\edu-dev.coko38.ru\venv\lib\site-packages\celery\utils\dispatch\signal.py", line 288, in send
    response = receiver(signal=self, sender=sender, **named)
  File "C:\inetpub\sites\edu-dev.coko38.ru\venv\lib\site-packages\celery\fixups\django.py", line 166, in on_task_prerun
    self.close_database()
  File "C:\inetpub\sites\edu-dev.coko38.ru\venv\lib\site-packages\celery\fixups\django.py", line 177, in close_database
    return self._close_database()
  File "C:\inetpub\sites\edu-dev.coko38.ru\venv\lib\site-packages\celery\fixups\django.py", line 186, in _close_database
    conn.close_if_unusable_or_obsolete()
  File "C:\inetpub\sites\edu-dev.coko38.ru\venv\lib\site-packages\django\db\backends\base\base.py", line 559, in close_if_unusable_or_obsolete
    self.close()
  File "C:\inetpub\sites\edu-dev.coko38.ru\venv\lib\site-packages\django\utils\asyncio.py", line 26, in inner
    return func(*args, **kwargs)
  File "C:\inetpub\sites\edu-dev.coko38.ru\venv\lib\site-packages\django\db\backends\base\base.py", line 310, in close
    self.validate_thread_sharing()
  File "C:\inetpub\sites\edu-dev.coko38.ru\venv\lib\site-packages\django\db\backends\base\base.py", line 589, in validate_thread_sharing
    raise DatabaseError(
django.db.utils.DatabaseError: DatabaseWrapper objects created in a thread can only be used in that same thread. The object with alias 'default' was created in thread id 2029956420528 and this is thread id 2030169302640.
[2022-07-11 08:00:00,042: WARNING/MainProcess] --- Logging error ---
[2022-07-11 08:00:00,042: WARNING/MainProcess] Traceback (most recent call last):
[2022-07-11 08:00:00,042: WARNING/MainProcess] File "C:\inetpub\sites\edu-dev.coko38.ru\venv\lib\site-packages\celery\app\trace.py", line 385, in trace_task
    R = retval = fun(*args, **kwargs)
[2022-07-11 08:00:00,042: WARNING/MainProcess] File "C:\inetpub\sites\edu-dev.coko38.ru\venv\lib\site-packages\celery\app\trace.py", line 648, in __protected_call__
    return self.run(*args, **kwargs)
[2022-07-11 08:00:00,058: WARNING/MainProcess] File "C:\inetpub\sites\edu-dev.coko38.ru\venv\lib\site-packages\django\db\models\manager.py", line 85, in manager_method
    return getattr(self.get_queryset(), name)(*args, **kwargs)
[2022-07-11 08:00:00,058: WARNING/MainProcess] File "C:\inetpub\sites\edu-dev.coko38.ru\venv\lib\site-packages\django\db\models\query.py", line 492, in get
    num = len(clone)
[2022-07-11 08:00:00,058: WARNING/MainProcess] File "C:\inetpub\sites\edu-dev.coko38.ru\venv\lib\site-packages\django\db\models\query.py", line 302, in __len__
    self._fetch_all()
[2022-07-11 08:00:00,058: WARNING/MainProcess] File "C:\inetpub\sites\edu-dev.coko38.ru\venv\lib\site-packages\django\db\models\query.py", line 1507, in _fetch_all
    self._result_cache = list(self._iterable_class(self))
[2022-07-11 08:00:00,058: WARNING/MainProcess] File "C:\inetpub\sites\edu-dev.coko38.ru\venv\lib\site-packages\django\db\models\query.py", line 57, in __iter__
    results = compiler.execute_sql(
[2022-07-11 08:00:00,058: WARNING/MainProcess] File "C:\inetpub\sites\edu-dev.coko38.ru\venv\lib\site-packages\django\db\models\sql\compiler.py", line 1359, in execute_sql
    cursor = self.connection.cursor()
[2022-07-11 08:00:00,058: WARNING/MainProcess] File "C:\inetpub\sites\edu-dev.coko38.ru\venv\lib\site-packages\django\utils\asyncio.py", line 26, in inner
    return func(*args, **kwargs)
[2022-07-11 08:00:00,058: WARNING/MainProcess] File "C:\inetpub\sites\edu-dev.coko38.ru\venv\lib\site-packages\django\db\backends\base\base.py", line 284, in cursor
    return self._cursor()
[2022-07-11 08:00:00,058: WARNING/MainProcess] File "C:\inetpub\sites\edu-dev.coko38.ru\venv\lib\site-packages\mssql\base.py", line 230, in _cursor
    conn = super()._cursor()
[2022-07-11 08:00:00,058: WARNING/MainProcess] File "C:\inetpub\sites\edu-dev.coko38.ru\venv\lib\site-packages\django\db\backends\base\base.py", line 262, in _cursor
    return self._prepare_cursor(self.create_cursor(name))
[2022-07-11 08:00:00,058: WARNING/MainProcess] File "C:\inetpub\sites\edu-dev.coko38.ru\venv\lib\site-packages\django\db\backends\base\base.py", line 252, in _prepare_cursor
    self.validate_thread_sharing()
[2022-07-11 08:00:00,058: WARNING/MainProcess] File "C:\inetpub\sites\edu-dev.coko38.ru\venv\lib\site-packages\django\db\backends\base\base.py", line 589, in validate_thread_sharing
    raise DatabaseError(
[2022-07-11 08:00:00,058: WARNING/MainProcess] django.db.utils.DatabaseError: DatabaseWrapper objects created in a thread can only be used in that same thread. The object with alias 'default' was created in thread id 2029956420528 and this is thread id 2030169302640.
[2022-07-11 08:00:00,074: WARNING/MainProcess] During handling of the above exception, another exception occurred:
[2022-07-11 08:00:00,074: WARNING/MainProcess] Traceback (most recent call last):
[2022-07-11 08:00:00,074: WARNING/MainProcess] File "C:\Python39\lib\logging\__init__.py", line 1086, in emit
    stream.write(msg + self.terminator)
[2022-07-11 08:00:00,074: WARNING/MainProcess] File "C:\Python39\lib\encodings\cp1252.py", line 19, in encode
    return codecs.charmap_encode(input,self.errors,encoding_table)[0]
[2022-07-11 08:00:00,074: WARNING/MainProcess] UnicodeEncodeError: 'charmap' codec can't encode characters in position 881-884: character maps to <undefined>
[2022-07-11 08:00:00,074: WARNING/MainProcess] Call stack:
[2022-07-11 08:00:00,074: WARNING/MainProcess] File "C:\inetpub\sites\edu-dev.coko38.ru\venv\lib\site-packages\eventlet\greenpool.py", line 88, in _spawn_n_impl
    func(*args, **kwargs)
[2022-07-11 08:00:00,074: WARNING/MainProcess] File "C:\inetpub\sites\edu-dev.coko38.ru\venv\lib\site-packages\celery\concurrency\eventlet.py", line 33, in apply_target
    return base.apply_target(target, args, kwargs, callback, accept_callback,
[2022-07-11 08:00:00,074: WARNING/MainProcess] File "C:\inetpub\sites\edu-dev.coko38.ru\venv\lib\site-packages\celery\concurrency\base.py", line 31, in apply_target
    ret = target(*args, **kwargs)
[2022-07-11 08:00:00,074: WARNING/MainProcess] File "C:\inetpub\sites\edu-dev.coko38.ru\venv\lib\site-packages\celery\app\trace.py", line 555, in _fast_trace_task
    R, I, T, Rstr = tasks[task].__trace__(
[2022-07-11 08:00:00,074: WARNING/MainProcess] File "C:\inetpub\sites\edu-dev.coko38.ru\venv\lib\site-packages\celery\app\trace.py", line 399, in trace_task
    I, R, state, retval = on_error(task_request, exc, uuid)
[2022-07-11 08:00:00,074: WARNING/MainProcess] File "C:\inetpub\sites\edu-dev.coko38.ru\venv\lib\site-packages\celery\app\trace.py", line 338, in on_error
    R = I.handle_error_state(
[2022-07-11 08:00:00,074: WARNING/MainProcess] File "C:\inetpub\sites\edu-dev.coko38.ru\venv\lib\site-packages\celery\app\trace.py", line 167, in handle_error_state
    return {
[2022-07-11 08:00:00,074: WARNING/MainProcess] File "C:\inetpub\sites\edu-dev.coko38.ru\venv\lib\site-packages\celery\app\trace.py", line 226, in handle_failure
    self._log_error(task, req, einfo)
[2022-07-11 08:00:00,074: WARNING/MainProcess] File "C:\inetpub\sites\edu-dev.coko38.ru\venv\lib\site-packages\celery\app\trace.py", line 254, in _log_error
    logger.log(policy.severity, policy.format.strip(), context,
[2022-07-11 08:00:00,074: ERROR/MainProcess] Signal handler <bound method DjangoWorkerFixup.on_task_postrun of <celery.fixups.django.DjangoWorkerFixup object at 0x000001D8A3688100>> raised: DatabaseError("DatabaseWrapper objects created in a thread can only be used in that same thread. The object with alias 'default' was created in thread id 2029956420528 and this is thread id 2030169302640.")
Traceback (most recent call last):
  File "C:\inetpub\sites\edu-dev.coko38.ru\venv\lib\site-packages\celery\utils\dispatch\signal.py", line 288, in send
    response = receiver(signal=self, sender=sender, **named)
  File "C:\inetpub\sites\edu-dev.coko38.ru\venv\lib\site-packages\celery\fixups\django.py", line 172, in on_task_postrun
    self.close_database()
  File "C:\inetpub\sites\edu-dev.coko38.ru\venv\lib\site-packages\celery\fixups\django.py", line 177, in close_database
    return self._close_database()
  File "C:\inetpub\sites\edu-dev.coko38.ru\venv\lib\site-packages\celery\fixups\django.py", line 186, in _close_database
    conn.close_if_unusable_or_obsolete()
  File "C:\inetpub\sites\edu-dev.coko38.ru\venv\lib\site-packages\django\db\backends\base\base.py", line 559, in close_if_unusable_or_obsolete
    self.close()
  File "C:\inetpub\sites\edu-dev.coko38.ru\venv\lib\site-packages\django\utils\asyncio.py", line 26, in inner
    return func(*args, **kwargs)
  File "C:\inetpub\sites\edu-dev.coko38.ru\venv\lib\site-packages\django\db\backends\base\base.py", line 310, in close
    self.validate_thread_sharing()
  File "C:\inetpub\sites\edu-dev.coko38.ru\venv\lib\site-packages\django\db\backends\base\base.py", line 589, in validate_thread_sharing
    raise DatabaseError(
django.db.utils.DatabaseError: DatabaseWrapper objects created in a thread can only be used in that same thread. The object with alias 'default' was created in thread id 2029956420528 and this is thread id 2030169302640.
[2022-07-11 08:00:00,074: INFO/MainProcess] Received task: centre.tasks.ShowSurveyUrl[8a0023b7-f0b3-43d8-a978-faf075638753]  
[2022-07-11 08:00:00,074: ERROR/MainProcess] Signal handler <bound method DjangoWorkerFixup.on_task_prerun of <celery.fixups.django.DjangoWorkerFixup object at 0x000001D8A3688100>> raised: DatabaseError("DatabaseWrapper objects created in a thread can only be used in that same thread. The object with alias 'default' was created in thread id 2029956420528 and this is thread id 2030169267008.")
Traceback (most recent call last):
  File "C:\inetpub\sites\edu-dev.coko38.ru\venv\lib\site-packages\celery\utils\dispatch\signal.py", line 288, in send
    response = receiver(signal=self, sender=sender, **named)
  File "C:\inetpub\sites\edu-dev.coko38.ru\venv\lib\site-packages\celery\fixups\django.py", line 166, in on_task_prerun
    self.close_database()
  File "C:\inetpub\sites\edu-dev.coko38.ru\venv\lib\site-packages\celery\fixups\django.py", line 177, in close_database
    return self._close_database()
  File "C:\inetpub\sites\edu-dev.coko38.ru\venv\lib\site-packages\celery\fixups\django.py", line 186, in _close_database
    conn.close_if_unusable_or_obsolete()
  File "C:\inetpub\sites\edu-dev.coko38.ru\venv\lib\site-packages\django\db\backends\base\base.py", line 559, in close_if_unusable_or_obsolete
    self.close()
  File "C:\inetpub\sites\edu-dev.coko38.ru\venv\lib\site-packages\django\utils\asyncio.py", line 26, in inner
    return func(*args, **kwargs)
  File "C:\inetpub\sites\edu-dev.coko38.ru\venv\lib\site-packages\django\db\backends\base\base.py", line 310, in close
    self.validate_thread_sharing()
  File "C:\inetpub\sites\edu-dev.coko38.ru\venv\lib\site-packages\django\db\backends\base\base.py", line 589, in validate_thread_sharing
    raise DatabaseError(
django.db.utils.DatabaseError: DatabaseWrapper objects created in a thread can only be used in that same thread. The object with alias 'default' was created in thread id 2029956420528 and this is thread id 2030169267008.
[2022-07-11 08:00:00,074: WARNING/MainProcess] --- Logging error ---
[2022-07-11 08:00:00,089: WARNING/MainProcess] Traceback (most recent call last):
[2022-07-11 08:00:00,089: WARNING/MainProcess] File "C:\inetpub\sites\edu-dev.coko38.ru\venv\lib\site-packages\celery\app\trace.py", line 385, in trace_task
    R = retval = fun(*args, **kwargs)
[2022-07-11 08:00:00,089: WARNING/MainProcess] File "C:\inetpub\sites\edu-dev.coko38.ru\venv\lib\site-packages\celery\app\trace.py", line 648, in __protected_call__
    return self.run(*args, **kwargs)
[2022-07-11 08:00:00,089: WARNING/MainProcess] File "C:\inetpub\sites\edu-dev.coko38.ru\venv\lib\site-packages\django\db\models\manager.py", line 85, in manager_method
    return getattr(self.get_queryset(), name)(*args, **kwargs)
[2022-07-11 08:00:00,089: WARNING/MainProcess] File "C:\inetpub\sites\edu-dev.coko38.ru\venv\lib\site-packages\django\db\models\query.py", line 492, in get
    num = len(clone)
[2022-07-11 08:00:00,089: WARNING/MainProcess] File "C:\inetpub\sites\edu-dev.coko38.ru\venv\lib\site-packages\django\db\models\query.py", line 302, in __len__
    self._fetch_all()
[2022-07-11 08:00:00,089: WARNING/MainProcess] File "C:\inetpub\sites\edu-dev.coko38.ru\venv\lib\site-packages\django\db\models\query.py", line 1507, in _fetch_all
    self._result_cache = list(self._iterable_class(self))
[2022-07-11 08:00:00,089: WARNING/MainProcess] File "C:\inetpub\sites\edu-dev.coko38.ru\venv\lib\site-packages\django\db\models\query.py", line 57, in __iter__
    results = compiler.execute_sql(
[2022-07-11 08:00:00,089: WARNING/MainProcess] File "C:\inetpub\sites\edu-dev.coko38.ru\venv\lib\site-packages\django\db\models\sql\compiler.py", line 1359, in execute_sql
    cursor = self.connection.cursor()
[2022-07-11 08:00:00,089: WARNING/MainProcess] File "C:\inetpub\sites\edu-dev.coko38.ru\venv\lib\site-packages\django\utils\asyncio.py", line 26, in inner
    return func(*args, **kwargs)
[2022-07-11 08:00:00,089: WARNING/MainProcess] File "C:\inetpub\sites\edu-dev.coko38.ru\venv\lib\site-packages\django\db\backends\base\base.py", line 284, in cursor
    return self._cursor()
[2022-07-11 08:00:00,089: WARNING/MainProcess] File "C:\inetpub\sites\edu-dev.coko38.ru\venv\lib\site-packages\mssql\base.py", line 230, in _cursor
    conn = super()._cursor()
[2022-07-11 08:00:00,089: WARNING/MainProcess] File "C:\inetpub\sites\edu-dev.coko38.ru\venv\lib\site-packages\django\db\backends\base\base.py", line 262, in _cursor
    return self._prepare_cursor(self.create_cursor(name))
[2022-07-11 08:00:00,089: WARNING/MainProcess] File "C:\inetpub\sites\edu-dev.coko38.ru\venv\lib\site-packages\django\db\backends\base\base.py", line 252, in _prepare_cursor
    self.validate_thread_sharing()
[2022-07-11 08:00:00,089: WARNING/MainProcess] File "C:\inetpub\sites\edu-dev.coko38.ru\venv\lib\site-packages\django\db\backends\base\base.py", line 589, in validate_thread_sharing
    raise DatabaseError(
[2022-07-11 08:00:00,089: WARNING/MainProcess] django.db.utils.DatabaseError: DatabaseWrapper objects created in a thread can only be used in that same thread. The object with alias 'default' was created in thread id 2029956420528 and this is thread id 2030169267008.
[2022-07-11 08:00:00,089: WARNING/MainProcess] During handling of the above exception, another exception occurred:
[2022-07-11 08:00:00,089: WARNING/MainProcess] Traceback (most recent call last):
[2022-07-11 08:00:00,089: WARNING/MainProcess] File "C:\Python39\lib\logging\__init__.py", line 1086, in emit
    stream.write(msg + self.terminator)
[2022-07-11 08:00:00,089: WARNING/MainProcess] File "C:\Python39\lib\encodings\cp1252.py", line 19, in encode
    return codecs.charmap_encode(input,self.errors,encoding_table)[0]
[2022-07-11 08:00:00,089: WARNING/MainProcess] UnicodeEncodeError: 'charmap' codec can't encode characters in position 867-870: character maps to <undefined>
[2022-07-11 08:00:00,089: WARNING/MainProcess] Call stack:
[2022-07-11 08:00:00,089: WARNING/MainProcess] File "C:\inetpub\sites\edu-dev.coko38.ru\venv\lib\site-packages\eventlet\greenpool.py", line 88, in _spawn_n_impl
    func(*args, **kwargs)
[2022-07-11 08:00:00,089: WARNING/MainProcess] File "C:\inetpub\sites\edu-dev.coko38.ru\venv\lib\site-packages\celery\concurrency\eventlet.py", line 33, in apply_target
    return base.apply_target(target, args, kwargs, callback, accept_callback,
[2022-07-11 08:00:00,089: WARNING/MainProcess] File "C:\inetpub\sites\edu-dev.coko38.ru\venv\lib\site-packages\celery\concurrency\base.py", line 31, in apply_target
    ret = target(*args, **kwargs)
[2022-07-11 08:00:00,089: WARNING/MainProcess] File "C:\inetpub\sites\edu-dev.coko38.ru\venv\lib\site-packages\celery\app\trace.py", line 555, in _fast_trace_task
    R, I, T, Rstr = tasks[task].__trace__(
[2022-07-11 08:00:00,089: WARNING/MainProcess] File "C:\inetpub\sites\edu-dev.coko38.ru\venv\lib\site-packages\celery\app\trace.py", line 399, in trace_task
    I, R, state, retval = on_error(task_request, exc, uuid)
[2022-07-11 08:00:00,089: WARNING/MainProcess] File "C:\inetpub\sites\edu-dev.coko38.ru\venv\lib\site-packages\celery\app\trace.py", line 338, in on_error
    R = I.handle_error_state(
[2022-07-11 08:00:00,089: WARNING/MainProcess] File "C:\inetpub\sites\edu-dev.coko38.ru\venv\lib\site-packages\celery\app\trace.py", line 167, in handle_error_state
    return {
[2022-07-11 08:00:00,089: WARNING/MainProcess] File "C:\inetpub\sites\edu-dev.coko38.ru\venv\lib\site-packages\celery\app\trace.py", line 226, in handle_failure
    self._log_error(task, req, einfo)
[2022-07-11 08:00:00,089: WARNING/MainProcess] File "C:\inetpub\sites\edu-dev.coko38.ru\venv\lib\site-packages\celery\app\trace.py", line 254, in _log_error
    logger.log(policy.severity, policy.format.strip(), context,
[2022-07-11 08:00:00,089: ERROR/MainProcess] Signal handler <bound method DjangoWorkerFixup.on_task_postrun of <celery.fixups.django.DjangoWorkerFixup object at 0x000001D8A3688100>> raised: DatabaseError("DatabaseWrapper objects created in a thread can only be used in that same thread. The object with alias 'default' was created in thread id 2029956420528 and this is thread id 2030169267008.")
Traceback (most recent call last):
  File "C:\inetpub\sites\edu-dev.coko38.ru\venv\lib\site-packages\celery\utils\dispatch\signal.py", line 288, in send
    response = receiver(signal=self, sender=sender, **named)
  File "C:\inetpub\sites\edu-dev.coko38.ru\venv\lib\site-packages\celery\fixups\django.py", line 172, in on_task_postrun
    self.close_database()
  File "C:\inetpub\sites\edu-dev.coko38.ru\venv\lib\site-packages\celery\fixups\django.py", line 177, in close_database
    return self._close_database()
  File "C:\inetpub\sites\edu-dev.coko38.ru\venv\lib\site-packages\celery\fixups\django.py", line 186, in _close_database
    conn.close_if_unusable_or_obsolete()
  File "C:\inetpub\sites\edu-dev.coko38.ru\venv\lib\site-packages\django\db\backends\base\base.py", line 559, in close_if_unusable_or_obsolete
    self.close()
  File "C:\inetpub\sites\edu-dev.coko38.ru\venv\lib\site-packages\django\utils\asyncio.py", line 26, in inner
    return func(*args, **kwargs)
  File "C:\inetpub\sites\edu-dev.coko38.ru\venv\lib\site-packages\django\db\backends\base\base.py", line 310, in close
    self.validate_thread_sharing()
  File "C:\inetpub\sites\edu-dev.coko38.ru\venv\lib\site-packages\django\db\backends\base\base.py", line 589, in validate_thread_sharing
    raise DatabaseError(
django.db.utils.DatabaseError: DatabaseWrapper objects created in a thread can only be used in that same thread. The object with alias 'default' was created in thread id 2029956420528 and this is thread id 2030169267008.
[2022-07-11 12:57:18,150: INFO/MainProcess] Events of group {task} enabled by remote.
[2022-07-11 13:08:01,211: INFO/MainProcess] Connected to redis://172.16.55.20:6379/0
[2022-07-11 13:08:01,211: INFO/MainProcess] mingle: searching for neighbors
[2022-07-11 13:08:02,258: INFO/MainProcess] mingle: all alone
[2022-07-11 13:08:02,273: INFO/MainProcess] pidbox: Connected to redis://172.16.55.20:6379/0.
[2022-07-11 13:08:02,289: WARNING/MainProcess] C:\inetpub\sites\edu-dev.coko38.ru\venv\lib\site-packages\celery\fixups\django.py:203: UserWarning: Using settings.DEBUG leads to a memory
            leak, never use this setting in production environments!
  warnings.warn('''Using settings.DEBUG leads to a memory

[2022-07-11 13:08:02,289: INFO/MainProcess] celery@srv-dev ready.
[2022-07-11 13:08:02,289: INFO/MainProcess] Task centre.tasks.CheckRegistrationEnd[8b4bb987-e91f-41db-a1c4-3bf0a1df455a] received
[2022-07-11 13:08:02,352: INFO/MainProcess] Task centre.tasks.CheckRegistrationEnd[e9c7167e-30a8-403c-bb1f-0a2fe74da4a0] received
[2022-07-11 13:08:02,398: INFO/MainProcess] Task centre.tasks.CheckRegistrationEnd[8b4bb987-e91f-41db-a1c4-3bf0a1df455a] succeeded in 0.10999999998603016s: None
[2022-07-11 13:08:02,414: INFO/MainProcess] Task centre.tasks.CheckRegistrationEnd[e9c7167e-30a8-403c-bb1f-0a2fe74da4a0] succeeded in 0.062000000005355105s: None
[2022-07-11 13:08:03,164: INFO/MainProcess] Events of group {task} enabled by remote.
[2022-07-11 13:09:00,025: INFO/MainProcess] Task centre.tasks.CheckRegistrationEnd[425992b6-d5cc-40ee-8be4-f1a6d8b731a4] received
[2022-07-11 13:09:00,079: INFO/MainProcess] Task centre.tasks.CheckRegistrationEnd[425992b6-d5cc-40ee-8be4-f1a6d8b731a4] succeeded in 0.046999999991385266s: None
[2022-07-11 13:10:00,028: INFO/MainProcess] Task centre.tasks.CheckRegistrationEnd[db6d7206-ae46-412a-89d7-ccbfc4e60061] received
[2022-07-11 13:10:00,086: INFO/MainProcess] Task centre.tasks.CheckRegistrationEnd[db6d7206-ae46-412a-89d7-ccbfc4e60061] succeeded in 0.046999999991385266s: None
[2022-07-11 13:11:32,729: INFO/MainProcess] Connected to redis://172.16.55.20:6379/0
[2022-07-11 13:11:32,744: INFO/MainProcess] mingle: searching for neighbors
[2022-07-11 13:11:33,787: INFO/MainProcess] mingle: all alone
[2022-07-11 13:11:33,803: WARNING/MainProcess] C:\inetpub\sites\edu-dev.coko38.ru\venv\lib\site-packages\celery\fixups\django.py:203: UserWarning: Using settings.DEBUG leads to a memory
            leak, never use this setting in production environments!
  warnings.warn('''Using settings.DEBUG leads to a memory

[2022-07-11 13:11:33,803: INFO/MainProcess] celery@srv-dev ready.
[2022-07-11 13:11:33,818: INFO/MainProcess] pidbox: Connected to redis://172.16.55.20:6379/0.
[2022-07-11 13:11:38,155: INFO/MainProcess] Events of group {task} enabled by remote.
[2022-07-12 08:00:00,064: INFO/MainProcess] Task centre.tasks.ShowSurveyUrl[a8a7d801-5787-4c73-91a6-e2fc190af81e] received
[2022-07-12 08:00:00,423: INFO/MainProcess] Task centre.tasks.CheckRegistrationEnd[b7d6dc73-c63a-439e-a6d3-53a88e38df1c] received
[2022-07-12 08:00:00,470: INFO/MainProcess] Task centre.tasks.ShowSurveyUrl[a8a7d801-5787-4c73-91a6-e2fc190af81e] succeeded in 0.39100000000325963s: None
[2022-07-12 08:00:00,470: INFO/MainProcess] Task centre.tasks.CheckRegistrationEnd[b7d6dc73-c63a-439e-a6d3-53a88e38df1c] succeeded in 0.0470000000204891s: None
[2022-07-13 08:00:00,040: INFO/MainProcess] Task centre.tasks.CheckRegistrationEnd[af11df77-71b5-48cc-877a-b0870f5fd35b] received
[2022-07-13 08:00:00,446: INFO/MainProcess] Task centre.tasks.ShowSurveyUrl[01383841-1d3e-432c-b0b5-d3dbe312b2c0] received
[2022-07-13 08:00:00,509: INFO/MainProcess] Task centre.tasks.CheckRegistrationEnd[af11df77-71b5-48cc-877a-b0870f5fd35b] succeeded in 0.45300000003771856s: None
[2022-07-13 08:00:00,509: INFO/MainProcess] Task centre.tasks.ShowSurveyUrl[01383841-1d3e-432c-b0b5-d3dbe312b2c0] succeeded in 0.0470000000204891s: None
[2022-07-13 08:52:53,246: INFO/MainProcess] Task centre.tasks.EmailOfferPay[5487cd8d-0242-47d8-b3f1-3ec958958809] received
[2022-07-13 08:53:01,520: INFO/MainProcess] Task centre.tasks.EmailOfferPay[5487cd8d-0242-47d8-b3f1-3ec958958809] succeeded in 8.26600000000326s: None
[2022-07-13 09:11:07,183: INFO/MainProcess] Task centre.tasks.EmailAcceptPay[b9119336-3c85-4bfc-9af6-7f08dfb9a195] received
[2022-07-13 09:11:10,252: INFO/MainProcess] Task centre.tasks.EmailAcceptPay[b9119336-3c85-4bfc-9af6-7f08dfb9a195] succeeded in 3.077999999979511s: None
[2022-07-13 11:06:51,350: INFO/MainProcess] Task centre.tasks.EmailOfferPay[d87cd9f1-74c1-4295-8bfe-4ba3eb0af41a] received
[2022-07-13 11:06:53,825: INFO/MainProcess] Task centre.tasks.EmailOfferPay[d87cd9f1-74c1-4295-8bfe-4ba3eb0af41a] succeeded in 2.48499999998603s: None
[2022-07-13 11:16:17,073: INFO/MainProcess] Connected to redis://172.16.55.20:6379/0
[2022-07-13 11:16:17,104: INFO/MainProcess] mingle: searching for neighbors
[2022-07-13 11:16:18,139: INFO/MainProcess] mingle: all alone
[2022-07-13 11:16:18,154: INFO/MainProcess] pidbox: Connected to redis://172.16.55.20:6379/0.
[2022-07-13 11:16:18,170: WARNING/MainProcess] C:\inetpub\sites\edu-dev.coko38.ru\venv\lib\site-packages\celery\fixups\django.py:203: UserWarning: Using settings.DEBUG leads to a memory
            leak, never use this setting in production environments!
  warnings.warn('''Using settings.DEBUG leads to a memory

[2022-07-13 11:16:18,170: INFO/MainProcess] celery@srv-dev ready.
[2022-07-13 11:17:40,768: INFO/MainProcess] Task centre.tasks.EmailOfferPay[6895e932-f331-4765-be6d-7902f3ce5173] received
[2022-07-13 11:17:43,428: INFO/MainProcess] Task centre.tasks.EmailOfferPay[6895e932-f331-4765-be6d-7902f3ce5173] succeeded in 2.656000000000006s: None
[2022-07-13 11:19:15,781: INFO/MainProcess] Task centre.tasks.EmailAcceptPay[a425aadc-1d8d-418d-9e68-62d7d90f1539] received
[2022-07-13 11:19:18,716: INFO/MainProcess] Task centre.tasks.EmailAcceptPay[a425aadc-1d8d-418d-9e68-62d7d90f1539] succeeded in 2.937000000000012s: None
[2022-07-13 11:29:08,157: INFO/MainProcess] Task centre.tasks.EmailOfferPay[14ab2bc2-8ee9-4774-8362-7d3d9fcc971b] received
[2022-07-13 11:29:10,448: INFO/MainProcess] Task centre.tasks.EmailOfferPay[14ab2bc2-8ee9-4774-8362-7d3d9fcc971b] succeeded in 2.296000000000049s: None
[2022-07-13 11:46:12,868: INFO/MainProcess] Connected to redis://172.16.55.20:6379/0
[2022-07-13 11:46:12,875: INFO/MainProcess] mingle: searching for neighbors
[2022-07-13 11:46:13,898: INFO/MainProcess] mingle: all alone
[2022-07-13 11:46:16,920: INFO/MainProcess] pidbox: Connected to redis://172.16.55.20:6379/0.
[2022-07-13 11:46:19,941: WARNING/MainProcess] C:\inetpub\sites\edu-dev.coko38.ru\venv\lib\site-packages\celery\fixups\django.py:203: UserWarning: Using settings.DEBUG leads to a memory
            leak, never use this setting in production environments!
  warnings.warn('''Using settings.DEBUG leads to a memory

[2022-07-13 11:46:19,941: INFO/MainProcess] celery@srv-dev ready.
[2022-07-13 12:43:33,459: INFO/MainProcess] Events of group {task} enabled by remote.
[2022-07-13 12:45:33,585: INFO/MainProcess] Task centre.tasks.EmailDeniedPay[afd5a87e-5662-4ce4-8a0f-771162d60ecc] received
[2022-07-13 12:45:36,104: INFO/MainProcess] Task centre.tasks.EmailDeniedPay[afd5a87e-5662-4ce4-8a0f-771162d60ecc] succeeded in 2.5s: None
[2022-07-13 12:49:30,168: INFO/MainProcess] Connected to redis://172.16.55.20:6379/0
[2022-07-13 12:49:30,168: INFO/MainProcess] mingle: searching for neighbors
[2022-07-13 12:49:31,192: INFO/MainProcess] mingle: all alone
[2022-07-13 12:49:31,223: INFO/MainProcess] pidbox: Connected to redis://172.16.55.20:6379/0.
[2022-07-13 12:49:31,255: WARNING/MainProcess] C:\inetpub\sites\edu-dev.coko38.ru\venv\lib\site-packages\celery\fixups\django.py:203: UserWarning: Using settings.DEBUG leads to a memory
            leak, never use this setting in production environments!
  warnings.warn('''Using settings.DEBUG leads to a memory

[2022-07-13 12:49:31,255: INFO/MainProcess] celery@srv-dev ready.
[2022-07-13 13:11:32,592: INFO/MainProcess] Task centre.tasks.EmailOfferPay[0b8dd040-1b49-41f6-b5b1-ce830c6e8c66] received
[2022-07-13 13:11:35,126: INFO/MainProcess] Task centre.tasks.EmailOfferPay[0b8dd040-1b49-41f6-b5b1-ce830c6e8c66] succeeded in 2.5319999999999254s: None
[2022-07-13 13:16:41,863: INFO/MainProcess] Task centre.tasks.EmailOfferPay[c4bdfd0b-443e-46e3-8b1c-2bdab446eaf4] received
[2022-07-13 13:16:45,003: INFO/MainProcess] Task centre.tasks.EmailOfferPay[c4bdfd0b-443e-46e3-8b1c-2bdab446eaf4] succeeded in 3.1410000000000764s: None
[2022-07-13 13:17:47,978: INFO/MainProcess] Task centre.tasks.EmailDeniedPay[98b9aada-7ec7-47e1-9528-12f677632e3a] received
[2022-07-13 13:17:50,903: INFO/MainProcess] Task centre.tasks.EmailDeniedPay[98b9aada-7ec7-47e1-9528-12f677632e3a] succeeded in 2.9220000000000255s: None
[2022-07-13 13:18:56,692: INFO/MainProcess] Task centre.tasks.EmailAcceptPay[9538859f-025d-4499-8854-0ab725354706] received
[2022-07-13 13:18:59,411: INFO/MainProcess] Task centre.tasks.EmailAcceptPay[9538859f-025d-4499-8854-0ab725354706] succeeded in 2.719000000000051s: None
[2022-07-14 08:00:00,040: INFO/MainProcess] Task centre.tasks.CheckRegistrationEnd[8c1e449c-d9c0-4e71-9f6a-87b9a6448554] received
[2022-07-14 08:00:00,587: INFO/MainProcess] Task centre.tasks.ShowSurveyUrl[2037ef71-a142-43ce-84e8-3efa4f1a6b84] received
[2022-07-14 08:00:00,650: INFO/MainProcess] Task centre.tasks.CheckRegistrationEnd[8c1e449c-d9c0-4e71-9f6a-87b9a6448554] succeeded in 0.6100000000005821s: None
[2022-07-14 08:00:00,650: INFO/MainProcess] Task centre.tasks.ShowSurveyUrl[2037ef71-a142-43ce-84e8-3efa4f1a6b84] succeeded in 0.0629999999946449s: None
[2022-07-15 08:00:00,034: INFO/MainProcess] Task centre.tasks.ShowSurveyUrl[97401853-2b15-4c2f-b8e8-972d8ff7da02] received
[2022-07-15 08:00:00,346: INFO/MainProcess] Task centre.tasks.CheckRegistrationEnd[2db49cc5-c22c-4ec3-b213-ebfc9521e80f] received
[2022-07-15 08:00:00,424: INFO/MainProcess] Task centre.tasks.ShowSurveyUrl[97401853-2b15-4c2f-b8e8-972d8ff7da02] succeeded in 0.39100000000325963s: None
[2022-07-15 08:00:00,424: INFO/MainProcess] Task centre.tasks.CheckRegistrationEnd[2db49cc5-c22c-4ec3-b213-ebfc9521e80f] succeeded in 0.07899999999790452s: None
[2022-07-16 08:00:00,040: INFO/MainProcess] Task centre.tasks.CheckRegistrationEnd[5083ef29-4224-414e-90f0-15a2fc932c78] received
[2022-07-16 08:00:00,415: INFO/MainProcess] Task centre.tasks.ShowSurveyUrl[94cc7cc8-252f-4baf-93bd-8198db65e29b] received
[2022-07-16 08:00:00,478: INFO/MainProcess] Task centre.tasks.CheckRegistrationEnd[5083ef29-4224-414e-90f0-15a2fc932c78] succeeded in 0.4370000000053551s: None
[2022-07-16 08:00:00,478: INFO/MainProcess] Task centre.tasks.ShowSurveyUrl[94cc7cc8-252f-4baf-93bd-8198db65e29b] succeeded in 0.062000000005355105s: None
[2022-07-17 08:00:00,031: INFO/MainProcess] Task centre.tasks.ShowSurveyUrl[2fa7e053-a86e-4214-abe0-72c84fe874f2] received
[2022-07-17 08:00:00,375: INFO/MainProcess] Task centre.tasks.CheckRegistrationEnd[13c89107-a433-4db5-a965-9480f414939b] received
[2022-07-17 08:00:00,438: INFO/MainProcess] Task centre.tasks.ShowSurveyUrl[2fa7e053-a86e-4214-abe0-72c84fe874f2] succeeded in 0.40600000001722947s: None
[2022-07-17 08:00:00,438: INFO/MainProcess] Task centre.tasks.CheckRegistrationEnd[13c89107-a433-4db5-a965-9480f414939b] succeeded in 0.062000000034458935s: None
[2022-07-17 18:31:19,780: INFO/MainProcess] Connected to redis://172.16.55.20:6379/0
[2022-07-17 18:31:19,795: INFO/MainProcess] mingle: searching for neighbors
[2022-07-17 18:31:20,822: INFO/MainProcess] mingle: all alone
[2022-07-17 18:31:26,880: WARNING/MainProcess] C:\inetpub\sites\edu-dev.coko38.ru\venv\lib\site-packages\celery\fixups\django.py:203: UserWarning: Using settings.DEBUG leads to a memory
            leak, never use this setting in production environments!
  warnings.warn('''Using settings.DEBUG leads to a memory

[2022-07-17 18:31:26,880: INFO/MainProcess] celery@srv-dev ready.
[2022-07-17 18:31:29,888: INFO/MainProcess] pidbox: Connected to redis://172.16.55.20:6379/0.
[2022-07-17 18:33:02,509: INFO/MainProcess] Task centre.tasks.generate_pk1[dfc5f540-7fa7-4828-9ca1-be419135b11c] received
[2022-07-17 18:33:08,212: ERROR/MainProcess] Task centre.tasks.generate_pk1[dfc5f540-7fa7-4828-9ca1-be419135b11c] raised unexpected: AttributeError("type object 'datetime.datetime' has no attribute 'datetime'")
Traceback (most recent call last):
  File "C:\inetpub\sites\edu-dev.coko38.ru\venv\lib\site-packages\celery\app\trace.py", line 451, in trace_task
    R = retval = fun(*args, **kwargs)
  File "C:\inetpub\sites\edu-dev.coko38.ru\venv\lib\site-packages\celery\app\trace.py", line 734, in __protected_call__
    return self.run(*args, **kwargs)
  File "C:\inetpub\sites\edu-dev.coko38.ru\edu\centre\tasks.py", line 179, in generate_pk1
    age = datetime.datetime.today().year - form.profile.birthday.year
AttributeError: type object 'datetime.datetime' has no attribute 'datetime'
[2022-07-17 20:34:21,751: INFO/MainProcess] Events of group {task} enabled by remote.
[2022-07-17 20:35:14,357: INFO/MainProcess] Task centre.tasks.generate_pk1[ad9f8719-db41-4d65-9c1e-433f7048e585] received
[2022-07-17 20:35:19,421: ERROR/MainProcess] Task centre.tasks.generate_pk1[ad9f8719-db41-4d65-9c1e-433f7048e585] raised unexpected: AttributeError("type object 'datetime.datetime' has no attribute 'datetime'")
Traceback (most recent call last):
  File "C:\inetpub\sites\edu-dev.coko38.ru\venv\lib\site-packages\celery\app\trace.py", line 451, in trace_task
    R = retval = fun(*args, **kwargs)
  File "C:\inetpub\sites\edu-dev.coko38.ru\venv\lib\site-packages\celery\app\trace.py", line 734, in __protected_call__
    return self.run(*args, **kwargs)
  File "C:\inetpub\sites\edu-dev.coko38.ru\edu\centre\tasks.py", line 179, in generate_pk1
    age = datetime.datetime.today().year - form.profile.birthday.year
AttributeError: type object 'datetime.datetime' has no attribute 'datetime'
[2022-07-17 20:39:59,589: INFO/MainProcess] Task centre.tasks.generate_pk1[ca2d6a14-64f5-4813-8dac-6a2a22ed8e29] received
[2022-07-17 20:40:04,855: ERROR/MainProcess] Task centre.tasks.generate_pk1[ca2d6a14-64f5-4813-8dac-6a2a22ed8e29] raised unexpected: AttributeError("type object 'datetime.datetime' has no attribute 'datetime'")
Traceback (most recent call last):
  File "C:\inetpub\sites\edu-dev.coko38.ru\venv\lib\site-packages\celery\app\trace.py", line 451, in trace_task
    R = retval = fun(*args, **kwargs)
  File "C:\inetpub\sites\edu-dev.coko38.ru\venv\lib\site-packages\celery\app\trace.py", line 734, in __protected_call__
    return self.run(*args, **kwargs)
  File "C:\inetpub\sites\edu-dev.coko38.ru\edu\centre\tasks.py", line 179, in generate_pk1
    age = datetime.today().year - form.profile.birthday.year
AttributeError: type object 'datetime.datetime' has no attribute 'datetime'
[2022-07-17 20:43:32,026: INFO/MainProcess] Connected to redis://172.16.55.20:6379/0
[2022-07-17 20:43:32,042: INFO/MainProcess] mingle: searching for neighbors
[2022-07-17 20:43:33,063: INFO/MainProcess] mingle: all alone
[2022-07-17 20:43:33,079: INFO/MainProcess] pidbox: Connected to redis://172.16.55.20:6379/0.
[2022-07-17 20:43:33,094: WARNING/MainProcess] C:\inetpub\sites\edu-dev.coko38.ru\venv\lib\site-packages\celery\fixups\django.py:203: UserWarning: Using settings.DEBUG leads to a memory
            leak, never use this setting in production environments!
  warnings.warn('''Using settings.DEBUG leads to a memory

[2022-07-17 20:43:33,094: INFO/MainProcess] celery@srv-dev ready.
[2022-07-17 20:45:25,293: INFO/MainProcess] Events of group {task} enabled by remote.
[2022-07-17 20:46:28,825: INFO/MainProcess] Task centre.tasks.generate_pk1[1bdcad93-5ed9-47c7-b9ae-f1adcab93865] received
[2022-07-17 20:46:55,292: ERROR/MainProcess] Task centre.tasks.generate_pk1[1bdcad93-5ed9-47c7-b9ae-f1adcab93865] raised unexpected: PermissionError(13, 'Access is denied')
Traceback (most recent call last):
  File "C:\inetpub\sites\edu-dev.coko38.ru\venv\lib\site-packages\celery\app\trace.py", line 451, in trace_task
    R = retval = fun(*args, **kwargs)
  File "C:\inetpub\sites\edu-dev.coko38.ru\venv\lib\site-packages\celery\app\trace.py", line 734, in __protected_call__
    return self.run(*args, **kwargs)
  File "C:\inetpub\sites\edu-dev.coko38.ru\edu\centre\tasks.py", line 1043, in generate_pk1
    os.makedirs(newpath)
  File "C:\Python39\lib\os.py", line 225, in makedirs
    mkdir(name, mode)
PermissionError: [WinError 5] Access is denied: '\\\\srv-fs-1.coko38.ru\\Docs\\Центр УЦ\\АИС Учебный Центр\\Отчеты\\ПК-1\\Морозов Н.Д\\'
[2022-07-17 21:04:06,794: INFO/MainProcess] Connected to redis://172.16.55.20:6379/0
[2022-07-17 21:04:06,825: INFO/MainProcess] mingle: searching for neighbors
[2022-07-17 21:04:07,845: INFO/MainProcess] mingle: all alone
[2022-07-17 21:04:07,892: WARNING/MainProcess] C:\inetpub\sites\edu-dev.coko38.ru\venv\lib\site-packages\celery\fixups\django.py:203: UserWarning: Using settings.DEBUG leads to a memory
            leak, never use this setting in production environments!
  warnings.warn('''Using settings.DEBUG leads to a memory

[2022-07-17 21:04:07,892: INFO/MainProcess] celery@srv-dev ready.
[2022-07-17 21:04:07,908: INFO/MainProcess] pidbox: Connected to redis://172.16.55.20:6379/0.
[2022-07-17 21:05:35,933: INFO/MainProcess] Events of group {task} enabled by remote.
[2022-07-17 21:06:02,248: INFO/MainProcess] Task centre.tasks.generate_pk1[a5c488c3-56d0-468d-9c9d-2a6e0a889353] received
[2022-07-17 21:06:27,758: ERROR/MainProcess] Task centre.tasks.generate_pk1[a5c488c3-56d0-468d-9c9d-2a6e0a889353] raised unexpected: PermissionError(13, 'Access is denied')
Traceback (most recent call last):
  File "C:\inetpub\sites\edu-dev.coko38.ru\venv\lib\site-packages\celery\app\trace.py", line 451, in trace_task
    R = retval = fun(*args, **kwargs)
  File "C:\inetpub\sites\edu-dev.coko38.ru\venv\lib\site-packages\celery\app\trace.py", line 734, in __protected_call__
    return self.run(*args, **kwargs)
  File "C:\inetpub\sites\edu-dev.coko38.ru\edu\centre\tasks.py", line 1043, in generate_pk1
    os.makedirs(newpath)
  File "C:\Python39\lib\os.py", line 225, in makedirs
    mkdir(name, mode)
PermissionError: [WinError 5] Access is denied: '\\\\srv-fs-1.coko38.ru\\Docs\\Центр УЦ\\АИС Учебный Центр\\Отчеты\\ПК-1\\Морозов Н.Д\\'
[2022-07-17 21:24:01,162: INFO/MainProcess] Connected to redis://172.16.55.20:6379/0
[2022-07-17 21:24:01,178: INFO/MainProcess] mingle: searching for neighbors
[2022-07-17 21:24:02,184: INFO/MainProcess] mingle: all alone
[2022-07-17 21:24:02,247: WARNING/MainProcess] C:\inetpub\sites\edu-dev.coko38.ru\venv\lib\site-packages\celery\fixups\django.py:203: UserWarning: Using settings.DEBUG leads to a memory
            leak, never use this setting in production environments!
  warnings.warn('''Using settings.DEBUG leads to a memory

[2022-07-17 21:24:02,247: INFO/MainProcess] celery@srv-dev ready.
[2022-07-17 21:24:02,247: INFO/MainProcess] pidbox: Connected to redis://172.16.55.20:6379/0.
[2022-07-17 21:24:59,672: INFO/MainProcess] Events of group {task} enabled by remote.
[2022-07-17 21:25:25,036: INFO/MainProcess] Task centre.tasks.generate_pk1[2dc6a836-916f-4b65-b29f-58ed47526c86] received
[2022-07-17 21:25:50,419: ERROR/MainProcess] Task centre.tasks.generate_pk1[2dc6a836-916f-4b65-b29f-58ed47526c86] raised unexpected: PermissionError(13, 'Permission denied')
Traceback (most recent call last):
  File "C:\inetpub\sites\edu-dev.coko38.ru\venv\lib\site-packages\celery\app\trace.py", line 451, in trace_task
    R = retval = fun(*args, **kwargs)
  File "C:\inetpub\sites\edu-dev.coko38.ru\venv\lib\site-packages\celery\app\trace.py", line 734, in __protected_call__
    return self.run(*args, **kwargs)
  File "C:\inetpub\sites\edu-dev.coko38.ru\edu\centre\tasks.py", line 1042, in generate_pk1
    writer.save(newpath + "Отчет_" + datetime.today().strftime('%d.%m.%Y') + ".xlsx")
  File "C:\inetpub\sites\edu-dev.coko38.ru\venv\lib\site-packages\xltpl\writerx.py", line 95, in save
    self.workbook.save(fname)
  File "C:\inetpub\sites\edu-dev.coko38.ru\venv\lib\site-packages\openpyxl\workbook\workbook.py", line 407, in save
    save_workbook(self, filename)
  File "C:\inetpub\sites\edu-dev.coko38.ru\venv\lib\site-packages\openpyxl\writer\excel.py", line 291, in save_workbook
    archive = ZipFile(filename, 'w', ZIP_DEFLATED, allowZip64=True)
  File "C:\Python39\lib\zipfile.py", line 1239, in __init__
    self.fp = io.open(file, filemode)
PermissionError: [Errno 13] Permission denied: '\\\\srv-fs-1.coko38.ru\\Docs\\Центр УЦ\\АИС Учебный Центр\\Отчеты\\ПК-1\\Морозов Н.Д\\Отчет_17.07.2022.xlsx'
[2022-07-17 22:05:03,649: INFO/MainProcess] Connected to redis://172.16.55.20:6379/0
[2022-07-17 22:05:03,665: INFO/MainProcess] mingle: searching for neighbors
[2022-07-17 22:05:04,681: INFO/MainProcess] mingle: all alone
[2022-07-17 22:05:04,696: INFO/MainProcess] pidbox: Connected to redis://172.16.55.20:6379/0.
[2022-07-17 22:05:04,728: WARNING/MainProcess] C:\inetpub\sites\edu-dev.coko38.ru\venv\lib\site-packages\celery\fixups\django.py:203: UserWarning: Using settings.DEBUG leads to a memory
            leak, never use this setting in production environments!
  warnings.warn('''Using settings.DEBUG leads to a memory

[2022-07-17 22:05:04,728: INFO/MainProcess] celery@srv-dev ready.
[2022-07-17 22:21:10,673: INFO/MainProcess] Connected to redis://172.16.55.20:6379/0
[2022-07-17 22:21:10,684: INFO/MainProcess] mingle: searching for neighbors
[2022-07-17 22:21:11,678: INFO/MainProcess] mingle: all alone
[2022-07-17 22:21:11,692: INFO/MainProcess] pidbox: Connected to redis://172.16.55.20:6379/0.
[2022-07-17 22:21:11,721: WARNING/MainProcess] C:\inetpub\sites\edu-dev.coko38.ru\venv\lib\site-packages\celery\fixups\django.py:203: UserWarning: Using settings.DEBUG leads to a memory
            leak, never use this setting in production environments!
  warnings.warn('''Using settings.DEBUG leads to a memory

[2022-07-17 22:21:11,722: INFO/MainProcess] celery@srv-dev ready.
[2022-07-17 22:23:32,979: INFO/MainProcess] Events of group {task} enabled by remote.
[2022-07-18 08:00:00,047: INFO/MainProcess] Task centre.tasks.CheckRegistrationEnd[59076bb1-142e-42e8-8a96-6c189a658525] received
[2022-07-18 08:00:00,390: INFO/MainProcess] Task centre.tasks.ShowSurveyUrl[1b718535-06e3-466c-9849-1708ccbb12c4] received
[2022-07-18 08:00:00,406: INFO/MainProcess] Task centre.tasks.CheckRegistrationEnd[59076bb1-142e-42e8-8a96-6c189a658525] succeeded in 0.35900000000401633s: None
[2022-07-18 08:00:00,484: INFO/MainProcess] Task centre.tasks.ShowSurveyUrl[1b718535-06e3-466c-9849-1708ccbb12c4] succeeded in 0.07800000000133878s: None
[2022-07-18 08:34:18,194: INFO/MainProcess] Task centre.tasks.generate_pk1[5a5aa612-379b-4f94-8f32-e868b7545c23] received
[2022-07-18 08:34:43,741: ERROR/MainProcess] Task centre.tasks.generate_pk1[5a5aa612-379b-4f94-8f32-e868b7545c23] raised unexpected: PermissionError(13, 'Permission denied')
Traceback (most recent call last):
  File "C:\inetpub\sites\edu-dev.coko38.ru\venv\lib\site-packages\celery\app\trace.py", line 451, in trace_task
    R = retval = fun(*args, **kwargs)
  File "C:\inetpub\sites\edu-dev.coko38.ru\venv\lib\site-packages\celery\app\trace.py", line 734, in __protected_call__
    return self.run(*args, **kwargs)
  File "C:\inetpub\sites\edu-dev.coko38.ru\edu\centre\tasks.py", line 1002, in generate_pk1
    save_report(info, info2, info3, info4, profile_id, report_id)
  File "C:\inetpub\sites\edu-dev.coko38.ru\edu\centre\another.py", line 52, in save_report
    writer.save(newpath + "Отчет_" + datetime.today().strftime('%d.%m.%Y') + ".xlsx")
  File "C:\inetpub\sites\edu-dev.coko38.ru\venv\lib\site-packages\xltpl\writerx.py", line 95, in save
    self.workbook.save(fname)
  File "C:\inetpub\sites\edu-dev.coko38.ru\venv\lib\site-packages\openpyxl\workbook\workbook.py", line 407, in save
    save_workbook(self, filename)
  File "C:\inetpub\sites\edu-dev.coko38.ru\venv\lib\site-packages\openpyxl\writer\excel.py", line 291, in save_workbook
    archive = ZipFile(filename, 'w', ZIP_DEFLATED, allowZip64=True)
  File "C:\Python39\lib\zipfile.py", line 1239, in __init__
    self.fp = io.open(file, filemode)
PermissionError: [Errno 13] Permission denied: '\\\\srv-fs-1.coko38.ru\\Docs\\Центр УЦ\\АИС Учебный Центр\\Отчеты\\ПК-1\\Морозов Н.Д\\Отчет_18.07.2022.xlsx'
[2022-07-18 08:51:14,370: INFO/MainProcess] Connected to redis://172.16.55.20:6379/0
[2022-07-18 08:51:14,385: INFO/MainProcess] mingle: searching for neighbors
[2022-07-18 08:51:15,401: INFO/MainProcess] mingle: all alone
[2022-07-18 08:51:15,448: WARNING/MainProcess] C:\inetpub\sites\edu-dev.coko38.ru\venv\lib\site-packages\celery\fixups\django.py:203: UserWarning: Using settings.DEBUG leads to a memory
            leak, never use this setting in production environments!
  warnings.warn('''Using settings.DEBUG leads to a memory

[2022-07-18 08:51:15,448: INFO/MainProcess] celery@srv-dev ready.
[2022-07-18 08:51:15,448: INFO/MainProcess] pidbox: Connected to redis://172.16.55.20:6379/0.
[2022-07-18 08:55:09,690: INFO/MainProcess] Connected to redis://172.16.55.20:6379/0
[2022-07-18 08:55:09,690: INFO/MainProcess] mingle: searching for neighbors
[2022-07-18 08:55:10,712: INFO/MainProcess] mingle: all alone
[2022-07-18 08:55:10,743: WARNING/MainProcess] C:\inetpub\sites\edu-dev.coko38.ru\venv\lib\site-packages\celery\fixups\django.py:203: UserWarning: Using settings.DEBUG leads to a memory
            leak, never use this setting in production environments!
  warnings.warn('''Using settings.DEBUG leads to a memory

[2022-07-18 08:55:10,743: INFO/MainProcess] celery@srv-dev ready.
[2022-07-18 08:55:10,743: INFO/MainProcess] pidbox: Connected to redis://172.16.55.20:6379/0.
[2022-07-18 08:56:44,470: INFO/MainProcess] Connected to redis://172.16.55.20:6379/0
[2022-07-18 08:56:44,470: INFO/MainProcess] mingle: searching for neighbors
[2022-07-18 08:56:45,477: INFO/MainProcess] mingle: all alone
[2022-07-18 08:56:45,538: WARNING/MainProcess] C:\inetpub\sites\edu-dev.coko38.ru\venv\lib\site-packages\celery\fixups\django.py:203: UserWarning: Using settings.DEBUG leads to a memory
            leak, never use this setting in production environments!
  warnings.warn('''Using settings.DEBUG leads to a memory

[2022-07-18 08:56:45,553: INFO/MainProcess] celery@srv-dev ready.
[2022-07-18 08:56:45,553: INFO/MainProcess] pidbox: Connected to redis://172.16.55.20:6379/0.
[2022-07-18 09:22:31,228: INFO/MainProcess] Connected to redis://172.16.55.20:6379/0
[2022-07-18 09:22:31,243: INFO/MainProcess] mingle: searching for neighbors
[2022-07-18 09:22:32,232: INFO/MainProcess] mingle: all alone
[2022-07-18 09:22:32,263: WARNING/MainProcess] C:\inetpub\sites\edu-dev.coko38.ru\venv\lib\site-packages\celery\fixups\django.py:203: UserWarning: Using settings.DEBUG leads to a memory
            leak, never use this setting in production environments!
  warnings.warn('''Using settings.DEBUG leads to a memory

[2022-07-18 09:22:32,263: INFO/MainProcess] celery@srv-dev ready.
[2022-07-18 09:22:32,263: INFO/MainProcess] pidbox: Connected to redis://172.16.55.20:6379/0.
[2022-07-18 09:23:28,599: INFO/MainProcess] Events of group {task} enabled by remote.
[2022-07-18 09:24:44,543: INFO/MainProcess] Task centre.tasks.generate_pk1[82ea2af2-4ed3-4cf5-b847-fe682db549f9] received
[2022-07-18 09:25:09,833: ERROR/MainProcess] Task centre.tasks.generate_pk1[82ea2af2-4ed3-4cf5-b847-fe682db549f9] raised unexpected: PermissionError(13, 'Permission denied')
Traceback (most recent call last):
  File "C:\inetpub\sites\edu-dev.coko38.ru\venv\lib\site-packages\celery\app\trace.py", line 451, in trace_task
    R = retval = fun(*args, **kwargs)
  File "C:\inetpub\sites\edu-dev.coko38.ru\venv\lib\site-packages\celery\app\trace.py", line 734, in __protected_call__
    return self.run(*args, **kwargs)
  File "C:\inetpub\sites\edu-dev.coko38.ru\edu\centre\tasks.py", line 1002, in generate_pk1
    save_report(info, info2, info3, info4, profile_id, report_id)
  File "C:\inetpub\sites\edu-dev.coko38.ru\edu\centre\another.py", line 52, in save_report
    writer.save(newpath + "Отчет_" + datetime.today().strftime('%d.%m.%Y') + ".xlsx")
  File "C:\inetpub\sites\edu-dev.coko38.ru\venv\lib\site-packages\xltpl\writerx.py", line 95, in save
    self.workbook.save(fname)
  File "C:\inetpub\sites\edu-dev.coko38.ru\venv\lib\site-packages\openpyxl\workbook\workbook.py", line 407, in save
    save_workbook(self, filename)
  File "C:\inetpub\sites\edu-dev.coko38.ru\venv\lib\site-packages\openpyxl\writer\excel.py", line 291, in save_workbook
    archive = ZipFile(filename, 'w', ZIP_DEFLATED, allowZip64=True)
  File "C:\Python39\lib\zipfile.py", line 1239, in __init__
    self.fp = io.open(file, filemode)
PermissionError: [Errno 13] Permission denied: '\\\\srv-fs-1.coko38.ru\\Docs\\Центр УЦ\\АИС Учебный Центр\\Отчеты\\ПК-1\\Морозов Н.Д\\Отчет_18.07.2022.xlsx'
[2022-07-18 10:07:33,701: INFO/MainProcess] Connected to redis://172.16.55.20:6379/0
[2022-07-18 10:07:33,748: INFO/MainProcess] mingle: searching for neighbors
[2022-07-18 10:07:34,781: INFO/MainProcess] mingle: all alone
[2022-07-18 10:07:34,811: INFO/MainProcess] pidbox: Connected to redis://172.16.55.20:6379/0.
[2022-07-18 10:07:34,826: WARNING/MainProcess] C:\inetpub\sites\edu-dev.coko38.ru\venv\lib\site-packages\celery\fixups\django.py:203: UserWarning: Using settings.DEBUG leads to a memory
            leak, never use this setting in production environments!
  warnings.warn('''Using settings.DEBUG leads to a memory

[2022-07-18 10:07:34,841: INFO/MainProcess] celery@srv-dev ready.
[2022-07-18 10:08:54,263: INFO/MainProcess] Events of group {task} enabled by remote.
[2022-07-18 10:09:26,980: INFO/MainProcess] Task centre.tasks.generate_pk1[8538e8b6-30c6-4efe-ada2-1d42ba44a7dd] received
[2022-07-18 10:09:53,094: WARNING/MainProcess] C:\inetpub\sites\edu-dev.coko38.ru\venv\lib\site-packages\django\db\models\fields\__init__.py:1534: RuntimeWarning: DateTimeField Reports.date_finish received a naive datetime (2022-07-18 10:09:53.078795) while time zone support is active.
  warnings.warn(

[2022-07-18 10:09:53,219: ERROR/MainProcess] Task centre.tasks.generate_pk1[8538e8b6-30c6-4efe-ada2-1d42ba44a7dd] raised unexpected: NameError("name 'save_report' is not defined")
Traceback (most recent call last):
  File "C:\inetpub\sites\edu-dev.coko38.ru\venv\lib\site-packages\celery\app\trace.py", line 451, in trace_task
    R = retval = fun(*args, **kwargs)
  File "C:\inetpub\sites\edu-dev.coko38.ru\venv\lib\site-packages\celery\app\trace.py", line 734, in __protected_call__
    return self.run(*args, **kwargs)
  File "C:\inetpub\sites\edu-dev.coko38.ru\edu\centre\tasks.py", line 1047, in generate_pk1
    save_report(info, info2, info3, info4, profile_id, report_id)
NameError: name 'save_report' is not defined
[2022-07-18 10:11:21,803: INFO/MainProcess] Connected to redis://172.16.55.20:6379/0
[2022-07-18 10:11:21,803: INFO/MainProcess] mingle: searching for neighbors
[2022-07-18 10:11:22,823: INFO/MainProcess] mingle: all alone
[2022-07-18 10:11:25,817: INFO/MainProcess] pidbox: Connected to redis://172.16.55.20:6379/0.
[2022-07-18 10:11:31,810: WARNING/MainProcess] C:\inetpub\sites\edu-dev.coko38.ru\venv\lib\site-packages\celery\fixups\django.py:203: UserWarning: Using settings.DEBUG leads to a memory
            leak, never use this setting in production environments!
  warnings.warn('''Using settings.DEBUG leads to a memory

[2022-07-18 10:11:31,810: INFO/MainProcess] celery@srv-dev ready.
[2022-07-18 10:19:06,117: INFO/MainProcess] Events of group {task} enabled by remote.
[2022-07-18 10:19:29,588: INFO/MainProcess] Task centre.tasks.generate_pk1[d492ea12-1bd9-45fd-87f6-0bbbd8d7b95d] received
[2022-07-18 10:19:56,378: WARNING/MainProcess] C:\inetpub\sites\edu-dev.coko38.ru\venv\lib\site-packages\django\db\models\fields\__init__.py:1534: RuntimeWarning: DateTimeField Reports.date_finish received a naive datetime (2022-07-18 10:19:56.347237) while time zone support is active.
  warnings.warn(

[2022-07-18 10:19:59,799: INFO/MainProcess] Task centre.tasks.generate_pk1[d492ea12-1bd9-45fd-87f6-0bbbd8d7b95d] succeeded in 30.187000000000012s: None
[2022-07-18 10:55:45,968: INFO/MainProcess] Task centre.tasks.generate_pk1[e6f242f2-3082-4b36-87ab-deaaeffa13ab] received
[2022-07-18 10:56:12,601: WARNING/MainProcess] C:\inetpub\sites\edu-dev.coko38.ru\venv\lib\site-packages\django\db\models\fields\__init__.py:1534: RuntimeWarning: DateTimeField Reports.date_finish received a naive datetime (2022-07-18 10:56:12.600530) while time zone support is active.
  warnings.warn(

[2022-07-18 10:56:15,542: INFO/MainProcess] Task centre.tasks.generate_pk1[e6f242f2-3082-4b36-87ab-deaaeffa13ab] succeeded in 29.577999999999975s: None
[2022-07-18 11:02:49,298: INFO/MainProcess] Connected to redis://172.16.55.20:6379/0
[2022-07-18 11:02:49,311: INFO/MainProcess] mingle: searching for neighbors
[2022-07-18 11:02:50,353: INFO/MainProcess] mingle: all alone
[2022-07-18 11:02:50,384: INFO/MainProcess] pidbox: Connected to redis://172.16.55.20:6379/0.
[2022-07-18 11:02:50,400: WARNING/MainProcess] C:\inetpub\sites\edu-dev.coko38.ru\venv\lib\site-packages\celery\fixups\django.py:203: UserWarning: Using settings.DEBUG leads to a memory
            leak, never use this setting in production environments!
  warnings.warn('''Using settings.DEBUG leads to a memory

[2022-07-18 11:02:50,415: INFO/MainProcess] celery@srv-dev ready.
[2022-07-18 11:03:39,771: INFO/MainProcess] Task centre.tasks.generate_pk1[6a8e22b6-e5b1-451a-9cd1-91986d941a82] received
[2022-07-18 11:04:06,286: WARNING/MainProcess] C:\inetpub\sites\edu-dev.coko38.ru\venv\lib\site-packages\django\db\models\fields\__init__.py:1534: RuntimeWarning: DateTimeField Reports.date_finish received a naive datetime (2022-07-18 11:04:06.271177) while time zone support is active.
  warnings.warn(

[2022-07-18 11:04:09,287: INFO/MainProcess] Task centre.tasks.generate_pk1[6a8e22b6-e5b1-451a-9cd1-91986d941a82] succeeded in 29.516000000000005s: None
[2022-07-18 11:11:31,837: INFO/MainProcess] Connected to redis://172.16.55.20:6379/0
[2022-07-18 11:11:31,868: INFO/MainProcess] mingle: searching for neighbors
[2022-07-18 11:11:38,889: INFO/MainProcess] mingle: all alone
[2022-07-18 11:11:41,951: WARNING/MainProcess] C:\inetpub\sites\edu-dev.coko38.ru\venv\lib\site-packages\celery\fixups\django.py:203: UserWarning: Using settings.DEBUG leads to a memory
            leak, never use this setting in production environments!
  warnings.warn('''Using settings.DEBUG leads to a memory

[2022-07-18 11:11:41,951: INFO/MainProcess] celery@srv-dev ready.
[2022-07-18 11:11:41,951: INFO/MainProcess] pidbox: Connected to redis://172.16.55.20:6379/0.
[2022-07-18 11:13:39,953: INFO/MainProcess] Task centre.tasks.generate_pk1[f18c019f-3fdd-47fd-a96f-31d53e67aa60] received
[2022-07-18 11:14:05,234: ERROR/MainProcess] Task centre.tasks.generate_pk1[f18c019f-3fdd-47fd-a96f-31d53e67aa60] raised unexpected: FileNotFoundError(2, 'No such file or directory')
Traceback (most recent call last):
  File "C:\inetpub\sites\edu-dev.coko38.ru\venv\lib\site-packages\celery\app\trace.py", line 451, in trace_task
    R = retval = fun(*args, **kwargs)
  File "C:\inetpub\sites\edu-dev.coko38.ru\venv\lib\site-packages\celery\app\trace.py", line 734, in __protected_call__
    return self.run(*args, **kwargs)
  File "C:\inetpub\sites\edu-dev.coko38.ru\edu\centre\tasks.py", line 1042, in generate_pk1
    writer.save(newpath + "Отчет_" + datetime.today().strftime('%d.%m.%Y') + ".xlsx")
  File "C:\inetpub\sites\edu-dev.coko38.ru\venv\lib\site-packages\xltpl\writerx.py", line 95, in save
    self.workbook.save(fname)
  File "C:\inetpub\sites\edu-dev.coko38.ru\venv\lib\site-packages\openpyxl\workbook\workbook.py", line 407, in save
    save_workbook(self, filename)
  File "C:\inetpub\sites\edu-dev.coko38.ru\venv\lib\site-packages\openpyxl\writer\excel.py", line 291, in save_workbook
    archive = ZipFile(filename, 'w', ZIP_DEFLATED, allowZip64=True)
  File "C:\Python39\lib\zipfile.py", line 1239, in __init__
    self.fp = io.open(file, filemode)
FileNotFoundError: [Errno 2] No such file or directory: 'C:\\Отчеты\\ПК-1\\Морозов Н.Д\\Отчет_18.07.2022.xlsx'
[2022-07-18 11:16:10,364: INFO/MainProcess] Events of group {task} enabled by remote.
[2022-07-18 11:17:19,805: INFO/MainProcess] Task centre.tasks.generate_pk1[52565669-7553-4f61-bfc5-799be0bd99bb] received
[2022-07-18 11:17:45,016: ERROR/MainProcess] Task centre.tasks.generate_pk1[52565669-7553-4f61-bfc5-799be0bd99bb] raised unexpected: FileNotFoundError(2, 'No such file or directory')
Traceback (most recent call last):
  File "C:\inetpub\sites\edu-dev.coko38.ru\venv\lib\site-packages\celery\app\trace.py", line 451, in trace_task
    R = retval = fun(*args, **kwargs)
  File "C:\inetpub\sites\edu-dev.coko38.ru\venv\lib\site-packages\celery\app\trace.py", line 734, in __protected_call__
    return self.run(*args, **kwargs)
  File "C:\inetpub\sites\edu-dev.coko38.ru\edu\centre\tasks.py", line 1042, in generate_pk1
    writer.save(newpath + "Отчет_" + datetime.today().strftime('%d.%m.%Y') + ".xlsx")
  File "C:\inetpub\sites\edu-dev.coko38.ru\venv\lib\site-packages\xltpl\writerx.py", line 95, in save
    self.workbook.save(fname)
  File "C:\inetpub\sites\edu-dev.coko38.ru\venv\lib\site-packages\openpyxl\workbook\workbook.py", line 407, in save
    save_workbook(self, filename)
  File "C:\inetpub\sites\edu-dev.coko38.ru\venv\lib\site-packages\openpyxl\writer\excel.py", line 291, in save_workbook
    archive = ZipFile(filename, 'w', ZIP_DEFLATED, allowZip64=True)
  File "C:\Python39\lib\zipfile.py", line 1239, in __init__
    self.fp = io.open(file, filemode)
FileNotFoundError: [Errno 2] No such file or directory: 'C:\\Отчеты\\ПК-1\\Морозов Н.Д\\Отчет_18.07.2022.xlsx'
[2022-07-18 11:20:26,953: INFO/MainProcess] Connected to redis://172.16.55.20:6379/0
[2022-07-18 11:20:26,965: INFO/MainProcess] mingle: searching for neighbors
[2022-07-18 11:20:27,986: INFO/MainProcess] mingle: all alone
[2022-07-18 11:20:31,008: INFO/MainProcess] pidbox: Connected to redis://172.16.55.20:6379/0.
[2022-07-18 11:20:34,021: WARNING/MainProcess] C:\inetpub\sites\edu-dev.coko38.ru\venv\lib\site-packages\celery\fixups\django.py:203: UserWarning: Using settings.DEBUG leads to a memory
            leak, never use this setting in production environments!
  warnings.warn('''Using settings.DEBUG leads to a memory

[2022-07-18 11:20:34,022: INFO/MainProcess] celery@srv-dev ready.
[2022-07-18 11:23:37,183: INFO/MainProcess] Task centre.tasks.generate_pk1[d20af9fe-a53e-4850-acf5-8a32cf982ea9] received
[2022-07-18 11:24:04,235: WARNING/MainProcess] C:\inetpub\sites\edu-dev.coko38.ru\venv\lib\site-packages\django\db\models\fields\__init__.py:1534: RuntimeWarning: DateTimeField Reports.date_finish received a naive datetime (2022-07-18 11:24:04.204013) while time zone support is active.
  warnings.warn(

[2022-07-18 11:24:06,641: INFO/MainProcess] Task centre.tasks.generate_pk1[d20af9fe-a53e-4850-acf5-8a32cf982ea9] succeeded in 29.452999999999975s: None
[2022-07-18 11:39:43,844: INFO/MainProcess] Task centre.tasks.generate_pk1[8336db61-81ec-4c8f-8011-171b2f9facce] received
[2022-07-18 11:40:10,251: WARNING/MainProcess] C:\inetpub\sites\edu-dev.coko38.ru\venv\lib\site-packages\django\db\models\fields\__init__.py:1534: RuntimeWarning: DateTimeField Reports.date_finish received a naive datetime (2022-07-18 11:40:10.251035) while time zone support is active.
  warnings.warn(

[2022-07-18 11:40:12,547: INFO/MainProcess] Task centre.tasks.generate_pk1[8336db61-81ec-4c8f-8011-171b2f9facce] succeeded in 28.687000000000126s: None
[2022-07-18 15:02:06,492: INFO/MainProcess] Task centre.tasks.generate_pk1[bdc45699-37ca-4643-949b-6bed41b2a6b8] received
[2022-07-18 15:02:32,180: WARNING/MainProcess] C:\inetpub\sites\edu-dev.coko38.ru\venv\lib\site-packages\django\db\models\fields\__init__.py:1534: RuntimeWarning: DateTimeField Reports.date_finish received a naive datetime (2022-07-18 15:02:32.180873) while time zone support is active.
  warnings.warn(

[2022-07-18 15:02:34,680: INFO/MainProcess] Task centre.tasks.generate_pk1[bdc45699-37ca-4643-949b-6bed41b2a6b8] succeeded in 28.186999999999898s: None
[2022-07-18 16:17:24,212: INFO/MainProcess] Task centre.tasks.EmailOfferPay[215cc9b6-c75c-4b4a-8f5d-c45dc157cf06] received
[2022-07-18 16:17:27,139: INFO/MainProcess] Task centre.tasks.EmailOfferPay[215cc9b6-c75c-4b4a-8f5d-c45dc157cf06] succeeded in 2.937000000001717s: None
[2022-07-18 16:19:53,119: INFO/MainProcess] Task centre.tasks.EmailDeniedPay[5dacdfea-7377-49a0-be7c-70b7c4658682] received
[2022-07-18 16:19:55,447: INFO/MainProcess] Task centre.tasks.EmailDeniedPay[5dacdfea-7377-49a0-be7c-70b7c4658682] succeeded in 2.327999999997701s: None
[2022-07-18 16:21:50,279: INFO/MainProcess] Task centre.tasks.EmailAcceptPay[dcca7a99-d9fb-4296-bf3d-a855e4c3fdec] received
[2022-07-18 16:21:53,261: INFO/MainProcess] Task centre.tasks.EmailAcceptPay[dcca7a99-d9fb-4296-bf3d-a855e4c3fdec] succeeded in 2.985000000000582s: None
[2022-07-19 08:00:00,053: INFO/MainProcess] Task centre.tasks.CheckRegistrationEnd[b3db8a81-99dd-426b-8c5a-94cc224200d9] received
[2022-07-19 08:00:00,604: INFO/MainProcess] Task centre.tasks.ShowSurveyUrl[9ad6c045-6d55-47c7-b219-dda146ffcad4] received
[2022-07-19 08:00:00,682: INFO/MainProcess] Task centre.tasks.CheckRegistrationEnd[b3db8a81-99dd-426b-8c5a-94cc224200d9] succeeded in 0.6089999999967404s: None
[2022-07-19 08:00:00,682: INFO/MainProcess] Task centre.tasks.ShowSurveyUrl[9ad6c045-6d55-47c7-b219-dda146ffcad4] succeeded in 0.07800000000861473s: None
[2022-07-20 08:00:00,044: INFO/MainProcess] Task centre.tasks.ShowSurveyUrl[db6de8cc-8105-4373-8925-e18a4875e098] received
[2022-07-20 08:00:00,404: INFO/MainProcess] Task centre.tasks.CheckRegistrationEnd[58f39517-05fb-4ee9-ab30-d77a45a152e2] received
[2022-07-20 08:00:00,450: INFO/MainProcess] Task centre.tasks.ShowSurveyUrl[db6de8cc-8105-4373-8925-e18a4875e098] succeeded in 0.40600000001722947s: None
[2022-07-20 08:00:00,450: INFO/MainProcess] Task centre.tasks.CheckRegistrationEnd[58f39517-05fb-4ee9-ab30-d77a45a152e2] succeeded in 0.046999999991385266s: None
[2022-07-21 08:00:00,030: INFO/MainProcess] Task centre.tasks.CheckRegistrationEnd[0303a727-5305-4141-b219-0de74ce508d9] received
[2022-07-21 08:00:00,420: INFO/MainProcess] Task centre.tasks.ShowSurveyUrl[93e1f7b2-f1bf-49ba-8650-61e406b27f2b] received
[2022-07-21 08:00:00,483: INFO/MainProcess] Task centre.tasks.CheckRegistrationEnd[0303a727-5305-4141-b219-0de74ce508d9] succeeded in 0.45300000000861473s: None
[2022-07-21 08:00:00,483: INFO/MainProcess] Task centre.tasks.ShowSurveyUrl[93e1f7b2-f1bf-49ba-8650-61e406b27f2b] succeeded in 0.0629999999946449s: None
[2022-07-21 09:18:17,868: INFO/MainProcess] Task centre.tasks.generate_pk1[9ad66bfa-f8cf-40a0-b865-361e191a8173] received
[2022-07-21 09:18:43,431: WARNING/MainProcess] C:\inetpub\sites\edu-dev.coko38.ru\venv\lib\site-packages\django\db\models\fields\__init__.py:1534: RuntimeWarning: DateTimeField Reports.date_finish received a naive datetime (2022-07-21 09:18:43.431658) while time zone support is active.
  warnings.warn(

[2022-07-21 09:18:46,447: INFO/MainProcess] Task centre.tasks.generate_pk1[9ad66bfa-f8cf-40a0-b865-361e191a8173] succeeded in 28.578000000008615s: None
[2022-07-21 09:34:07,569: INFO/MainProcess] Task centre.tasks.generate_pk1[533088c3-bad3-41a9-9064-fedb3b7b141d] received
[2022-07-21 09:34:33,210: WARNING/MainProcess] C:\inetpub\sites\edu-dev.coko38.ru\venv\lib\site-packages\django\db\models\fields\__init__.py:1534: RuntimeWarning: DateTimeField Reports.date_finish received a naive datetime (2022-07-21 09:34:33.210585) while time zone support is active.
  warnings.warn(

[2022-07-21 09:34:36,460: INFO/MainProcess] Task centre.tasks.generate_pk1[533088c3-bad3-41a9-9064-fedb3b7b141d] succeeded in 28.89000000001397s: None
[2022-07-21 09:34:57,672: INFO/MainProcess] Task centre.tasks.generate_pk1[0a747c77-3746-4f0b-a563-ac2574dd79b5] received
[2022-07-21 09:35:22,876: WARNING/MainProcess] C:\inetpub\sites\edu-dev.coko38.ru\venv\lib\site-packages\django\db\models\fields\__init__.py:1534: RuntimeWarning: DateTimeField Reports.date_finish received a naive datetime (2022-07-21 09:35:22.876135) while time zone support is active.
  warnings.warn(

[2022-07-21 09:35:26,070: INFO/MainProcess] Task centre.tasks.generate_pk1[0a747c77-3746-4f0b-a563-ac2574dd79b5] succeeded in 28.40700000000652s: None
[2022-07-21 11:06:53,950: INFO/MainProcess] Connected to redis://172.16.55.20:6379/0
[2022-07-21 11:06:53,950: INFO/MainProcess] mingle: searching for neighbors
[2022-07-21 11:06:54,961: INFO/MainProcess] mingle: all alone
[2022-07-21 11:06:55,022: WARNING/MainProcess] C:\inetpub\sites\edu-dev.coko38.ru\venv\lib\site-packages\celery\fixups\django.py:203: UserWarning: Using settings.DEBUG leads to a memory
            leak, never use this setting in production environments!
  warnings.warn('''Using settings.DEBUG leads to a memory

[2022-07-21 11:06:55,022: INFO/MainProcess] celery@srv-dev ready.
[2022-07-21 11:06:55,022: INFO/MainProcess] pidbox: Connected to redis://172.16.55.20:6379/0.
[2022-07-21 11:13:47,302: INFO/MainProcess] Task centre.tasks.generate_pk1[00d75797-4b67-4be9-9756-ed8ae3106d50] received
[2022-07-21 11:14:12,443: WARNING/MainProcess] C:\inetpub\sites\edu-dev.coko38.ru\venv\lib\site-packages\django\db\models\fields\__init__.py:1534: RuntimeWarning: DateTimeField Reports.date_finish received a naive datetime (2022-07-21 11:14:12.443333) while time zone support is active.
  warnings.warn(

[2022-07-21 11:14:14,771: INFO/MainProcess] Task centre.tasks.generate_pk1[00d75797-4b67-4be9-9756-ed8ae3106d50] succeeded in 27.468999999999994s: None
[2022-07-22 08:00:00,046: INFO/MainProcess] Task centre.tasks.ShowSurveyUrl[fb177255-a550-4f7e-8b11-168f252f8ffa] received
[2022-07-22 08:00:00,505: INFO/MainProcess] Task centre.tasks.CheckRegistrationEnd[680999e1-6739-4181-90f7-c38feaebe230] received
[2022-07-22 08:00:00,583: INFO/MainProcess] Task centre.tasks.ShowSurveyUrl[fb177255-a550-4f7e-8b11-168f252f8ffa] succeeded in 0.5160000000032596s: None
[2022-07-22 08:00:00,583: INFO/MainProcess] Task centre.tasks.CheckRegistrationEnd[680999e1-6739-4181-90f7-c38feaebe230] succeeded in 0.07899999999790452s: None
[2022-07-22 10:47:30,985: INFO/MainProcess] Task centre.tasks.generate_pk1[eac7959f-cd60-4b00-8761-33fdd81be1e7] received
[2022-07-22 10:47:31,297: ERROR/MainProcess] Task centre.tasks.generate_pk1[eac7959f-cd60-4b00-8761-33fdd81be1e7] raised unexpected: ProgrammingError('42S22', "[42S22] [Microsoft][ODBC Driver 17 for SQL Server][SQL Server]Invalid column name 'cat_id'. (207) (SQLExecDirectW); [42S22] [Microsoft][ODBC Driver 17 for SQL Server][SQL Server]Statement(s) could not be prepared. (8180)")
Traceback (most recent call last):
  File "C:\inetpub\sites\edu-dev.coko38.ru\venv\lib\site-packages\django\db\backends\utils.py", line 89, in _execute
    return self.cursor.execute(sql, params)
  File "C:\inetpub\sites\edu-dev.coko38.ru\venv\lib\site-packages\mssql\base.py", line 576, in execute
    return self.cursor.execute(sql, params)
pyodbc.ProgrammingError: ('42S22', "[42S22] [Microsoft][ODBC Driver 17 for SQL Server][SQL Server]Invalid column name 'cat_id'. (207) (SQLExecDirectW); [42S22] [Microsoft][ODBC Driver 17 for SQL Server][SQL Server]Statement(s) could not be prepared. (8180)")

The above exception was the direct cause of the following exception:

Traceback (most recent call last):
  File "C:\inetpub\sites\edu-dev.coko38.ru\venv\lib\site-packages\celery\app\trace.py", line 451, in trace_task
    R = retval = fun(*args, **kwargs)
  File "C:\inetpub\sites\edu-dev.coko38.ru\venv\lib\site-packages\celery\app\trace.py", line 734, in __protected_call__
    return self.run(*args, **kwargs)
  File "C:\inetpub\sites\edu-dev.coko38.ru\edu\centre\tasks.py", line 201, in generate_pk1
    for form in forms:
  File "C:\inetpub\sites\edu-dev.coko38.ru\venv\lib\site-packages\django\db\models\query.py", line 320, in __iter__
    self._fetch_all()
  File "C:\inetpub\sites\edu-dev.coko38.ru\venv\lib\site-packages\django\db\models\query.py", line 1507, in _fetch_all
    self._result_cache = list(self._iterable_class(self))
  File "C:\inetpub\sites\edu-dev.coko38.ru\venv\lib\site-packages\django\db\models\query.py", line 57, in __iter__
    results = compiler.execute_sql(
  File "C:\inetpub\sites\edu-dev.coko38.ru\venv\lib\site-packages\django\db\models\sql\compiler.py", line 1361, in execute_sql
    cursor.execute(sql, params)
  File "C:\inetpub\sites\edu-dev.coko38.ru\venv\lib\site-packages\django\db\backends\utils.py", line 103, in execute
    return super().execute(sql, params)
  File "C:\inetpub\sites\edu-dev.coko38.ru\venv\lib\site-packages\django\db\backends\utils.py", line 67, in execute
    return self._execute_with_wrappers(
  File "C:\inetpub\sites\edu-dev.coko38.ru\venv\lib\site-packages\django\db\backends\utils.py", line 80, in _execute_with_wrappers
    return executor(sql, params, many, context)
  File "C:\inetpub\sites\edu-dev.coko38.ru\venv\lib\site-packages\django\db\backends\utils.py", line 89, in _execute
    return self.cursor.execute(sql, params)
  File "C:\inetpub\sites\edu-dev.coko38.ru\venv\lib\site-packages\django\db\utils.py", line 91, in __exit__
    raise dj_exc_value.with_traceback(traceback) from exc_value
  File "C:\inetpub\sites\edu-dev.coko38.ru\venv\lib\site-packages\django\db\backends\utils.py", line 89, in _execute
    return self.cursor.execute(sql, params)
  File "C:\inetpub\sites\edu-dev.coko38.ru\venv\lib\site-packages\mssql\base.py", line 576, in execute
    return self.cursor.execute(sql, params)
django.db.utils.ProgrammingError: ('42S22', "[42S22] [Microsoft][ODBC Driver 17 for SQL Server][SQL Server]Invalid column name 'cat_id'. (207) (SQLExecDirectW); [42S22] [Microsoft][ODBC Driver 17 for SQL Server][SQL Server]Statement(s) could not be prepared. (8180)")
[2022-07-22 10:49:45,354: INFO/MainProcess] Events of group {task} enabled by remote.
[2022-07-22 10:50:01,946: INFO/MainProcess] Task centre.tasks.generate_pk1[72fd54c0-8f1c-47db-9251-8f17a0056678] received
[2022-07-22 10:50:02,108: ERROR/MainProcess] Task centre.tasks.generate_pk1[72fd54c0-8f1c-47db-9251-8f17a0056678] raised unexpected: ProgrammingError('42S22', "[42S22] [Microsoft][ODBC Driver 17 for SQL Server][SQL Server]Invalid column name 'cat_id'. (207) (SQLExecDirectW); [42S22] [Microsoft][ODBC Driver 17 for SQL Server][SQL Server]Statement(s) could not be prepared. (8180)")
Traceback (most recent call last):
  File "C:\inetpub\sites\edu-dev.coko38.ru\venv\lib\site-packages\django\db\backends\utils.py", line 89, in _execute
    return self.cursor.execute(sql, params)
  File "C:\inetpub\sites\edu-dev.coko38.ru\venv\lib\site-packages\mssql\base.py", line 576, in execute
    return self.cursor.execute(sql, params)
pyodbc.ProgrammingError: ('42S22', "[42S22] [Microsoft][ODBC Driver 17 for SQL Server][SQL Server]Invalid column name 'cat_id'. (207) (SQLExecDirectW); [42S22] [Microsoft][ODBC Driver 17 for SQL Server][SQL Server]Statement(s) could not be prepared. (8180)")

The above exception was the direct cause of the following exception:

Traceback (most recent call last):
  File "C:\inetpub\sites\edu-dev.coko38.ru\venv\lib\site-packages\celery\app\trace.py", line 451, in trace_task
    R = retval = fun(*args, **kwargs)
  File "C:\inetpub\sites\edu-dev.coko38.ru\venv\lib\site-packages\celery\app\trace.py", line 734, in __protected_call__
    return self.run(*args, **kwargs)
  File "C:\inetpub\sites\edu-dev.coko38.ru\edu\centre\tasks.py", line 201, in generate_pk1
    for form in forms:
  File "C:\inetpub\sites\edu-dev.coko38.ru\venv\lib\site-packages\django\db\models\query.py", line 320, in __iter__
    self._fetch_all()
  File "C:\inetpub\sites\edu-dev.coko38.ru\venv\lib\site-packages\django\db\models\query.py", line 1507, in _fetch_all
    self._result_cache = list(self._iterable_class(self))
  File "C:\inetpub\sites\edu-dev.coko38.ru\venv\lib\site-packages\django\db\models\query.py", line 57, in __iter__
    results = compiler.execute_sql(
  File "C:\inetpub\sites\edu-dev.coko38.ru\venv\lib\site-packages\django\db\models\sql\compiler.py", line 1361, in execute_sql
    cursor.execute(sql, params)
  File "C:\inetpub\sites\edu-dev.coko38.ru\venv\lib\site-packages\django\db\backends\utils.py", line 103, in execute
    return super().execute(sql, params)
  File "C:\inetpub\sites\edu-dev.coko38.ru\venv\lib\site-packages\django\db\backends\utils.py", line 67, in execute
    return self._execute_with_wrappers(
  File "C:\inetpub\sites\edu-dev.coko38.ru\venv\lib\site-packages\django\db\backends\utils.py", line 80, in _execute_with_wrappers
    return executor(sql, params, many, context)
  File "C:\inetpub\sites\edu-dev.coko38.ru\venv\lib\site-packages\django\db\backends\utils.py", line 89, in _execute
    return self.cursor.execute(sql, params)
  File "C:\inetpub\sites\edu-dev.coko38.ru\venv\lib\site-packages\django\db\utils.py", line 91, in __exit__
    raise dj_exc_value.with_traceback(traceback) from exc_value
  File "C:\inetpub\sites\edu-dev.coko38.ru\venv\lib\site-packages\django\db\backends\utils.py", line 89, in _execute
    return self.cursor.execute(sql, params)
  File "C:\inetpub\sites\edu-dev.coko38.ru\venv\lib\site-packages\mssql\base.py", line 576, in execute
    return self.cursor.execute(sql, params)
django.db.utils.ProgrammingError: ('42S22', "[42S22] [Microsoft][ODBC Driver 17 for SQL Server][SQL Server]Invalid column name 'cat_id'. (207) (SQLExecDirectW); [42S22] [Microsoft][ODBC Driver 17 for SQL Server][SQL Server]Statement(s) could not be prepared. (8180)")
[2022-07-22 10:52:37,983: INFO/MainProcess] Connected to redis://172.16.55.20:6379/0
[2022-07-22 10:52:40,972: INFO/MainProcess] mingle: searching for neighbors
[2022-07-22 10:52:47,986: INFO/MainProcess] mingle: all alone
[2022-07-22 10:52:48,001: INFO/MainProcess] pidbox: Connected to redis://172.16.55.20:6379/0.
[2022-07-22 10:52:48,017: WARNING/MainProcess] C:\inetpub\sites\edu-dev.coko38.ru\venv\lib\site-packages\celery\fixups\django.py:203: UserWarning: Using settings.DEBUG leads to a memory
            leak, never use this setting in production environments!
  warnings.warn('''Using settings.DEBUG leads to a memory

[2022-07-22 10:52:48,017: INFO/MainProcess] celery@srv-dev ready.
[2022-07-22 10:53:42,355: INFO/MainProcess] Task centre.tasks.generate_pk1[3bdd8a15-1e5b-48e3-8860-76e42982be92] received
[2022-07-22 10:54:08,325: WARNING/MainProcess] C:\inetpub\sites\edu-dev.coko38.ru\venv\lib\site-packages\django\db\models\fields\__init__.py:1534: RuntimeWarning: DateTimeField Reports.date_finish received a naive datetime (2022-07-22 10:54:08.325391) while time zone support is active.
  warnings.warn(

[2022-07-22 10:54:12,581: INFO/MainProcess] Task centre.tasks.generate_pk1[3bdd8a15-1e5b-48e3-8860-76e42982be92] succeeded in 30.233999999999995s: None
[2022-07-23 08:00:00,057: INFO/MainProcess] Task centre.tasks.ShowSurveyUrl[94667b67-bb52-4816-b683-320fb458b508] received
[2022-07-23 08:00:00,510: INFO/MainProcess] Task centre.tasks.CheckRegistrationEnd[8c5dd192-37ed-44e7-a06d-328857478798] received
[2022-07-23 08:00:00,604: INFO/MainProcess] Task centre.tasks.ShowSurveyUrl[94667b67-bb52-4816-b683-320fb458b508] succeeded in 0.5469999999913853s: None
[2022-07-23 08:00:00,604: INFO/MainProcess] Task centre.tasks.CheckRegistrationEnd[8c5dd192-37ed-44e7-a06d-328857478798] succeeded in 0.07799999999406282s: None
[2022-07-24 08:00:00,024: INFO/MainProcess] Task centre.tasks.CheckRegistrationEnd[57c728cc-98f3-44f2-91a8-abe4745eb033] received
[2022-07-24 08:00:00,524: INFO/MainProcess] Task centre.tasks.ShowSurveyUrl[d6d8867e-5be8-451f-a5de-27819c044764] received
[2022-07-24 08:00:00,602: INFO/MainProcess] Task centre.tasks.CheckRegistrationEnd[57c728cc-98f3-44f2-91a8-abe4745eb033] succeeded in 0.5779999999795109s: None
[2022-07-24 08:00:00,602: INFO/MainProcess] Task centre.tasks.ShowSurveyUrl[d6d8867e-5be8-451f-a5de-27819c044764] succeeded in 0.0779999999795109s: None
[2022-07-25 08:00:00,022: INFO/MainProcess] Task centre.tasks.ShowSurveyUrl[ace2a91a-e086-4e2b-bfa9-acf38f49d9cb] received
[2022-07-25 08:00:00,193: INFO/MainProcess] Task centre.tasks.CheckRegistrationEnd[4ca4545d-73cd-4b81-ad70-3d8b09b0eb71] received
[2022-07-25 08:00:00,256: INFO/MainProcess] Task centre.tasks.ShowSurveyUrl[ace2a91a-e086-4e2b-bfa9-acf38f49d9cb] succeeded in 0.2340000000258442s: None
[2022-07-25 08:00:00,256: INFO/MainProcess] Task centre.tasks.CheckRegistrationEnd[4ca4545d-73cd-4b81-ad70-3d8b09b0eb71] succeeded in 0.062000000005355105s: None
[2022-07-26 08:00:00,047: INFO/MainProcess] Task centre.tasks.CheckRegistrationEnd[a0b5fbf6-13b1-4b5c-a218-9b5da6680e83] received
[2022-07-26 08:00:00,359: INFO/MainProcess] Task centre.tasks.ShowSurveyUrl[2ca6b29e-1bdc-41b0-ac80-80fb74a1de52] received
[2022-07-26 08:00:00,437: INFO/MainProcess] Task centre.tasks.CheckRegistrationEnd[a0b5fbf6-13b1-4b5c-a218-9b5da6680e83] succeeded in 0.39100000000325963s: None
[2022-07-26 08:00:00,437: INFO/MainProcess] Task centre.tasks.ShowSurveyUrl[2ca6b29e-1bdc-41b0-ac80-80fb74a1de52] succeeded in 0.0779999999795109s: None
[2022-07-26 16:33:26,833: INFO/MainProcess] Task centre.tasks.EmailOfferPay[5f7361d1-b068-43bf-acde-004f1737cd3e] received
[2022-07-26 16:33:30,099: INFO/MainProcess] Task centre.tasks.EmailOfferPay[5f7361d1-b068-43bf-acde-004f1737cd3e] succeeded in 3.25s: None
[2022-07-26 16:35:04,292: INFO/MainProcess] Task centre.tasks.EmailDeniedPay[81a687a0-4791-4530-b112-ed133715c3ac] received
[2022-07-26 16:35:06,667: INFO/MainProcess] Task centre.tasks.EmailDeniedPay[81a687a0-4791-4530-b112-ed133715c3ac] succeeded in 2.375s: None
[2022-07-26 16:40:54,712: INFO/MainProcess] Task centre.tasks.EmailAcceptPay[818f334b-c108-4b46-aa29-c63b18d51ff6] received
[2022-07-26 16:40:57,133: INFO/MainProcess] Task centre.tasks.EmailAcceptPay[818f334b-c108-4b46-aa29-c63b18d51ff6] succeeded in 2.422000000020489s: None
[2022-07-27 08:00:00,041: INFO/MainProcess] Task centre.tasks.ShowSurveyUrl[df30ea0b-0d05-4a35-9f87-5bce7f495274] received
[2022-07-27 08:00:00,429: INFO/MainProcess] Task centre.tasks.CheckRegistrationEnd[1345fd45-ce42-49c4-b185-514c8a1b817d] received
[2022-07-27 08:00:00,507: INFO/MainProcess] Task centre.tasks.ShowSurveyUrl[df30ea0b-0d05-4a35-9f87-5bce7f495274] succeeded in 0.4690000000409782s: None
[2022-07-27 08:00:00,507: INFO/MainProcess] Task centre.tasks.CheckRegistrationEnd[1345fd45-ce42-49c4-b185-514c8a1b817d] succeeded in 0.07800000003771856s: None
[2022-07-28 08:00:00,037: INFO/MainProcess] Task centre.tasks.ShowSurveyUrl[7625dc28-8c66-47f4-a079-00966d7e637a] received
[2022-07-28 08:00:00,397: INFO/MainProcess] Task centre.tasks.CheckRegistrationEnd[5ee11fc8-515e-4cda-b6e3-73277c766143] received
[2022-07-28 08:00:00,459: INFO/MainProcess] Task centre.tasks.ShowSurveyUrl[7625dc28-8c66-47f4-a079-00966d7e637a] succeeded in 0.4220000000204891s: None
[2022-07-28 08:00:00,459: INFO/MainProcess] Task centre.tasks.CheckRegistrationEnd[5ee11fc8-515e-4cda-b6e3-73277c766143] succeeded in 0.0470000000204891s: None
[2022-07-28 08:24:49,241: INFO/MainProcess] Connected to redis://172.16.55.20:6379/0
[2022-07-28 08:24:55,256: INFO/MainProcess] mingle: searching for neighbors
[2022-07-28 08:24:56,287: INFO/MainProcess] mingle: all alone
[2022-07-28 08:24:56,428: INFO/MainProcess] pidbox: Connected to redis://172.16.55.20:6379/0.
[2022-07-28 08:24:56,444: WARNING/MainProcess] C:\inetpub\sites\edu-dev.coko38.ru\venv\lib\site-packages\celery\fixups\django.py:203: UserWarning: Using settings.DEBUG leads to a memory
            leak, never use this setting in production environments!
  warnings.warn('''Using settings.DEBUG leads to a memory

[2022-07-28 08:24:56,444: INFO/MainProcess] celery@srv-dev ready.
[2022-07-28 08:26:32,937: INFO/MainProcess] Task centre.tasks.generate_pk1[4c2deb9a-ff7f-4f70-aaaa-b2ffd6b5d80d] received
[2022-07-28 08:26:58,391: WARNING/MainProcess] C:\inetpub\sites\edu-dev.coko38.ru\venv\lib\site-packages\django\db\models\fields\__init__.py:1534: RuntimeWarning: DateTimeField Reports.date_finish received a naive datetime (2022-07-28 08:26:58.391007) while time zone support is active.
  warnings.warn(

[2022-07-28 08:27:34,337: INFO/MainProcess] Task centre.tasks.generate_pk1[4c2deb9a-ff7f-4f70-aaaa-b2ffd6b5d80d] succeeded in 61.389999999999986s: None
[2022-07-28 08:37:10,766: INFO/MainProcess] Task centre.tasks.generate_pk1[b593f051-0f43-401b-93ee-87e86b560638] received
[2022-07-28 08:37:37,297: WARNING/MainProcess] C:\inetpub\sites\edu-dev.coko38.ru\venv\lib\site-packages\django\db\models\fields\__init__.py:1534: RuntimeWarning: DateTimeField Reports.date_finish received a naive datetime (2022-07-28 08:37:37.297362) while time zone support is active.
  warnings.warn(

[2022-07-28 08:37:39,422: INFO/MainProcess] Task centre.tasks.generate_pk1[b593f051-0f43-401b-93ee-87e86b560638] succeeded in 28.656000000000063s: None
[2022-07-28 08:42:02,283: INFO/MainProcess] Task centre.tasks.generate_pk1[303b0335-a280-4e70-b507-76c16d42dc51] received
[2022-07-28 08:42:02,518: ERROR/MainProcess] Task centre.tasks.generate_pk1[303b0335-a280-4e70-b507-76c16d42dc51] raised unexpected: AttributeError("'NoneType' object has no attribute 'name'")
Traceback (most recent call last):
  File "C:\inetpub\sites\edu-dev.coko38.ru\venv\lib\site-packages\celery\app\trace.py", line 451, in trace_task
    R = retval = fun(*args, **kwargs)
  File "C:\inetpub\sites\edu-dev.coko38.ru\venv\lib\site-packages\celery\app\trace.py", line 734, in __protected_call__
    return self.run(*args, **kwargs)
  File "C:\inetpub\sites\edu-dev.coko38.ru\edu\centre\tasks.py", line 514, in generate_pk1
    if 'руководители' in form.position_cat.name and 'службы' not in form.position_cat.name \
AttributeError: 'NoneType' object has no attribute 'name'
[2022-07-28 08:46:06,933: INFO/MainProcess] Events of group {task} enabled by remote.
[2022-07-28 08:46:17,639: INFO/MainProcess] Task centre.tasks.generate_pk1[88779037-66a7-42be-a51a-61130675dbdb] received
[2022-07-28 08:46:17,858: ERROR/MainProcess] Task centre.tasks.generate_pk1[88779037-66a7-42be-a51a-61130675dbdb] raised unexpected: AttributeError("'NoneType' object has no attribute 'name'")
Traceback (most recent call last):
  File "C:\inetpub\sites\edu-dev.coko38.ru\venv\lib\site-packages\celery\app\trace.py", line 451, in trace_task
    R = retval = fun(*args, **kwargs)
  File "C:\inetpub\sites\edu-dev.coko38.ru\venv\lib\site-packages\celery\app\trace.py", line 734, in __protected_call__
    return self.run(*args, **kwargs)
  File "C:\inetpub\sites\edu-dev.coko38.ru\edu\centre\tasks.py", line 514, in generate_pk1
    if 'руководители' in form.position_cat.name and 'службы' not in form.position_cat.name \
AttributeError: 'NoneType' object has no attribute 'name'
[2022-07-28 08:49:09,780: INFO/MainProcess] Connected to redis://172.16.55.20:6379/0
[2022-07-28 08:49:09,796: INFO/MainProcess] mingle: searching for neighbors
[2022-07-28 08:49:10,827: INFO/MainProcess] mingle: all alone
[2022-07-28 08:49:10,968: INFO/MainProcess] pidbox: Connected to redis://172.16.55.20:6379/0.
[2022-07-28 08:49:10,968: WARNING/MainProcess] C:\inetpub\sites\edu-dev.coko38.ru\venv\lib\site-packages\celery\fixups\django.py:203: UserWarning: Using settings.DEBUG leads to a memory
            leak, never use this setting in production environments!
  warnings.warn('''Using settings.DEBUG leads to a memory

[2022-07-28 08:49:10,984: INFO/MainProcess] celery@srv-dev ready.
[2022-07-28 08:49:26,391: INFO/MainProcess] Events of group {task} enabled by remote.
[2022-07-28 08:49:28,192: INFO/MainProcess] Task centre.tasks.generate_pk1[584deeef-ded1-46f7-a3cd-8e5ffb3cfc59] received
[2022-07-28 08:49:55,994: WARNING/MainProcess] C:\inetpub\sites\edu-dev.coko38.ru\venv\lib\site-packages\django\db\models\fields\__init__.py:1534: RuntimeWarning: DateTimeField Reports.date_finish received a naive datetime (2022-07-28 08:49:55.991087) while time zone support is active.
  warnings.warn(

[2022-07-28 08:49:59,898: INFO/MainProcess] Task centre.tasks.generate_pk1[584deeef-ded1-46f7-a3cd-8e5ffb3cfc59] succeeded in 31.71900000000005s: None
[2022-07-29 08:00:00,036: INFO/MainProcess] Task centre.tasks.ShowSurveyUrl[d00636ca-a443-43f2-9544-ad01067c74c4] received
[2022-07-29 08:00:00,411: INFO/MainProcess] Task centre.tasks.CheckRegistrationEnd[53de05c8-7343-453f-9c45-cf46b2758b12] received
[2022-07-29 08:00:00,505: INFO/MainProcess] Task centre.tasks.ShowSurveyUrl[d00636ca-a443-43f2-9544-ad01067c74c4] succeeded in 0.4529999999940628s: None
[2022-07-29 08:00:00,505: INFO/MainProcess] Task centre.tasks.CheckRegistrationEnd[53de05c8-7343-453f-9c45-cf46b2758b12] succeeded in 0.09399999999732245s: None
[2022-07-29 15:53:33,434: INFO/MainProcess] Task centre.tasks.generate_pk1[bc338d21-11e4-467e-bed7-f969689650f2] received
[2022-07-29 15:53:59,481: WARNING/MainProcess] C:\inetpub\sites\edu-dev.coko38.ru\venv\lib\site-packages\django\db\models\fields\__init__.py:1534: RuntimeWarning: DateTimeField Reports.date_finish received a naive datetime (2022-07-29 15:53:59.481922) while time zone support is active.
  warnings.warn(

[2022-07-29 15:54:02,464: INFO/MainProcess] Task centre.tasks.generate_pk1[bc338d21-11e4-467e-bed7-f969689650f2] succeeded in 29.014999999999418s: None
[2022-07-30 08:00:00,034: INFO/MainProcess] Task centre.tasks.CheckRegistrationEnd[d7d4a65e-8c29-4d7b-96cd-668e6d8fda8c] received
[2022-07-30 08:00:00,403: INFO/MainProcess] Task centre.tasks.ShowSurveyUrl[60d6d063-7f32-4954-9bf5-447670a5ab25] received
[2022-07-30 08:00:00,465: INFO/MainProcess] Task centre.tasks.CheckRegistrationEnd[d7d4a65e-8c29-4d7b-96cd-668e6d8fda8c] succeeded in 0.42199999999138527s: None
[2022-07-30 08:00:00,481: INFO/MainProcess] Task centre.tasks.ShowSurveyUrl[60d6d063-7f32-4954-9bf5-447670a5ab25] succeeded in 0.062000000005355105s: None
[2022-07-31 08:00:00,028: INFO/MainProcess] Task centre.tasks.CheckRegistrationEnd[dd149aa4-5450-4db5-a685-c3d4bde57da4] received
[2022-07-31 08:00:00,528: INFO/MainProcess] Task centre.tasks.ShowSurveyUrl[2b1b05b1-8547-4a14-a29d-1afe7bfb07bb] received
[2022-07-31 08:00:00,621: INFO/MainProcess] Task centre.tasks.CheckRegistrationEnd[dd149aa4-5450-4db5-a685-c3d4bde57da4] succeeded in 0.5939999999827705s: None
[2022-07-31 08:00:00,637: INFO/MainProcess] Task centre.tasks.ShowSurveyUrl[2b1b05b1-8547-4a14-a29d-1afe7bfb07bb] succeeded in 0.09299999999348074s: None
[2022-08-01 08:00:00,035: INFO/MainProcess] Task centre.tasks.ShowSurveyUrl[21a19780-1511-45ed-9485-0d1256714743] received
[2022-08-01 08:00:00,442: INFO/MainProcess] Task centre.tasks.CheckRegistrationEnd[b22594b3-1e38-465f-8280-37d3465d5a88] received
[2022-08-01 08:00:00,520: INFO/MainProcess] Task centre.tasks.ShowSurveyUrl[21a19780-1511-45ed-9485-0d1256714743] succeeded in 0.48399999999674037s: None
[2022-08-01 08:00:00,520: INFO/MainProcess] Task centre.tasks.CheckRegistrationEnd[b22594b3-1e38-465f-8280-37d3465d5a88] succeeded in 0.061999999976251274s: None
[2022-08-02 08:00:00,032: INFO/MainProcess] Task centre.tasks.CheckRegistrationEnd[896935cf-4dcc-48c3-a95c-f827bad2f500] received
[2022-08-02 08:00:00,422: INFO/MainProcess] Task centre.tasks.ShowSurveyUrl[a5fc8624-024c-470f-9ee3-3d011940b91f] received
[2022-08-02 08:00:00,500: INFO/MainProcess] Task centre.tasks.CheckRegistrationEnd[896935cf-4dcc-48c3-a95c-f827bad2f500] succeeded in 0.4369999999762513s: None
[2022-08-02 08:00:00,500: INFO/MainProcess] Task centre.tasks.ShowSurveyUrl[a5fc8624-024c-470f-9ee3-3d011940b91f] succeeded in 0.0779999999795109s: None
[2022-08-03 08:00:00,024: INFO/MainProcess] Task centre.tasks.ShowSurveyUrl[894a1223-f402-4c2f-9483-e53daa15241f] received
[2022-08-03 08:00:00,492: INFO/MainProcess] Task centre.tasks.CheckRegistrationEnd[c06b739d-6084-4f65-b444-bc55094f0c13] received
[2022-08-03 08:00:00,570: INFO/MainProcess] Task centre.tasks.ShowSurveyUrl[894a1223-f402-4c2f-9483-e53daa15241f] succeeded in 0.5309999999590218s: None
[2022-08-03 08:00:00,570: INFO/MainProcess] Task centre.tasks.CheckRegistrationEnd[c06b739d-6084-4f65-b444-bc55094f0c13] succeeded in 0.0779999999795109s: None
[2022-08-04 08:00:00,240: INFO/MainProcess] Task centre.tasks.ShowSurveyUrl[7fa0bc49-5cf4-4cd6-b894-414f2a973291] received
[2022-08-04 08:00:00,990: INFO/MainProcess] Task centre.tasks.CheckRegistrationEnd[e25dd877-34df-43cd-a31c-8b06667e3936] received
[2022-08-04 08:00:01,022: INFO/MainProcess] Task centre.tasks.ShowSurveyUrl[7fa0bc49-5cf4-4cd6-b894-414f2a973291] succeeded in 0.7179999999934807s: None
[2022-08-04 08:00:01,178: INFO/MainProcess] Task centre.tasks.CheckRegistrationEnd[e25dd877-34df-43cd-a31c-8b06667e3936] succeeded in 0.125s: None
[2022-08-05 04:32:36,758: INFO/MainProcess] Connected to redis://172.16.55.20:6379/0
[2022-08-05 04:32:36,758: INFO/MainProcess] mingle: searching for neighbors
[2022-08-05 04:32:37,776: INFO/MainProcess] mingle: all alone
[2022-08-05 04:32:37,791: INFO/MainProcess] pidbox: Connected to redis://172.16.55.20:6379/0.
[2022-08-05 04:32:37,806: WARNING/MainProcess] C:\inetpub\sites\edu-dev.coko38.ru\venv\lib\site-packages\celery\fixups\django.py:203: UserWarning: Using settings.DEBUG leads to a memory
            leak, never use this setting in production environments!
  warnings.warn('''Using settings.DEBUG leads to a memory

[2022-08-05 04:32:37,806: INFO/MainProcess] celery@srv-dev ready.
[2022-08-05 08:00:00,048: INFO/MainProcess] Task centre.tasks.CheckRegistrationEnd[484af6ff-8106-4ea1-8a08-9a4b5a29fda9] received
[2022-08-05 08:00:00,298: INFO/MainProcess] Task centre.tasks.ShowSurveyUrl[7b08f37f-f8da-470a-822b-f3f6f8f18da2] received
[2022-08-05 08:00:00,377: INFO/MainProcess] Task centre.tasks.CheckRegistrationEnd[484af6ff-8106-4ea1-8a08-9a4b5a29fda9] succeeded in 0.3279999999995198s: None
[2022-08-05 08:00:00,377: INFO/MainProcess] Task centre.tasks.ShowSurveyUrl[7b08f37f-f8da-470a-822b-f3f6f8f18da2] succeeded in 0.06199999999989814s: None
[2022-08-06 08:00:00,032: INFO/MainProcess] Task centre.tasks.ShowSurveyUrl[2360fb0c-07b9-4d47-954f-51456e77927e] received
[2022-08-06 08:00:00,562: INFO/MainProcess] Task centre.tasks.CheckRegistrationEnd[a6d8eb10-b5e7-4e9f-bc87-e4395f84a58f] received
[2022-08-06 08:00:00,624: INFO/MainProcess] Task centre.tasks.ShowSurveyUrl[2360fb0c-07b9-4d47-954f-51456e77927e] succeeded in 0.5939999999973224s: None
[2022-08-06 08:00:00,624: INFO/MainProcess] Task centre.tasks.CheckRegistrationEnd[a6d8eb10-b5e7-4e9f-bc87-e4395f84a58f] succeeded in 0.0629999999946449s: None
[2022-08-07 08:00:00,029: INFO/MainProcess] Task centre.tasks.CheckRegistrationEnd[f8a453c7-0419-485b-8b35-d93cca82afba] received
[2022-08-07 08:00:00,483: INFO/MainProcess] Task centre.tasks.ShowSurveyUrl[2cf25281-7d5f-4f41-a667-979ad8a8d188] received
[2022-08-07 08:00:00,561: INFO/MainProcess] Task centre.tasks.CheckRegistrationEnd[f8a453c7-0419-485b-8b35-d93cca82afba] succeeded in 0.5160000000032596s: None
[2022-08-07 08:00:00,561: INFO/MainProcess] Task centre.tasks.ShowSurveyUrl[2cf25281-7d5f-4f41-a667-979ad8a8d188] succeeded in 0.062000000005355105s: None
[2022-08-08 08:00:00,030: INFO/MainProcess] Task centre.tasks.CheckRegistrationEnd[79b5a401-ae6f-4fca-91fd-d317accb842b] received
[2022-08-08 08:00:00,311: INFO/MainProcess] Task centre.tasks.ShowSurveyUrl[881eca64-d9af-4df2-9a6b-72b18b7c27f2] received
[2022-08-08 08:00:00,374: INFO/MainProcess] Task centre.tasks.CheckRegistrationEnd[79b5a401-ae6f-4fca-91fd-d317accb842b] succeeded in 0.3440000000409782s: None
[2022-08-08 08:00:00,374: INFO/MainProcess] Task centre.tasks.ShowSurveyUrl[881eca64-d9af-4df2-9a6b-72b18b7c27f2] succeeded in 0.0470000000204891s: None
[2022-08-08 14:43:10,083: INFO/MainProcess] Connected to redis://172.16.55.20:6379/0
[2022-08-08 14:43:10,114: INFO/MainProcess] mingle: searching for neighbors
[2022-08-08 14:43:11,145: INFO/MainProcess] mingle: all alone
[2022-08-08 14:43:11,177: WARNING/MainProcess] C:\inetpub\sites\edu-dev.coko38.ru\venv\lib\site-packages\celery\fixups\django.py:203: UserWarning: Using settings.DEBUG leads to a memory
            leak, never use this setting in production environments!
  warnings.warn('''Using settings.DEBUG leads to a memory

[2022-08-08 14:43:11,177: INFO/MainProcess] celery@srv-dev ready.
[2022-08-08 14:43:11,177: INFO/MainProcess] pidbox: Connected to redis://172.16.55.20:6379/0.
[2022-08-08 14:46:47,985: INFO/MainProcess] Events of group {task} enabled by remote.
[2022-08-08 14:47:46,323: INFO/MainProcess] Task centre.tasks.frdo_report[12f19d1b-2bcc-49e2-aa78-074b86034f75] received
[2022-08-08 14:47:47,086: WARNING/MainProcess] C:\inetpub\sites\edu-dev.coko38.ru\venv\lib\site-packages\urllib3\connectionpool.py:1045: InsecureRequestWarning: Unverified HTTPS request is being made to host 'apidata.mos.ru'. Adding certificate verification is strongly advised. See: https://urllib3.readthedocs.io/en/1.26.x/advanced-usage.html#ssl-warnings
  warnings.warn(

[2022-08-08 14:47:47,633: WARNING/MainProcess] C:\inetpub\sites\edu-dev.coko38.ru\venv\lib\site-packages\urllib3\connectionpool.py:1045: InsecureRequestWarning: Unverified HTTPS request is being made to host 'apidata.mos.ru'. Adding certificate verification is strongly advised. See: https://urllib3.readthedocs.io/en/1.26.x/advanced-usage.html#ssl-warnings
  warnings.warn(

[2022-08-08 14:47:48,789: WARNING/MainProcess] C:\inetpub\sites\edu-dev.coko38.ru\venv\lib\site-packages\urllib3\connectionpool.py:1045: InsecureRequestWarning: Unverified HTTPS request is being made to host 'apidata.mos.ru'. Adding certificate verification is strongly advised. See: https://urllib3.readthedocs.io/en/1.26.x/advanced-usage.html#ssl-warnings
  warnings.warn(

[2022-08-08 14:47:49,288: WARNING/MainProcess] C:\inetpub\sites\edu-dev.coko38.ru\venv\lib\site-packages\urllib3\connectionpool.py:1045: InsecureRequestWarning: Unverified HTTPS request is being made to host 'apidata.mos.ru'. Adding certificate verification is strongly advised. See: https://urllib3.readthedocs.io/en/1.26.x/advanced-usage.html#ssl-warnings
  warnings.warn(

[2022-08-08 14:47:50,129: WARNING/MainProcess] C:\inetpub\sites\edu-dev.coko38.ru\venv\lib\site-packages\urllib3\connectionpool.py:1045: InsecureRequestWarning: Unverified HTTPS request is being made to host 'apidata.mos.ru'. Adding certificate verification is strongly advised. See: https://urllib3.readthedocs.io/en/1.26.x/advanced-usage.html#ssl-warnings
  warnings.warn(

[2022-08-08 14:47:50,583: WARNING/MainProcess] C:\inetpub\sites\edu-dev.coko38.ru\venv\lib\site-packages\urllib3\connectionpool.py:1045: InsecureRequestWarning: Unverified HTTPS request is being made to host 'apidata.mos.ru'. Adding certificate verification is strongly advised. See: https://urllib3.readthedocs.io/en/1.26.x/advanced-usage.html#ssl-warnings
  warnings.warn(

[2022-08-08 14:47:51,409: ERROR/MainProcess] Task centre.tasks.frdo_report[12f19d1b-2bcc-49e2-aa78-074b86034f75] raised unexpected: AttributeError("'method_descriptor' object has no attribute 'today'")
Traceback (most recent call last):
  File "C:\inetpub\sites\edu-dev.coko38.ru\venv\lib\site-packages\celery\app\trace.py", line 451, in trace_task
    R = retval = fun(*args, **kwargs)
  File "C:\inetpub\sites\edu-dev.coko38.ru\venv\lib\site-packages\celery\app\trace.py", line 734, in __protected_call__
    return self.run(*args, **kwargs)
  File "C:\inetpub\sites\edu-dev.coko38.ru\edu\centre\tasks.py", line 1236, in frdo_report
    writer.save(newpath + "Отчет_" + datetime.date.today().strftime('%d.%m.%Y') + ".xlsx")
AttributeError: 'method_descriptor' object has no attribute 'today'
[2022-08-08 14:50:08,908: INFO/MainProcess] Connected to redis://172.16.55.20:6379/0
[2022-08-08 14:50:08,908: INFO/MainProcess] mingle: searching for neighbors
[2022-08-08 14:50:09,908: INFO/MainProcess] mingle: all alone
[2022-08-08 14:50:09,939: INFO/MainProcess] pidbox: Connected to redis://172.16.55.20:6379/0.
[2022-08-08 14:50:09,954: WARNING/MainProcess] C:\inetpub\sites\edu-dev.coko38.ru\venv\lib\site-packages\celery\fixups\django.py:203: UserWarning: Using settings.DEBUG leads to a memory
            leak, never use this setting in production environments!
  warnings.warn('''Using settings.DEBUG leads to a memory

[2022-08-08 14:50:09,954: INFO/MainProcess] celery@srv-dev ready.
[2022-08-08 14:51:10,439: INFO/MainProcess] Events of group {task} enabled by remote.
[2022-08-08 14:52:13,021: INFO/MainProcess] Task centre.tasks.frdo_report[2f2ce25f-4c0f-4309-a3f0-9cb08e7aa2ca] received
[2022-08-08 14:52:13,677: WARNING/MainProcess] C:\inetpub\sites\edu-dev.coko38.ru\venv\lib\site-packages\urllib3\connectionpool.py:1045: InsecureRequestWarning: Unverified HTTPS request is being made to host 'apidata.mos.ru'. Adding certificate verification is strongly advised. See: https://urllib3.readthedocs.io/en/1.26.x/advanced-usage.html#ssl-warnings
  warnings.warn(

[2022-08-08 14:52:14,422: WARNING/MainProcess] C:\inetpub\sites\edu-dev.coko38.ru\venv\lib\site-packages\urllib3\connectionpool.py:1045: InsecureRequestWarning: Unverified HTTPS request is being made to host 'apidata.mos.ru'. Adding certificate verification is strongly advised. See: https://urllib3.readthedocs.io/en/1.26.x/advanced-usage.html#ssl-warnings
  warnings.warn(

[2022-08-08 14:52:15,453: WARNING/MainProcess] C:\inetpub\sites\edu-dev.coko38.ru\venv\lib\site-packages\urllib3\connectionpool.py:1045: InsecureRequestWarning: Unverified HTTPS request is being made to host 'apidata.mos.ru'. Adding certificate verification is strongly advised. See: https://urllib3.readthedocs.io/en/1.26.x/advanced-usage.html#ssl-warnings
  warnings.warn(

[2022-08-08 14:52:15,953: WARNING/MainProcess] C:\inetpub\sites\edu-dev.coko38.ru\venv\lib\site-packages\urllib3\connectionpool.py:1045: InsecureRequestWarning: Unverified HTTPS request is being made to host 'apidata.mos.ru'. Adding certificate verification is strongly advised. See: https://urllib3.readthedocs.io/en/1.26.x/advanced-usage.html#ssl-warnings
  warnings.warn(

[2022-08-08 14:52:16,874: WARNING/MainProcess] C:\inetpub\sites\edu-dev.coko38.ru\venv\lib\site-packages\urllib3\connectionpool.py:1045: InsecureRequestWarning: Unverified HTTPS request is being made to host 'apidata.mos.ru'. Adding certificate verification is strongly advised. See: https://urllib3.readthedocs.io/en/1.26.x/advanced-usage.html#ssl-warnings
  warnings.warn(

[2022-08-08 14:52:17,361: WARNING/MainProcess] C:\inetpub\sites\edu-dev.coko38.ru\venv\lib\site-packages\urllib3\connectionpool.py:1045: InsecureRequestWarning: Unverified HTTPS request is being made to host 'apidata.mos.ru'. Adding certificate verification is strongly advised. See: https://urllib3.readthedocs.io/en/1.26.x/advanced-usage.html#ssl-warnings
  warnings.warn(

[2022-08-08 14:52:18,063: WARNING/MainProcess] C:\inetpub\sites\edu-dev.coko38.ru\venv\lib\site-packages\django\db\models\fields\__init__.py:1534: RuntimeWarning: DateTimeField Reports.date_finish received a naive datetime (2022-08-08 14:52:18.063017) while time zone support is active.
  warnings.warn(

[2022-08-08 14:52:21,560: INFO/MainProcess] Task centre.tasks.frdo_report[2f2ce25f-4c0f-4309-a3f0-9cb08e7aa2ca] succeeded in 8.546999999999997s: None
[2022-08-09 08:00:00,047: INFO/MainProcess] Task centre.tasks.CheckRegistrationEnd[24234f42-2011-43ae-a8d3-857076d045e3] received
[2022-08-09 08:00:00,547: INFO/MainProcess] Task centre.tasks.ShowSurveyUrl[d4a64a6c-da80-4921-ac0a-2bba30f482ce] received
[2022-08-09 08:00:00,547: INFO/MainProcess] Task centre.tasks.CheckRegistrationEnd[24234f42-2011-43ae-a8d3-857076d045e3] succeeded in 0.4850000000005821s: None
[2022-08-09 08:00:00,640: INFO/MainProcess] Task centre.tasks.ShowSurveyUrl[d4a64a6c-da80-4921-ac0a-2bba30f482ce] succeeded in 0.0930000000007567s: None
[2022-08-10 08:00:00,027: INFO/MainProcess] Task centre.tasks.ShowSurveyUrl[66de08cf-bc7a-421e-8b14-2a030a6e5147] received
[2022-08-10 08:00:00,449: INFO/MainProcess] Task centre.tasks.CheckRegistrationEnd[e51e3ef2-d901-4882-9efb-a873e1e69b96] received
[2022-08-10 08:00:00,527: INFO/MainProcess] Task centre.tasks.ShowSurveyUrl[66de08cf-bc7a-421e-8b14-2a030a6e5147] succeeded in 0.4840000000258442s: None
[2022-08-10 08:00:00,543: INFO/MainProcess] Task centre.tasks.CheckRegistrationEnd[e51e3ef2-d901-4882-9efb-a873e1e69b96] succeeded in 0.0779999999795109s: None
[2022-08-11 08:00:00,032: INFO/MainProcess] Task centre.tasks.CheckRegistrationEnd[4f941670-c5d4-4d9a-b759-0a1310016396] received
[2022-08-11 08:00:00,495: INFO/MainProcess] Task centre.tasks.ShowSurveyUrl[d4b10d42-9b2b-4c1b-8b0a-a37d46e55b37] received
[2022-08-11 08:00:00,495: INFO/MainProcess] Task centre.tasks.CheckRegistrationEnd[4f941670-c5d4-4d9a-b759-0a1310016396] succeeded in 0.46900000001187436s: None
[2022-08-11 08:00:00,573: INFO/MainProcess] Task centre.tasks.ShowSurveyUrl[d4b10d42-9b2b-4c1b-8b0a-a37d46e55b37] succeeded in 0.0629999999946449s: None
[2022-08-11 11:35:15,892: INFO/MainProcess] Task centre.tasks.generate_pk1[bb30d226-e068-4bf2-b066-0529e0a69e29] received
[2022-08-11 11:35:41,408: WARNING/MainProcess] C:\inetpub\sites\edu-dev.coko38.ru\venv\lib\site-packages\django\db\models\fields\__init__.py:1534: RuntimeWarning: DateTimeField Reports.date_finish received a naive datetime (2022-08-11 11:35:41.408601) while time zone support is active.
  warnings.warn(

[2022-08-11 11:35:44,172: INFO/MainProcess] Task centre.tasks.generate_pk1[bb30d226-e068-4bf2-b066-0529e0a69e29] succeeded in 28.28200000000652s: None
[2022-08-12 08:00:00,026: INFO/MainProcess] Task centre.tasks.ShowSurveyUrl[ffb5ff10-2fd8-43f6-a73c-cda615e6fac8] received
[2022-08-12 08:00:00,509: INFO/MainProcess] Task centre.tasks.CheckRegistrationEnd[effb8e9b-41b4-4c59-9454-1c3f5b65a63e] received
[2022-08-12 08:00:00,509: INFO/MainProcess] Task centre.tasks.ShowSurveyUrl[ffb5ff10-2fd8-43f6-a73c-cda615e6fac8] succeeded in 0.46899999998277053s: None
[2022-08-12 08:00:00,572: INFO/MainProcess] Task centre.tasks.CheckRegistrationEnd[effb8e9b-41b4-4c59-9454-1c3f5b65a63e] succeeded in 0.046999999962281436s: None
[2022-08-13 08:00:00,029: INFO/MainProcess] Task centre.tasks.CheckRegistrationEnd[d07e5202-a928-44f2-b9c8-56b788290492] received
[2022-08-13 08:00:00,692: INFO/MainProcess] Task centre.tasks.ShowSurveyUrl[c394f505-eff1-4d29-8064-0dfa4b1fbcfb] received
[2022-08-13 08:00:00,771: INFO/MainProcess] Task centre.tasks.CheckRegistrationEnd[d07e5202-a928-44f2-b9c8-56b788290492] succeeded in 0.7339999999967404s: None
[2022-08-13 08:00:00,771: INFO/MainProcess] Task centre.tasks.ShowSurveyUrl[c394f505-eff1-4d29-8064-0dfa4b1fbcfb] succeeded in 0.0779999999795109s: None
[2022-08-14 08:00:00,049: INFO/MainProcess] Task centre.tasks.ShowSurveyUrl[ec2da074-92e4-4466-9a83-b9dc8ae0f76a] received
[2022-08-14 08:00:00,768: INFO/MainProcess] Task centre.tasks.CheckRegistrationEnd[30383f12-61b9-4dcd-84a5-251e032c2ef3] received
[2022-08-14 08:00:00,846: INFO/MainProcess] Task centre.tasks.ShowSurveyUrl[ec2da074-92e4-4466-9a83-b9dc8ae0f76a] succeeded in 0.7970000000204891s: None
[2022-08-14 08:00:00,862: INFO/MainProcess] Task centre.tasks.CheckRegistrationEnd[30383f12-61b9-4dcd-84a5-251e032c2ef3] succeeded in 0.07800000003771856s: None
[2022-08-15 08:00:00,031: INFO/MainProcess] Task centre.tasks.CheckRegistrationEnd[cecc8d77-87d1-40a4-9cec-9beed6601416] received
[2022-08-15 08:00:00,454: INFO/MainProcess] Task centre.tasks.ShowSurveyUrl[a8ca3ca7-9563-4b64-9b38-955342405d70] received
[2022-08-15 08:00:00,454: INFO/MainProcess] Task centre.tasks.CheckRegistrationEnd[cecc8d77-87d1-40a4-9cec-9beed6601416] succeeded in 0.40600000007543713s: None
[2022-08-15 08:00:00,532: INFO/MainProcess] Task centre.tasks.ShowSurveyUrl[a8ca3ca7-9563-4b64-9b38-955342405d70] succeeded in 0.062000000034458935s: None
[2022-08-16 08:00:00,040: INFO/MainProcess] Task centre.tasks.ShowSurveyUrl[cf869da9-c8ec-4db1-aba2-05b4094851f7] received
[2022-08-16 08:00:00,509: INFO/MainProcess] Task centre.tasks.CheckRegistrationEnd[20fb8f8c-6486-408f-9eed-9e0dc5678c94] received
[2022-08-16 08:00:00,572: INFO/MainProcess] Task centre.tasks.ShowSurveyUrl[cf869da9-c8ec-4db1-aba2-05b4094851f7] succeeded in 0.5310000000754371s: None
[2022-08-16 08:00:00,572: INFO/MainProcess] Task centre.tasks.CheckRegistrationEnd[20fb8f8c-6486-408f-9eed-9e0dc5678c94] succeeded in 0.0470000000204891s: None
[2022-08-17 08:00:00,031: INFO/MainProcess] Task centre.tasks.CheckRegistrationEnd[7b52a343-1c7d-450d-9235-c14bb0521851] received
[2022-08-17 08:00:00,453: INFO/MainProcess] Task centre.tasks.ShowSurveyUrl[cdd6f896-29fc-4626-9e53-2f57d5c7dd60] received
[2022-08-17 08:00:00,468: INFO/MainProcess] Task centre.tasks.CheckRegistrationEnd[7b52a343-1c7d-450d-9235-c14bb0521851] succeeded in 0.4380000000819564s: None
[2022-08-17 08:00:00,562: INFO/MainProcess] Task centre.tasks.ShowSurveyUrl[cdd6f896-29fc-4626-9e53-2f57d5c7dd60] succeeded in 0.09399999992456287s: None
[2022-08-18 08:00:00,047: INFO/MainProcess] Task centre.tasks.ShowSurveyUrl[4384b68c-bbf4-4a21-9dd2-abbf633b6d91] received
[2022-08-18 08:00:00,500: INFO/MainProcess] Task centre.tasks.CheckRegistrationEnd[61dfd649-b2bf-4923-b848-dbef0efc2dea] received
[2022-08-18 08:00:00,500: INFO/MainProcess] Task centre.tasks.ShowSurveyUrl[4384b68c-bbf4-4a21-9dd2-abbf633b6d91] succeeded in 0.4530000000959262s: None
[2022-08-18 08:00:00,562: INFO/MainProcess] Task centre.tasks.CheckRegistrationEnd[61dfd649-b2bf-4923-b848-dbef0efc2dea] succeeded in 0.06199999991804361s: None
[2022-08-19 08:00:00,035: INFO/MainProcess] Task centre.tasks.CheckRegistrationEnd[e6b09b08-5ff5-41ed-856c-9fb9caeab833] received
[2022-08-19 08:00:00,441: INFO/MainProcess] Task centre.tasks.ShowSurveyUrl[6f6891e2-1b30-4011-8b58-af7691253f5a] received
[2022-08-19 08:00:00,441: INFO/MainProcess] Task centre.tasks.CheckRegistrationEnd[e6b09b08-5ff5-41ed-856c-9fb9caeab833] succeeded in 0.4059999999590218s: None
[2022-08-19 08:00:00,504: INFO/MainProcess] Task centre.tasks.ShowSurveyUrl[6f6891e2-1b30-4011-8b58-af7691253f5a] succeeded in 0.0470000000204891s: None
[2022-08-20 08:00:00,031: INFO/MainProcess] Task centre.tasks.ShowSurveyUrl[3de5c62d-9bc4-4958-94c2-fe51fa5a5cc4] received
[2022-08-20 08:00:00,500: INFO/MainProcess] Task centre.tasks.CheckRegistrationEnd[f3533aca-3a9e-4bee-a151-9f0305e49ff5] received
[2022-08-20 08:00:00,547: INFO/MainProcess] Task centre.tasks.ShowSurveyUrl[3de5c62d-9bc4-4958-94c2-fe51fa5a5cc4] succeeded in 0.515999999945052s: None
[2022-08-20 08:00:00,547: INFO/MainProcess] Task centre.tasks.CheckRegistrationEnd[f3533aca-3a9e-4bee-a151-9f0305e49ff5] succeeded in 0.0470000000204891s: None
[2022-08-21 08:00:00,026: INFO/MainProcess] Task centre.tasks.ShowSurveyUrl[cfdedb9d-fe08-41a8-8961-bbcd26dd5329] received
[2022-08-21 08:00:00,480: INFO/MainProcess] Task centre.tasks.CheckRegistrationEnd[16041727-5c67-4fad-99d1-a6df8647a60d] received
[2022-08-21 08:00:00,480: INFO/MainProcess] Task centre.tasks.ShowSurveyUrl[cfdedb9d-fe08-41a8-8961-bbcd26dd5329] succeeded in 0.4529999999795109s: None
[2022-08-21 08:00:00,527: INFO/MainProcess] Task centre.tasks.CheckRegistrationEnd[16041727-5c67-4fad-99d1-a6df8647a60d] succeeded in 0.0470000000204891s: None
[2022-08-22 08:00:00,023: INFO/MainProcess] Task centre.tasks.CheckRegistrationEnd[8740416f-30f8-4d6a-b51c-babdf3099cac] received
[2022-08-22 08:00:00,463: INFO/MainProcess] Task centre.tasks.ShowSurveyUrl[d2636375-331e-41e3-af6d-57f81160b4d6] received
[2022-08-22 08:00:00,556: INFO/MainProcess] Task centre.tasks.CheckRegistrationEnd[8740416f-30f8-4d6a-b51c-babdf3099cac] succeeded in 0.5150000001303852s: None
[2022-08-22 08:00:00,556: INFO/MainProcess] Task centre.tasks.ShowSurveyUrl[d2636375-331e-41e3-af6d-57f81160b4d6] succeeded in 0.09300000010989606s: None
[2022-08-23 08:00:00,027: INFO/MainProcess] Task centre.tasks.CheckRegistrationEnd[6f93f0c0-5404-4e96-bdd2-ff48beaed0bc] received
[2022-08-23 08:00:00,449: INFO/MainProcess] Task centre.tasks.ShowSurveyUrl[097537cb-c578-44f3-9d28-074787514f4b] received
[2022-08-23 08:00:00,449: INFO/MainProcess] Task centre.tasks.CheckRegistrationEnd[6f93f0c0-5404-4e96-bdd2-ff48beaed0bc] succeeded in 0.4220000000204891s: None
[2022-08-23 08:00:00,542: INFO/MainProcess] Task centre.tasks.ShowSurveyUrl[097537cb-c578-44f3-9d28-074787514f4b] succeeded in 0.0940000000409782s: None
[2022-08-24 08:00:00,034: INFO/MainProcess] Task centre.tasks.ShowSurveyUrl[41433bc6-b6de-4d0b-b545-a6e911d7ad3b] received
[2022-08-24 08:00:00,456: INFO/MainProcess] Task centre.tasks.CheckRegistrationEnd[f615ea83-e762-49ce-a1e4-7d00ecd57b8f] received
[2022-08-24 08:00:00,471: INFO/MainProcess] Task centre.tasks.ShowSurveyUrl[41433bc6-b6de-4d0b-b545-a6e911d7ad3b] succeeded in 0.43799999984912574s: None
[2022-08-24 08:00:00,518: INFO/MainProcess] Task centre.tasks.CheckRegistrationEnd[f615ea83-e762-49ce-a1e4-7d00ecd57b8f] succeeded in 0.0470000000204891s: None
[2022-08-25 08:00:00,029: INFO/MainProcess] Task centre.tasks.CheckRegistrationEnd[5083114e-623d-4f9f-bd98-91caaee86818] received
[2022-08-25 08:00:00,467: INFO/MainProcess] Task centre.tasks.ShowSurveyUrl[7bdcc078-612f-4657-9f01-88df683eda5b] received
[2022-08-25 08:00:00,560: INFO/MainProcess] Task centre.tasks.CheckRegistrationEnd[5083114e-623d-4f9f-bd98-91caaee86818] succeeded in 0.5150000001303852s: None
[2022-08-25 08:00:00,576: INFO/MainProcess] Task centre.tasks.ShowSurveyUrl[7bdcc078-612f-4657-9f01-88df683eda5b] succeeded in 0.0940000000409782s: None
[2022-08-26 08:00:00,035: INFO/MainProcess] Task centre.tasks.ShowSurveyUrl[5164eb8b-bb2b-438c-ad1c-7a70fa4834f2] received
[2022-08-26 08:00:00,507: INFO/MainProcess] Task centre.tasks.CheckRegistrationEnd[135d050c-cf25-4440-9225-15f34887a6c6] received
[2022-08-26 08:00:00,554: INFO/MainProcess] Task centre.tasks.ShowSurveyUrl[5164eb8b-bb2b-438c-ad1c-7a70fa4834f2] succeeded in 0.5319999998901039s: None
[2022-08-26 08:00:00,554: INFO/MainProcess] Task centre.tasks.CheckRegistrationEnd[135d050c-cf25-4440-9225-15f34887a6c6] succeeded in 0.0470000000204891s: None
[2022-08-27 08:00:00,037: INFO/MainProcess] Task centre.tasks.CheckRegistrationEnd[dc1206c3-8c69-4f75-921d-5097633705bf] received
[2022-08-27 08:00:00,443: INFO/MainProcess] Task centre.tasks.ShowSurveyUrl[0b06eed5-b6e6-4ea0-9135-3611ffd6ac13] received
[2022-08-27 08:00:00,443: INFO/MainProcess] Task centre.tasks.CheckRegistrationEnd[dc1206c3-8c69-4f75-921d-5097633705bf] succeeded in 0.3910000000614673s: None
[2022-08-27 08:00:00,521: INFO/MainProcess] Task centre.tasks.ShowSurveyUrl[0b06eed5-b6e6-4ea0-9135-3611ffd6ac13] succeeded in 0.0779999999795109s: None
[2022-08-28 08:00:00,029: INFO/MainProcess] Task centre.tasks.ShowSurveyUrl[51a7e2eb-8870-43e0-9408-d12f590c37a4] received
[2022-08-28 08:00:00,468: INFO/MainProcess] Task centre.tasks.CheckRegistrationEnd[a318058b-b1fe-4a3e-9176-0b6ba4c691c0] received
[2022-08-28 08:00:00,515: INFO/MainProcess] Task centre.tasks.ShowSurveyUrl[51a7e2eb-8870-43e0-9408-d12f590c37a4] succeeded in 0.4850000001024455s: None
[2022-08-28 08:00:00,531: INFO/MainProcess] Task centre.tasks.CheckRegistrationEnd[a318058b-b1fe-4a3e-9176-0b6ba4c691c0] succeeded in 0.06199999991804361s: None
[2022-08-29 08:00:00,040: INFO/MainProcess] Task centre.tasks.CheckRegistrationEnd[2519562f-68dd-4646-a3dc-0390432c584c] received
[2022-08-29 08:00:00,463: INFO/MainProcess] Task centre.tasks.ShowSurveyUrl[19934a29-a4aa-47df-b225-b197fce3e8dd] received
[2022-08-29 08:00:00,572: INFO/MainProcess] Task centre.tasks.CheckRegistrationEnd[2519562f-68dd-4646-a3dc-0390432c584c] succeeded in 0.5309999999590218s: None
